Workbook

Sheet Revised 3mwp
A2: Results Areas | B2: Main Activities | C2: Sub Activities | D2: Expected Outputs | E2: Performance Indicators | F2: Target | G2: Means of verification | H2: 2023/24 | K2: Estimated Cost | L2: Approved Budget (Rec & Dev) | N2: Off-budget resources | P2: Funding Gap
H3: April | I3: May | J3: June | L3: GOK | M3: Source of funding | N3: Amount | O3: Source of funding
A4: Mapping of snakes of medical importance and snakebite Hotspots | B4: Conduct coverage surveys to map Snakebite Hotspots | C4: Apply for ethical approvals and NACOSTI permits to conduct householdsurveys for the mapping of snakebite hotspots in 30 counties | D4: applications for the Ethical approvals and NACOSTI permits submitted | E4: Number of ethical approvals and NACOSTI | F4: 4 | G4: Ethical approvals, NACOSTI permits | K4: =(40000*4)+(10000*4) -> 200000
C5: Procure a venue for a 3-day stakeholders meeting with county health management teams in two counties (Kitui, Turkana) to obtain approvals for conducting surveys to map snakebite hotspots. (Procure transport, conference, DSA for 15 officers for 3 days per county) | D5: Venue to hold stakeholders meetings with county health management teams procured | E5: Number of venues procured, number of county approval letters acquired. | F5: 2 | G5: Invoice receipts, Attendance sheets, county approval letters | K5: ='3 M-Budget'!N27 -> 2092000 | U5: ='1Y-Budget'!F29 -> 0
C6: Conduct a 5 day workshop for the training of county data collectors on snakebite community-based survey methodologies in 2 counties (Kitui, Turkana) | D6: Data collectors trained on community-based survey methodologies | E6: number of data collectors trained per county | F6: 2 | G6: Training certificates | K6: ='3 M-Budget'!F40 -> 2215000
C7: Conduct community based surveys in 2 counties (Kitui, Turkana) to map snakebite hotspots (Procure transport, subsistenance allowance for 10 data collectors, and DSA for 10 public officers for 3 weeks per county | D7: 2 counties surveyed to map snakebite hotspots | E7: Number of counties surveyed | F7: 2 | G7: survey questionnaires, geographic maps | K7: ='3 M-Budget'!N95 -> 8494000
B8: Integrate Snakebite Envenoming mapping with other NTD programs | C8: Conduct a 10-day workshop with national stakeholders to develop protocols for integrating snakebite management with existing MoH-NTD programs and develop a snakebite database. (Procure transport, conference, DSA for 15 officers for 3 days per county) | D8: common integration programs on snakebite prevention and intervention identified, integration protocols and SOPs developed, Dashboard for mapping of snakes of medical importance and snakebite hotspots created | E8: number of integration programs identified, number of protocols developed, Number of dashboards created and intergrated into the MoH-NTD database | F8: 1 | G8: workshop programme, attendance sheet, Meeting agendas and minutes, venue payment receipts, Database | K8: ='3 M-Budget'!N12 -> 3970000
C9: Train county and sub county healthcare workers and community health promoters on protocols in 3 counties (Homa Bay, Siaya, Migori) | D9: healthcare workers and community healthcare promoters in 3 counties trained on protocols in integrating Snakebite Envenoming mapping with other NTD programs | E9: number of counties trained | F9: 3 | G9: training schedules, attendance sheets, photo evidence | K9: ='3 M-Budget'!F81 -> 1542000
C10: Conduct surveys to integrate Snakebite Envenoming mapping with other NTD programs in 3 counties (Homa Bay, Siaya, Migori) (procure transport and DSA for 10 public officers for 10 days per county ) | D10: 3 counties surveyed for integration of snakebite envenoming mapping with other NTD programs | E10: Number of counties surveyed | F10: 3 | G10: Maps of surveyed counties, Vehicle work tickets, county approval letters | K10: ='3 M-Budget'!F95 -> 3725000
B11: Integrate Snakebite mapping with the Kenya Livestock MasterPlan (KLMP) | C11: Organize a one-week workshop with national stakeholders from the Kenya Ministry of Agriculture to integrate snakebite mortality mapping into the Kenya Livestock Master Plan (KLMP) and develop training and data collection protocols for livestock ward officers and community health promoters to support this integration. | D11: common integration programs on snakebite prevention and intervention identified, Integration protocols and SOPs in integrating Snakebite Envenoming mapping with Livestock KLMP program developed | E11: number of integration programs on snakebite prevention and intervention | F11: 1 | G11: workshop programme, attendance sheet, Meeting agendas and minutes, venue payment receipts, Integrated program protocols, SOPs | K11: ='3 M-Budget'!F121 -> 1160000
C12: Train livestock ward officers and community healthcare promoters on protocols in integrating Snakebite integrating snakebite mapping with the KLMP in 3 counties (Kisumu, Siaya, Migori) | D12: healthcare workers and community healthcare promoters in 8 counties trained on protocols in integrating Snakebite Envenoming mapping with other NTDs, Malaria and Livestock programs | E12: number of counties trained | F12: 3 | G12: training schedules, attendance sheets, photo evidence | K12: ='3 M-Budget'!F134 -> 1143000
C13: Conduct surveys to Integrate snakebite mapping with the KLMP in 3 counties (procure transport and DSA for 5 public officers for 10 days per county ) | D13: 3 counties surveyed for integration of snakebite envenoming mapping with other NTDs, Malaria and Livestock programs | E13: Number of counties surveyed | F13: 3 | G13: Maps of surveyed counties, Vehicle work tickets, county approval letters | K13: ='3 M-Budget'!F145 -> 5660000
C14: Engage Social media, website & other digital platforms to create awareness on snake identification, snakebite first aid and prevention and control measures | D14: Social media, website & other digital platforms engaged | E14: Number of Social media, website & other digital platforms Engaged | F14: 3 | G14: Active Social Media Handles, Website | K14: 500000
A15: Subtotal | K15: =SUM(K5:K14) -> 30501000
A16: Strengthen the Human Resource for snakebite management and antivenom production | B16: Train health care workers on snakebite diagnosis, management, antivenom administration and snakebite prevention and control measures | C16: Conduct a training needs assessment across 2 counties (Turkana, Kitui) to evaluate the requirements for training healthcare workers in snakebite diagnosis, management, antivenom administration, and prevention and control measures (procure transportation and DSA for 5 officers, 3 weeks per county) | D16: training needs assessment to evaluate the requirements for training healthcare workers in snakebite diagnosis, management, antivenom administration, and prevention and control measures conducted | E16: Needs assessment reports per county | F16: 2 | G16: Finalized assessment reports | K16: ='3 M-Budget'!F198 -> 1370000
C17: Conduct a 5 day Workshop to develop training manuals on snake identification snakebite diagnosis, management, antivenom administration and snakebite prevention and control measures (procure workshop venue, transportation and DSA for 5 officers) | D17: training mannuals on snakebite diagnosis, management, antivenom administration and snakebite prevention and control measures developed. | E17: number of training mannuals developed | F17: 2 | G17: workshop reports, Training manuals, Vehicle work tickets, | K17: ='3 M-Budget'!F211 -> 1760000
C18: Conduct a county level Trainer of Trainer (ToT) trainings on snakebite diagnosis, management, antivenom administration and snakebite prevention and control measures to capacity build across different health care carders in 2 counties (Kitui, Turkana). Procure training venue, provide daily subsistence allowance (DSA) for 15 officers, and lunch allowance for 20 healthcare workers per county, for a duration of 5 days per county | D18: County ToTs trained on snakebite diagnosis, management, antivenom administration and snakebite prevention and control measure | E18: Number of counties trained | F18: 2 | G18: County approvals, Training Reports, training certificates, attendance sheets | K18: ='3 M-Budget'!F226 -> 3620000
B19: Train Community Health Promoters (CHPs) on snake species identification, snakebite diagnosis, first aid, prevention and control measures | C19: Train CHPs on snake species identification, snakebite diagnosis, first aid, prevention and control measures. (Procure IEC tools to populate amongst CHPs, procure workshop venue, transportation and DSA for 5 officers for 5 days per county) | D19: CHPs trained on snakebite diagnosis, treatment, management and rehabilitation | E19: Number of counties where CHPs were trained | F19: 2 | G19: Training reports, training certificates | K19: ='3 M-Budget'!F325 -> 3120000
A20: Subtotal | K20: =SUM(K16:K18) -> 6750000
A21: Grandtotal | K21: =K20+K15 -> 37251000

Sheet 3 M-Budget
A1: Sub activity 1
A2: ITEM | B2: UNIT COST | C2: QTY | D2: Days | E2: counties | F2: TOTAL | I2: Sub activity
A3: Per diem | B3: 14000 | C3: 15 | D3: 14 | E3: 2 | F3: =B3*C3*D3*E3 -> 5880000 | I3: ITEM | J3: UNIT COST | K3: QTY | L3: Days | M3: counties | N3: TOTAL
A4: conference | B4: 0 | C4: 0 | D4: 0 | E4: 0 | F4: =B4*C4*D4*E4 -> 0 | I4: Per diem | J4: 14000 | K4: 20 | L4: 10 | M4: 1 | N4: =J4*K4*L4*M4 -> 2800000
A5: fuel cost | B5: 200 | C5: 85 | D5: 14 | E5: 2 | F5: =B5*C5*D5*E5 -> 476000 | I5: conference | J5: 5000 | K5: 20 | L5: 10 | M5: 1 | N5: =J5*K5*L5*M5 -> 1000000
A6: vehicle maintenance | B6: 0 | C6: 0 | D6: 0 | E6: 0 | F6: =B6*C6*D6*E6 -> 0 | I6: fuel cost | J6: 200 | K6: 85 | L6: 10 | M6: 1 | N6: =J6*K6*L6*M6 -> 170000
A7: Air ticket | B7: 28000 | C7: 5 | D7: 1 | E7: 1 | F7: =B7*C7*D7*E7 -> 140000 | I7: vehicle maintenance | J7: 0 | K7: 0 | L7: 0 | M7: 0 | N7: =J7*K7*L7*M7 -> 0
A8: Subsistence allowance | B8: 0 | C8: 0 | D8: 0 | E8: 0 | F8: =B8*C8*D8*E8 -> 0 | I8: Air ticket | J8: 0 | K8: 0 | L8: 0 | M8: 0 | N8: =J8*K8*L8*M8 -> 0
A9: Training allowance | B9: 0 | C9: 0 | D9: 0 | E9: 0 | F9: =B9*C9*D9*E9 -> 0 | I9: Subsistence allowance | J9: 0 | K9: 0 | L9: 0 | M9: 0 | N9: =J9*K9*L9*M9 -> 0
A10: training materials | B10: 0 | C10: 0 | D10: 0 | E10: 0 | F10: =B10*C10*D10*E10 -> 0 | I10: Training allowance | J10: 0 | K10: 0 | L10: 0 | M10: 0 | N10: =J10*K10*L10*M10 -> 0
A11: Total | B11: 0 | C11: 0 | D11: 0 | E11: 0 | F11: =SUM(F3:F10) -> 6496000 | I11: training materials | J11: 0 | K11: 0 | L11: 0 | M11: 0 | N11: =J11*K11*L11*M11 -> 0
I12: Total | J12: 0 | K12: 0 | L12: 0 | M12: 0 | N12: =SUM(N4:N11) -> 3970000
A15: Sub activity 2 | I15: chmt budget
A16: ITEM | B16: UNIT COST | C16: QTY | D16: Days | E16: counties | F16: TOTAL | I16: ITEM | J16: UNIT COST | K16: QTY | L16: Days | M16: counties | N16: TOTAL
A17: Per diem | B17: 14000 | C17: 10 | D17: 2 | E17: 3 | F17: =B17*C17*D17*E17 -> 840000 | I17: Per diem | J17: 14000 | K17: 15 | L17: 3 | M17: 2 | N17: =J17*K17*L17*M17 -> 1260000
A18: conference | B18: 5000 | C18: 10 | D18: 2 | E18: 2 | F18: =B18*C18*D18*E18 -> 200000 | I18: conference | J18: 5000 | K18: 15 | L18: 3 | M18: 2 | N18: =J18*K18*L18*M18 -> 450000
A19: fuel cost | B19: 0 | C19: 0 | D19: 0 | E19: 0 | F19: =B19*C19*D19*E19 -> 0 | I19: fuel cost | J19: 200 | K19: 85 | L19: 3 | M19: 2 | N19: =J19*K19*L19*M19 -> 102000
A20: vehicle maintenance | B20: 0 | C20: 0 | D20: 0 | E20: 0 | F20: =B20*C20*D20*E20 -> 0 | I20: vehicle maintenance | J20: 0 | K20: 0 | L20: 0 | M20: 0 | N20: =J20*K20*L20*M20 -> 0
A21: Air ticket | B21: 28000 | C21: 5 | D21: 1 | E21: 1 | F21: =B21*C21*D21*E21 -> 140000 | I21: Air ticket | J21: 28000 | K21: 5 | L21: 1 | M21: 2 | N21: =J21*K21*L21*M21 -> 280000
A22: Subsistence allowance | B22: 0 | C22: 0 | D22: 0 | E22: 0 | F22: =B22*C22*D22*E22 -> 0 | I22: Subsistence allowance | J22: 0 | K22: 0 | L22: 0 | M22: 0 | N22: =J22*K22*L22*M22 -> 0
A23: Training allowance | B23: 0 | C23: 0 | D23: 0 | E23: 0 | F23: =B23*C23*D23*E23 -> 0 | I23: Training allowance | J23: 0 | K23: 0 | L23: 0 | M23: 0 | N23: =J23*K23*L23*M23 -> 0
A24: training materials | B24: 0 | C24: 0 | D24: 0 | E24: 0 | F24: =B24*C24*D24*E24 -> 0 | I24: Security | J24: 0 | K24: 0 | L24: 0 | M24: 0 | N24: =J24*K24*L24*M24 -> 0
A25: Media | B25: 0 | C25: 0 | D25: 0 | E25: 0 | F25: 0 | I25: training materials | J25: 0 | K25: 0 | L25: 0 | M25: 0 | N25: =J25*K25*L25*M25 -> 0
F26: =SUM(F17:F24) -> 1180000 | I26: Media | J26: 0 | K26: 0 | L26: 0 | M26: 0 | N26: 0
N27: =SUM(N17:N25) -> 2092000
A29: Sub activity 3
A30: ITEM | B30: UNIT COST | C30: QTY | D30: Days | E30: counties | F30: TOTAL
A31: Per diem | B31: 14000 | C31: 10 | D31: 5 | E31: 2 | F31: =B31*C31*D31*E31 -> 1400000
A32: conference | B32: 5000 | C32: 10 | D32: 5 | E32: 2 | F32: =B32*C32*D32*E32 -> 500000
A33: fuel cost | B33: 200 | C33: 85 | D33: 5 | E33: 2 | F33: =B33*C33*D33*E33 -> 170000
A34: vehicle maintenance | B34: 0 | C34: 0 | D34: 0 | E34: 0 | F34: =B34*C34*D34*E34 -> 0
A35: Air ticket | B35: 0 | C35: 0 | D35: 0 | E35: 0 | F35: =B35*C35*D35*E35 -> 0
A36: Subsistence allowance | B36: 0 | C36: 0 | D36: 0 | E36: 0 | F36: =B36*C36*D36*E36 -> 0
A37: Training allowance | B37: 2500 | C37: 5 | D37: 5 | E37: 2 | F37: =B37*C37*D37*E37 -> 125000
A38: training materials | B38: 10000 | C38: 1 | D38: 1 | E38: 2 | F38: =B38*C38*D38*E38 -> 20000
A39: Media | B39: 0 | C39: 0 | D39: 0 | E39: 0 | F39: =B39*C39*D39*E39 -> 0
F40: =SUM(F31:F39) -> 2215000
A43: Sub activity 4
A44: ITEM | B44: UNIT COST | C44: QTY | D44: Days | E44: counties | F44: TOTAL
A45: Per diem | B45: 14000 | C45: 5 | D45: 21 | E45: 2 | F45: =B45*C45*D45*E45 -> 2940000
...

Sheet Revised 1ywp
A2: Results Areas | B2: Main Activities | C2: Sub Activities | D2: Expected Outputs | E2: Performance Indicators | F2: Target | G2: Means of verification | I2: 2024/25 | U2: Estimated Cost | V2: Approved Budget (Rec & Dev) | X2: Off-budget resources | Z2: Funding Gap
H3: GOK | I3: July | J3: Aug | K3: Sep | L3: Oct | M3: Nov | N3: Dec | O3: Jan | P3: Feb | Q3: Mar | R3: Apr | S3: May | T3: Jun | V3: GOK | W3: Source of funding | X3: Amount | Y3: Source of funding
A4: Mapping of snakes of medical importance and snakebite Hotspots | B4: Identify and map Snakes of Medical Importance and other venomous snakes, map intra and intercounty snakebite hotspots in endemic counties | C4: Train 5 program officers on mapping of snakes of Medical Importance and other venomous snakes using the Geographic Information System.(GIS) | D4: program officers trained on mapping of snakes of Medical Importance and other venomous snakes using the GIS system | E4: Number of program officers trained | F4: 5 | G4: Training programes/ schedules, training certificates | U4: 250000
C5: Procure voice recorders, digital camera, data collection tablets, laptops, GIS communication devices, power banks, high definition binoculars, printer, N ViVo analysis software, tents (10 units) | D5: Items procured | E5: Number of items procured | F5: 73 | G5: Invoices, DOF, Receipts | U5: ='1Y-Budget'!L15 -> 4843716
C6: Conduct a 5 day workshop for the training of data collectors on snakebite community-based survey methodologies in 10 counties (Kilifi, Marsabit, Wajir, Makueni, Samburu) | D6: Data collectors trained on community-based survey methodologies | E6: number of data collectors trained per county | F6: 5 | G6: Training certificates | U6: ='1Y-Budget'!F43 -> 12900000
C7: Survey 5 counties to map snakebite incidences (Procure subsistence allowance for 10 county data collectors, transport and DSA for 10 public officers for 3 weeks per county) | D7: counties surveyed for venomous snake identification and GIS mapping | E7: Number of counties surveyed, Species of snakes of medical importance and other venomous snakes identified, Number of county geographical maps developed | F7: 5 | G7: Vehicle work tickets, county approval letters, complete Snake species data sheets, County geographical maps | U7: ='1Y-Budget'!F13 -> 20797000
B8: Integrate Snakebite Envenoming mapping with other NTD programs | C8: Train healthcare workers and community healthcare promoters on protocols in integrating Snakebite Envenoming mapping with other NTD programs in 5 counties | D8: healthcare workers and community healthcare promoters in 5 counties trained on protocols in integrating Snakebite Envenoming mapping with other NTD programs | E8: number of counties trained | F8: 5 | G8: training schedules, attendance sheets, photo evidence | U8: ='1Y-Budget'!F70 -> 1835000
C9: Conduct surveys to integrate Snakebite Envenoming mapping with other NTD programs in 5 counties. (procure transport and DSA for 10 public officers for 5 days per county ) | D9: 10 counties surveyed for integration of snakebite envenoming mapping with other NTD programs | E9: Number of counties surveyed | F9: 5 | G9: Maps of surveyed counties, Vehicle work tickets, county approval letters | U9: ='1Y-Budget'!F84 -> 4925000
C10: Develop a user friendly community based reporting tool to report snakebite incidences and deaths across 8 counties | D10: Tool for reporting community-based snakebite incidences and deaths developed | E10: Number of reporting tools developed | F10: 1 | G10: reporting tool populated across 8 counties | U10: 300000
C11: Conduct a validation survey to assess and validate the reach and impact of surveys to integrate Snakebite Envenoming mapping with other NTD in 5 counties (procure transport and DSA for 10 public officers for 5 days per county) | D11: validation surveys conducted | E11: Number of counties where validation surveys were conducted | F11: 5 | G11: Validation report, Vehicle work tickets | U11: 0
C12: Disseminattion of survey findings to 5 counties (procure transport and DSA for 10 public officers for 12 days, 2 days per county- total 10 counties ) | D12: Dissemination conducted in counties where integration of snakebite envenoming mapping with other NTD programs was conducted | E12: Number of sub counties where dissemination was conducted | F12: 5 | G12: Report | U12: 0
B13: Integrate Snakebite mapping with the Kenya Livestock MasterPlan (KLMP) | C13: Train livestock ward officers and community healthcare promoters on protocols in integrating Snakebite integrating snakebite mapping with the KLMP in 5 counties | D13: healthcare workers and community healthcare promoters in 5 counties trained on protocols in integrating Snakebite Envenoming mapping with the Livestock program | E13: number of counties trained | F13: 5 | G13: training schedules, attendance sheets, photo evidence | U13: ='1Y-Budget'!F97 -> 1445000
C14: Survey 5 counties to integrate snakebite mapping with the KLMP in 5 counties (procure transport and DSA for 5 public officers for 10 days per county ) | D14: 5 counties surveyed for integration of snakebite envenoming mapping with other NTDs, Malaria and Livestock programs | E14: Number of counties surveyed | F14: 5 | G14: Maps of surveyed counties, Vehicle work tickets, county approval letters | U14: ='1Y-Budget'!F108 -> 9000000
C15: Conduct public awareness campaigns on snake identification, snakebite first aid and prevention and control measures in 5 counties | D15: awareness campaigns to educate communities on snakebite first aidnd prevention and control measures held | E15: Number of awareness campaigns held | F15: 5 | G15: Meeting notices, Photos | U15: ='1Y-Budget'!F122 -> 4481000
C16: Engage Social media, website & other digital platforms to create awareness on snake identification, snakebite first aid and prevention and control measures | D16: Social media, website & other digital platforms engaged | E16: Number of Social media, website & other digital platforms Engaged | F16: 10 | G16: Active Social Media Handles, Website | U16: =100000*5 -> 500000
C17: Conduct five school-based campaigns in each of the 10 counties to raise awareness among children on snake identification, first aid measures, and snakebite prevention and control. | D17: school based campaigns to raise awareness on snake identification, first aid measures and prevention and control of snakebite conducted (educational games, puppetries) | E17: Number of school based campaigns conducted | F17: 50 | G17: mpaign reports, attendance records, photographs, feedback forms | U17: ='1Y-Budget'!F135 -> 5425000
C18: Disseminate survey findings to 10 Counties (Kitui, Turkana, Lamu, Kwale, Baringo, Samburu) (procure transport and DSA for 15 public officers for 5 days) | D18: Dissemination conducted in counties where integration of snakebite envenoming mapping with KLMP programs was conducted | E18: Number of sub counties where dissemination was conducted | G18: Report | U18: 0
C19: Procure projector, flipcharts, rollup banners, tear drops | D19: Items procured | E19: number of items procured | F19: 30 | G19: Invoices, receipts | U19: 0
B20: Subtotal | U20: =SUM(U4:U19) -> 66701716
A21: Strengthen the Human Resource for snakebite management and antivenom production | B21: Human Resource and personnel | U21: 10620000
B22: Train health care workers on snakebite diagnosis, management, antivenom administration and snakebite prevention and control measures | C22: Conduct a county level Trainer of Trainer (ToT) trainings on snakebite diagnosis, management, antivenom administration and snakebite prevention and control measures to capacity build across different health care carders in 5 counties. Procure training venue, provide daily subsistence allowance (DSA) for 5 officers, and lunch allowance for 20 healthcare workers per county, for a duration of 5 days per county | D22: County ToTs trained on snakebite diagnosis, management, antivenom administration and snakebite prevention and control measure | E22: Number of counties trained | F22: 5 | G22: County approvals, Training Reports, training certificates, attendance sheets | U22: ='1Y-Budget'!F150 -> 12150000
C23: Conduct a Kenya Health Reporting System (KHIS) training workshop to county and subcounty Health Records Information Officers (HRIOs) to ensure complete accurate and timely reporting of snakebite and antivenom utilization data in 5 counties. Procure conference venue, transport, DSA for 5 officers, allowance for 20 (HRIOs) | D23: county and subcounty HRIOs trained on snakebite reporting in the KHIS | E23: Number of counties trained | F23: 5 | G23: Training reports | U23: ='1Y-Budget'!F210 -> 6905000
B24: Train Community Health Promoters (CHPs) on snake species identification, snakebite diagnosis, first aid, prevention and control measures | C24: organise a 5 day workshop to develop, update and improve CHP training modules Information, Education and Communication (IEC) materials on snakebite awareness, first aid measures and prevention and control of snakebite (secure workshop venue, transport and DSA for 15 officers) | D24: CHP training modules, IEC materials developed (posters, pullup banners, leaflets, T-shirts, lesos, Caps, brochures, pamplets) | E24: Number of IEC materials developed, Number of training modules imptroved | F24: 1 | G24: workshop report, attendance list, IEC materials and training mannuals | U24: ='1Y-Budget'!F223 -> 3035000
C25: Launch CHP training programs in 5 counties. procure workshop venue, transportation and DSA for 5 officers for 5 days per county. | D25: County CHP training programes launched | E25: Number of CHP Training programs launched | F25: 5 | G25: Attendance sheets, county approval letters, invitation letters, photos | U25: ='1Y-Budget'!F165 -> 7937000
C26: Train CHPs on snake species identification, snakebite diagnosis, first aid, prevention and control measures. (Procure IEC tools to populate amongst CHPs, procure workshop venue, transportation and DSA for 5 officers for 5 days per county) | D26: CHPs trained on snakebite diagnosis, treatment, management and rehabilitation | E26: Number of counties where CHPs were trained | F26: 5 | G26: Training reports, training certificates | U26: ='1Y-Budget'!F179 -> 6260000
C27: Implement Motorcycle Snakebite Emergency Response System (SERS) for Community Health Promoters (CHPs) to efficiently respond to snakebite incidents within the community. Procure fuel and maintenance for 6 motorcycle ambulances in 6 counties. | D27: motorcycle ambulances fuel and maintenance service procured | E27: Number of maintenance services per county | F27: 4 | G27: fuel invoices, receipts | U27: ='1Y-Budget'!F195 -> 2130000
A28: Subtotal | U28: =SUM(U21:U27) -> 49037000
A29: Grand total | U29: =U28+U20 -> 115738716

Sheet Itemized 1ywp
A2: Results Areas | B2: Main Activities | C2: Sub Activities | D2: Expected Outputs | E2: Performance Indicators | F2: Target | G2: Means of verification | I2: 2024/25 | U2: Estimated Cost | V2: Approved Budget (Rec & Dev) | X2: Off-budget resources | Z2: Funding Gap
H3: GOK | I3: July | J3: Aug | K3: Sep | L3: Oct | M3: Nov | N3: Dec | O3: Jan | P3: Feb | Q3: Mar | R3: Apr | S3: May | T3: Jun | V3: GOK | W3: Source of funding | X3: Amount | Y3: Source of funding
A4: Mapping of snakes of medical importance and snakebite Hotspots | B4: Identify and map Snakes of Medical Importance and other venomous snakes, map intra and intercounty snakebite hotspots in endemic counties | C4: Train 5 program officers on mapping of snakes of Medical Importance and other venomous snakes using the Geographic Information System.(GIS) | D4: program officers trained on mapping of snakes of Medical Importance and other venomous snakes using the GIS system | E4: Number of program officers trained | F4: 5 | G4: Training programes/ schedules, training certificates | U4: 250000 | V4: =U4 -> 250000 | W4: =V4 -> 250000
C5: Procure voice recorders, digital camera, data collection tablets, laptops, GIS communication devices, power banks, high definition binoculars, printer, N ViVo analysis software, tents (10 units) | D5: Items procured | E5: Number of items procured | F5: 73 | G5: Invoices, DOF, Receipts | U5: ='1Y-Budget'!L15 -> 4843716 | V5: =U5 -> 4843716 | W5: =V5 -> 4843716
C6: Conduct a 5 day workshop for the training of data collectors on snakebite community-based survey methodologies in 5 counties (Kilifi, Marsabit, Wajir, Makueni, Samburu) | D6: Data collectors trained on community-based survey methodologies | E6: number of data collectors trained per county | F6: 5 | G6: Training certificates | U6: ='1Y-Budget'!F43 -> 12900000 | V6: =U6/5 -> 2580000 | W6: =V6*2 -> 5160000
C7: Survey 5 counties to map snakebite incidences (Procure subsistence allowance for 10 county data collectors, transport and DSA for 10 public officers for 3 weeks per county) | D7: counties surveyed for venomous snake identification and GIS mapping | E7: Number of counties surveyed, Species of snakes of medical importance and other venomous snakes identified, Number of county geographical maps developed | F7: 5 | G7: Vehicle work tickets, county approval letters, complete Snake species data sheets, County geographical maps | U7: ='1Y-Budget'!F13 -> 20797000 | V7: =U7/5 -> 4159400 | W7: =V7*2 -> 8318800
B8: Integrate Snakebite Envenoming mapping with other NTD programs | C8: Train healthcare workers and community healthcare promoters on protocols in integrating Snakebite Envenoming mapping with other NTD programs in 5 counties | D8: healthcare workers and community healthcare promoters in 5 counties trained on protocols in integrating Snakebite Envenoming mapping with other NTD programs | E8: number of counties trained | F8: 5 | G8: training schedules, attendance sheets, photo evidence | U8: ='1Y-Budget'!F70 -> 1835000 | V8: =U8/5 -> 367000 | W8: =V8*2 -> 734000
C9: Conduct surveys to integrate Snakebite Envenoming mapping with other NTD programs in 5 counties. (procure transport and DSA for 10 public officers for 5 days per county ) | D9: 10 counties surveyed for integration of snakebite envenoming mapping with other NTD programs | E9: Number of counties surveyed | F9: 5 | G9: Maps of surveyed counties, Vehicle work tickets, county approval letters | U9: ='1Y-Budget'!F84 -> 4925000 | V9: =U9/5 -> 985000 | W9: =V9*2 -> 1970000
C10: Develop a user friendly community based reporting tool to report snakebite incidences and deaths across 5 counties | D10: Tool for reporting community-based snakebite incidences and deaths developed | E10: Number of reporting tools developed | F10: 1 | G10: reporting tool populated across 8 counties | U10: 300000 | V10: 0 | W10: =V10*2 -> 0
C11: Conduct a validation survey to assess and validate the reach and impact of surveys to integrate Snakebite Envenoming mapping with other NTD in 5 counties (procure transport and DSA for 10 public officers for 5 days per county) | D11: validation surveys conducted | E11: Number of counties where validation surveys were conducted | F11: 5 | G11: Validation report, Vehicle work tickets | U11: 0 | V11: =U11/5 -> 0 | W11: =V11*2 -> 0
C12: Disseminattion of survey findings to 5 counties (procure transport and DSA for 10 public officers for 12 days, 2 days per county- total 10 counties ) | D12: Dissemination conducted in counties where integration of snakebite envenoming mapping with other NTD programs was conducted | E12: Number of sub counties where dissemination was conducted | F12: 5 | G12: Report | U12: 0 | V12: =U12/5 -> 0 | W12: =V12*2 -> 0
B13: Integrate Snakebite mapping with the Kenya Livestock MasterPlan (KLMP) | C13: Train livestock ward officers and community healthcare promoters on protocols in integrating Snakebite integrating snakebite mapping with the KLMP in 5 counties | D13: healthcare workers and community healthcare promoters in 5 counties trained on protocols in integrating Snakebite Envenoming mapping with the Livestock program | E13: number of counties trained | F13: 5 | G13: training schedules, attendance sheets, photo evidence | U13: ='1Y-Budget'!F97 -> 1445000 | V13: =U13/5 -> 289000 | W13: =V13*2 -> 578000
C14: Survey 5 counties to integrate snakebite mapping with the KLMP in 5 counties (procure transport and DSA for 5 public officers for 10 days per county ) | D14: 5 counties surveyed for integration of snakebite envenoming mapping with other NTDs, Malaria and Livestock programs | E14: Number of counties surveyed | F14: 5 | G14: Maps of surveyed counties, Vehicle work tickets, county approval letters | U14: ='1Y-Budget'!F108 -> 9000000 | V14: =U14/5 -> 1800000 | W14: =V14*2 -> 3600000
C15: Conduct public awareness campaigns on snake identification, snakebite first aid and prevention and control measures in 5 counties | D15: awareness campaigns to educate communities on snakebite first aidnd prevention and control measures held | E15: Number of awareness campaigns held | F15: 5 | G15: Meeting notices, Photos | U15: ='1Y-Budget'!F122 -> 4481000 | V15: =U15/5 -> 896200 | W15: =V15*2 -> 1792400
C16: Engage Social media, website & other digital platforms to create awareness on snake identification, snakebite first aid and prevention and control measures | D16: Social media, website & other digital platforms engaged | E16: Number of Social media, website & other digital platforms Engaged | F16: 10 | G16: Active Social Media Handles, Website | U16: =100000*5 -> 500000 | V16: 0 | W16: =U16 -> 500000
C17: Conduct five school-based campaigns in each of the 10 counties to raise awareness among children on snake identification, first aid measures, and snakebite prevention and control. | D17: school based campaigns to raise awareness on snake identification, first aid measures and prevention and control of snakebite conducted (educational games, puppetries) | E17: Number of school based campaigns conducted | F17: 50 | G17: mpaign reports, attendance records, photographs, feedback forms | U17: ='1Y-Budget'!F135 -> 5425000 | V17: =U17/5 -> 1085000 | W17: =V17*2 -> 2170000
C18: Disseminate survey findings to 10 Counties (Kitui, Turkana, Lamu, Kwale, Baringo, Samburu) (procure transport and DSA for 15 public officers for 5 days) | D18: Dissemination conducted in counties where integration of snakebite envenoming mapping with KLMP programs was conducted | E18: Number of sub counties where dissemination was conducted | G18: Report | U18: 0 | V18: =U18/5 -> 0 | W18: =V18*2 -> 0
B19: Subtotal | U19: =SUM(U4:U18) -> 66701716 | W19: =SUM(W4:W18) -> 29916916 | X19: =U19-W19 -> 36784800
A20: Strengthen the Human Resource for snakebite management and antivenom production | B20: Human Resource and personnel | U20: 10620000 | V20: =U20/12 -> 885000 | W20: =V20*3 -> 2655000
B21: Train health care workers on snakebite diagnosis, management, antivenom administration and snakebite prevention and control measures | C21: Conduct a county level Trainer of Trainer (ToT) trainings on snakebite diagnosis, management, antivenom administration and snakebite prevention and control measures to capacity build across different health care carders in 5 counties. Procure training venue, provide daily subsistence allowance (DSA) for 5 officers, and lunch allowance for 20 healthcare workers per county, for a duration of 5 days per county | D21: County ToTs trained on snakebite diagnosis, management, antivenom administration and snakebite prevention and control measure | E21: Number of counties trained | F21: 5 | G21: County approvals, Training Reports, training certificates, attendance sheets | U21: ='1Y-Budget'!F150 -> 12150000 | V21: =U21/5 -> 2430000 | W21: =V21*2 -> 4860000
C22: Conduct a Kenya Health Reporting System (KHIS) training workshop to county and subcounty Health Records Information Officers (HRIOs) to ensure complete accurate and timely reporting of snakebite and antivenom utilization data in 5 counties. Procure conference venue, transport, DSA for 5 officers, allowance for 20 (HRIOs) | D22: county and subcounty HRIOs trained on snakebite reporting in the KHIS | E22: Number of counties trained | F22: 5 | G22: Training reports | U22: ='1Y-Budget'!F210 -> 6905000 | V22: =U22/5 -> 1381000 | W22: =V22*2 -> 2762000
B23: Train Community Health Promoters (CHPs) on snake species identification, snakebite diagnosis, first aid, prevention and control measures | C23: organise a 5 day workshop to develop, update and improve CHP training modules Information, Education and Communication (IEC) materials on snakebite awareness, first aid measures and prevention and control of snakebite (secure workshop venue, transport and DSA for 15 officers) | D23: CHP training modules, IEC materials developed (posters, pullup banners, leaflets, T-shirts, lesos, Caps, brochures, pamplets) | E23: Number of IEC materials developed, Number of training modules imptroved | F23: 1 | G23: workshop report, attendance list, IEC materials and training mannuals | U23: ='1Y-Budget'!F223 -> 3035000 | V23: =U23/5 -> 607000 | W23: =V23*2 -> 1214000
C24: Launch CHP training programs in 5 counties. procure workshop venue, transportation and DSA for 5 officers for 5 days per county. | D24: County CHP training programes launched | E24: Number of CHP Training programs launched | F24: 5 | G24: Attendance sheets, county approval letters, invitation letters, photos | U24: ='1Y-Budget'!F165 -> 7937000 | V24: =U24/5 -> 1587400 | W24: =V24*2 -> 3174800
C25: Train CHPs on snake species identification, snakebite diagnosis, first aid, prevention and control measures. (Procure IEC tools to populate amongst CHPs, procure workshop venue, transportation and DSA for 5 officers for 5 days per county) | D25: CHPs trained on snakebite diagnosis, treatment, management and rehabilitation | E25: Number of counties where CHPs were trained | F25: 5 | G25: Training reports, training certificates | U25: ='1Y-Budget'!F179 -> 6260000 | V25: =U25/5 -> 1252000 | W25: =V25*2 -> 2504000
C26: Implement Motorcycle Snakebite Emergency Response System (SERS) for Community Health Promoters (CHPs) to efficiently respond to snakebite incidents within the community. Procure fuel and maintenance for 6 motorcycle ambulances in 6 counties. | D26: motorcycle ambulances fuel and maintenance service procured | E26: Number of maintenance services per county | F26: 4 | G26: fuel invoices, receipts | U26: ='1Y-Budget'!F195 -> 2130000 | V26: 0 | W26: =V26*2 -> 0 | Y26: =X26*3 -> 0
A27: Subtotal | U27: =SUM(U20:U26) -> 49037000 | V27: =SUM(V20:V26) -> 8142400 | W27: =SUM(W20:W26) -> 17169800 | X27: =U27-W27 -> 31867200
A28: Grand total | U28: =U27+U19 -> 115738716

Sheet 1Y-Budget
A1: Sub activity 1
A2: ITEM | B2: UNIT COST | C2: QTY | D2: Days | E2: counties | F2: TOTAL | H2: Survey materials
A3: Per diem | B3: 14000 | C3: 10 | D3: 21 | E3: 5 | F3: =B3*C3*D3*E3 -> 14700000 | H3: Item | I3: No. | J3: QTY | K3: Unit cost | L3: Total
A4: conference | B4: 0 | C4: 0 | D4: 0 | E4: 0 | F4: =B4*C4*D4*E4 -> 0 | H4: Voice Recorder | I4: No. | J4: 10 | K4: 20000 | L4: =J4*K4 -> 200000
A5: fuel cost | B5: 200 | C5: 85 | D5: 21 | E5: 5 | F5: =B5*C5*D5*E5 -> 1785000 | H5: External Hards Disk 3TB | I5: No. | J5: 5 | K5: 26000 | L5: =J5*K5 -> 130000
A6: vehicle maintenance | B6: 0 | C6: 0 | D6: 0 | E6: 0 | F6: =B6*C6*D6*E6 -> 0 | H6: Digital Cameras | I6: No. | J6: 1 | K6: 490000 | L6: =J6*K6 -> 490000
A7: Air ticket | B7: 28000 | C7: 2 | D7: 1 | E7: 2 | F7: =B7*C7*D7*E7 -> 112000 | H7: laptops | I7: nos | J7: 2 | K7: 280000 | L7: =J7*K7 -> 560000
A8: Subsistence allowance | B8: 2500 | C8: 10 | D8: 21 | E8: 5 | F8: =B8*C8*D8*E8 -> 2625000 | H8: Tablets | I8: nos | J8: 20 | K8: 90000 | L8: =J8*K8 -> 1800000
A9: Training allowance | B9: 0 | C9: 0 | D9: 0 | E9: 0 | F9: =B9*C9*D9*E9 -> 0 | H9: Power Bank | I9: nos | J9: 20 | K9: 10000 | L9: =J9*K9 -> 200000
A10: Security | B10: 5000 | C10: 5 | D10: 21 | E10: 3 | F10: =B10*C10*D10*E10 -> 1575000 | H10: GPS Communicaton Devices | I10: nos | J10: 10 | K10: 50000 | L10: =J10*K10 -> 500000
F11: 0 | H11: Tents | J11: 10 | K11: 40000 | L11: =J11*K11 -> 400000
A12: training materials | B12: 0 | C12: 0 | D12: 0 | E12: 0 | F12: =B12*C12*D12*E12 -> 0 | H12: Printer | I12: nos | J12: 1 | K12: 50000 | L12: =J12*K12 -> 50000
A13: Total | B13: 0 | C13: 0 | D13: 0 | E13: 0 | F13: =SUM(F3:F12) -> 20797000 | H13: computer software | I13: nos | J13: 2 | K13: 131858 | L13: =J13*K13 -> 263716
H14: High Defination Binoculars | I14: No. | J14: 10 | K14: 25000 | L14: =J14*K14 -> 250000
L15: =SUM(L4:L14) -> 4843716
H16: Training materials
A17: Sub activity 2 | H17: Flip chart | I17: no | J17: 20 | K17: 2000 | L17: =J17*K17 -> 40000
A18: ITEM | B18: UNIT COST | C18: QTY | D18: Days | E18: counties | F18: TOTAL | H18: Flip chart stand | I18: no | J18: 5 | K18: 10000 | L18: =J18*K18 -> 50000
A19: Per diem | B19: 14000 | C19: 20 | D19: 3 | E19: 10 | F19: =B19*C19*D19*E19 -> 8400000 | H19: Roller Banners | J19: 5 | K19: 15000 | L19: =J19*K19 -> 75000
H20: Projector | J20: 1 | K20: 280000 | L20: =K20*J20 -> 280000
A21: conference | B21: 5000 | C21: 20 | D21: 3 | E21: 10 | F21: =B21*C21*D21*E21 -> 3000000 | H21: Tear Drops | J21: 20 | K21: 15000 | L21: =J21*K21 -> 300000
A22: fuel cost | B22: 200 | C22: 85 | D22: 3 | E22: 10 | F22: =B22*C22*D22*E22 -> 510000 | H22: printing | I22: no | J22: 1000 | K22: 1000 | L22: =J22*K22 -> 1000000
A23: vehicle maintenance | B23: 0 | C23: 0 | D23: 0 | E23: 0 | F23: =B23*C23*D23*E23 -> 0 | L23: =SUM(L17:L22) -> 1745000
A24: Air ticket | B24: 28000 | C24: 3 | D24: 1 | E24: 2 | F24: =B24*C24*D24*E24 -> 168000
A25: Subsistence allowance | B25: 0 | C25: 0 | D25: 0 | E25: 0 | F25: =B25*C25*D25*E25 -> 0
A26: Training allowance | B26: 0 | C26: 0 | D26: 0 | E26: 0 | F26: =B26*C26*D26*E26 -> 0
A27: Security | B27: 0 | C27: 0 | D27: 0 | E27: 0 | F27: =B27*C27*D27*E27 -> 0
A28: training materials | B28: 0 | C28: 0 | D28: 0 | E28: 0 | F28: =B28*C28*D28*E28 -> 0
A29: Media | B29: 0 | C29: 0 | D29: 0 | E29: 0 | F29: 0
F30: =SUM(F19:F28) -> 12078000
A32: Sub activity 3
A33: ITEM | B33: UNIT COST | C33: QTY | D33: Days | E33: counties | F33: TOTAL
A34: Per diem | B34: 14000 | C34: 10 | D34: 5 | E34: 10 | F34: =B34*C34*D34*E34 -> 7000000
A35: conference | B35: 5000 | C35: 10 | D35: 5 | E35: 10 | F35: =B35*C35*D35*E35 -> 2500000
A36: fuel cost | B36: 200 | C36: 85 | D36: 5 | E36: 10 | F36: =B36*C36*D36*E36 -> 850000
A37: vehicle maintenance | B37: 0 | C37: 0 | D37: 0 | E37: 0 | F37: =B37*C37*D37*E37 -> 0
A38: Air ticket | B38: 0 | C38: 0 | D38: 0 | E38: 0 | F38: =B38*C38*D38*E38 -> 0
A39: Subsistence allowance | B39: 2500 | C39: 10 | D39: 5 | E39: 10 | F39: =B39*C39*D39*E39 -> 1250000
A40: Training allowance | B40: 2000 | C40: 2 | D40: 30 | E40: 10 | F40: =B40*C40*D40*E40 -> 1200000
A41: training materials | B41: 10000 | C41: 1 | D41: 1 | E41: 10 | F41: =B41*C41*D41*E41 -> 100000
...

Sheet ksric budget
B2: ITEM DESCRIPTION | C2: UNIT | D2: QTY | E2: ESTIMATED UNIT PRICE | F2: TOTAL ESTIMATED PRICE | G2: USER DEPT | H2: PROCUREMENT METHOD | I2: SOURCE OF FUNDS | J2: YOUTH | K2: WOMEN | L2: PWD | M2: OPEN | N2: QUARTER REQUIRED
N3: 1ST | P3: 2ND | R3: 3RD | T3: 4TH
N4: QTY | O4: KSH | P4: QTY | Q4: KSH | R4: QTY | S4: KSH | T4: QTY | U4: KSH
A5: 1.Licenses and permits
A6: 1 | B6: NACOSTI research license | D6: 1 | E6: 10000 | F6: =D6*E6 -> 10000 | G6: KSRIC | H6: Direct Procurement | I6: GOK | M6: √ | T6: 1 | U6: =D6*E6 -> 10000
A7: 2 | B7: WRTI research permit | D7: 1 | E7: 10000 | F7: =D7*E7 -> 10000 | G7: KSRIC | H7: Direct Procurement | I7: GOK | M7: √ | T7: 1 | U7: =D7*E7 -> 10000
A8: 3 | B8: NEMA access permit | D8: 1 | E8: 50000 | F8: =D8*E8 -> 50000 | G8: KSRIC | H8: Direct Procurement | I8: GOK | M8: √ | T8: 1 | U8: =D8*E8 -> 50000
A9: 4 | B9: KWS research permit | D9: 1 | E9: 10000 | F9: =D9*E9 -> 10000 | G9: KSRIC | H9: Direct Procurement | I9: GOK
A10: 5 | B10: ISO Certificate | D10: 1 | G10: KSRIC | H10: Direct Procurement | I10: GOK | M10: √
A13: 2.Medical and veterinary supplies consumables | U13: =D13*E13 -> 0
A14: 2 | B14: SAIMR monovalent antivenom(Boomslang), EchiTab-Plus monovalent antivenom , Saimr polyvalent | C14: PKT | D14: 50 | E14: 72000 | F14: =D14*E14 -> 3600000 | H14: Direct Procurement | I14: GOK | M14: √ | T14: 120 | U14: =D14*E14 -> 3600000
A15: 4 | B15: 30 gauge insulin/trajector syringes | C15: box | D15: 20 | E15: 3600 | F15: =D15*E15 -> 72000 | H15: RFQ | I15: GOK | T15: 20 | U15: =D15*E15 -> 72000
A16: 5 | B16: cotton wool | C16: roll | D16: 10 | E16: 600 | F16: =D16*E16 -> 6000 | H16: RFQ | I16: GOK | T16: 10 | U16: =D16*E16 -> 6000
A17: 6 | B17: dissecting kit | C17: no | D17: 3 | E17: 30000 | F17: =D17*E17 -> 90000 | H17: RFQ | I17: GOK | T17: 3 | U17: =D17*E17 -> 90000
A18: 7 | B18: formaldehyde | C18: 2.5litres | D18: 4 | E18: 3600 | F18: =D18*E18 -> 14400 | H18: RFQ | I18: GOK | T18: 4 | U18: =D18*E18 -> 14400
A19: 8 | B19: surgical spirit | C19: 5litres | D19: 10 | E19: 2600 | F19: =D19*E19 -> 26000 | H19: RFQ | I19: GOK | T19: 4 | U19: =D19*E19 -> 26000
A20: 9 | B20: Nitrile gloves-Large | C20: Pkt | D20: 30 | E20: 1600 | F20: =D20*E20 -> 48000 | H20: RFQ | I20: GOK | T20: 30 | U20: =D20*E20 -> 48000
A21: 10 | B21: Nitrile gloves medium | C21: Pkt | D21: 30 | E21: 1500 | F21: =D21*E21 -> 45000 | H21: RFQ | I21: GOK | T21: 30 | U21: =D21*E21 -> 45000
A22: 11 | B22: Nitrile gloves small | C22: Pkt | D22: 30 | E22: 1600 | F22: =D22*E22 -> 48000 | H22: RFQ | I22: GOK | T22: 30 | U22: =D22*E22 -> 48000
A23: 12 | B23: Bio hazards bags | C23: Pkt | D23: 4 | E23: 8500 | F23: =D23*E23 -> 34000 | H23: RFQ | I23: GOK | T23: 4 | U23: =D23*E23 -> 34000
A24: 13 | B24: Disposable bags | C24: Pkt | D24: 4 | E24: 5000 | F24: =D24*E24 -> 20000 | H24: RFQ | I24: GOK | T24: 4 | U24: =D24*E24 -> 20000
A25: 14 | B25: Dustbins | C25: No. | D25: 10 | E25: 9200 | F25: =D25*E25 -> 92000 | H25: RFQ | I25: GOK | T25: 10 | U25: =D25*E25 -> 92000
A26: 15 | B26: Oxytetracycline | C26: 100ml | D26: 20
A27: 16 | B27: Penstrep | C27: 100ml | D27: 20
A28: 17 | B28: Biotrin | C28: 200g | D28: 10
A29: 18 | B29: Piperazin | C29: 100g | D29: 20
A30: 19 | B30: Albafas 10% | C30: 1liter | D30: 20
A31: 20 | B31: Hydrogen peroxide | C31: 200ml | D31: 10
A32: 21 | B32: Iodine | C32: 500ml | D32: 10
A33: 22 | B33: Ivermectin | C33: 100ml | D33: 10
A34: 23 | B34: Jik | C34: 5litres | D34: 30
A35: 24 | B35: 20ml ordinary syringe | C35: PKT | D35: 10
A36: 25 | B36: 5ml Ordinary syringe | C36: pkt | D36: 10
U38: =D38*E38 -> 0
A39: 3.Medical and veterinary supplies non consumbles | U39: =D39*E39 -> 0
A40: 1 | B40: First Aid kit | C40: No | D40: 2 | E40: 25000 | F40: =D40*E40 -> 50000 | G40: KSRIC | H40: RFQ | I40: GOK | M40: √ | T40: 2 | U40: =D40*E40 -> 50000
A41: 2 | B41: Eye wash and mounted station | C41: No | D41: 6 | E41: 20000 | F41: =D41*E41 -> 120000 | G41: KSRIC | H41: RFQ | I41: GOK | M41: √ | T41: 6 | U41: =D41*E41 -> 120000
A42: 3 | B42: Spray Bottles 500ml | C42: No | D42: 20 | E42: 480 | F42: =D42*E42 -> 9600 | H42: RFQ | I42: GOK | T42: 20 | U42: =D42*E42 -> 9600
A43: 5 | B43: Wash Bottles 500ml | C43: NO | D43: 20 | E43: 1600 | F43: =D43*E43 -> 32000 | H43: RFQ | I43: GOK | T43: 20 | U43: =D43*E43 -> 32000
A44: 6 | B44: Snake bite emergency kit | C44: no | F44: =D44*E44 -> 0 | U44: =D44*E44 -> 0
...
