Workbook

Sheet Sheet1
C4: ANNUAL WORK PLAN 2024- 2025
C5: Programme Name: ……………………………………………………………….
C6: Programme Outcome: ……………………………………………………………….
C7: Sub-Programme Name: ……………………………………………………………….
C8: Delivery Unit/Directorate/Division/Section Name: ……………………………………………………………….
C9: Results Areas | D9: Main Activities | E9: Sub Activities | F9: Expected Outputs | G9: Performance Indicators | H9: Target | I9: Means of verification | J9: 2024/25 | V9: Estimated Cost | W9: Approved Budget (Rec & Dev) | Y9: Off-budget resources | AA9: Funding Gap
J10: July | K10: Aug | L10: Sep | M10: Oct | N10: Nov | O10: Dec | P10: Jan | Q10: Feb | R10: Mar | S10: Apr | T10: May | U10: Jun | W10: GOK | X10: Source of funding | Y10: Amount | Z10: Source of funding
B11: 5 | C11: Modernization and expansion of infrastructure and equipment for antivenom research and production | D11: Feasibility study for anti-venom fill & finish facility | E11: Visit antivenom manufacturing and commercial partners for feasibility study | F11: Antivenom manufacturing and commercial partners visited | G11: Number of visits to antivenom manufacturing and commercial partners | H11: 3 | I11: Meeting reports, Invoices for return air tickets, DSA | V11: ='Budget Estimates'!C31 -> 23972945
E12: Perform Snakebite Envenoming (SBE) antivenom market analysis & Survey. (local, Regional & International: consultancy Services) | F12: Snakebite Envenoming (SBE) antivenom market analysis performed | G12: Number of SBE antivenom market analysis reports | H12: 6 | I12: Meeting reports, Invoices for return air tickets, DSA | V12: ='Budget Estimates'!B67 -> 15833740
E13: Conduct Environmental Impact Assessment for Snakebite preclinical rodent & biocontainment facility | F13: Environmental Impact Assessment for Fill and Finish Facility conducted | G13: Number of NEMA permits | H13: 1 | I13: NEMA permit | V13: ='Budget Estimates'!B73 -> 2726000
E14: Develop architectural designs and estimamted BQs for anti-venom fill and finish facility | F14: Architectural and estimated BQs for Fill and Finish facility designed | G14: Number of Architectural design and BQs | H14: 2 | I14: Approved architectural designs & BQ | V14: ='Budget Estimates'!D86 -> 2380000
E15: Technology transfer for establishing the antivenom Fill & Finish facility | F15: Skills & technology for antivenom fill & finish acquired | G15: Number of staff deployed | H15: 2 | I15: Signed letter of deployment
E16: Advertise for tender for construction of fill & finish facility | F16: Fill & Finish facility tender advertised | G16: Number of advertisements | H16: 3 | I16: Tender documents, PVs
E17: Award contract for antivenom fill & finish facility | F17: Fill & Finish facility contract awarded | G17: Number of contracts | H17: 1 | I17: Signed contract
D18: Initiate the establishment of Snakebite Preclinical rodent & bio-containment facility | E18: Develop architectural designs and estimated BQs for Snakebite Preclinical rodent & biocontainment facility | F18: Architectural and estimated BQs for Snakebite Preclinical rodent & biocontainment facility developed | G18: Number of Architectural design and BQs | H18: 2 | I18: Approved architectural designs & BQ | V18: ='Budget Estimates'!L9 -> 2380000
E19: Conduct Environmental Impact Assessment for Snakebite preclinical rodent & biocontainment facility | F19: Environmental Impact Assessment for Snakebite preclinical rodent & biocontainment facility conducted | G19: Number of NEMA permits | H19: 1 | I19: NEMA permit | V19: ='Budget Estimates'!L27 -> 1876000
E20: Advertise for tender for construction of Snakebite Preclinical rodent & bio-containment facility | F20: Snakebite preclinical rodent & bio-containment facility tender advertised | G20: Number of advertisements | H20: 3 | I20: Tender documents, PVs | V20: ='Budget Estimates'!J32 -> 250000
E21: Award contract for snakebite preclinical rodent & bio-containment facility | F21: Snakebite preclinical rodent & bio-containment facility contract awarded | G21: Number of contracts | H21: 1 | I21: Signed contract | V21: ='Budget Estimates'!L41 -> 1160000
D22: Initiate the establishment of snakebite venom & anti-venom research Laboratories, Coldroom, Offices & conference /training facility | E22: Develop architectural designs and estimated BQs for snakebite venom & anti-venom research Laboratories, Coldroom, Offices & conference /training facility | F22: Architectural designs and estinated BQs for snakebite venom & anti-venom research Laboratories, Coldroom, Offices & conference /training facility developed | G22: Number of Architectural designs and BQs | H22: 2 | I22: Approved architectural designs & BQ | V22: ='Budget Estimates'!L49 -> 2380000
E23: Conduct Environmental Impact Assessment for Snakebite venom & anti-venom research Laboratories, Coldroom, Offices & conference /training facility | F23: Environmental Impact Assessment for snakebite venom & anti-venom research Laboratories, Coldroom, Offices & conference /training facility facility conducted | G23: Number of NEMA permits | H23: 1 | I23: NEMA permit | V23: ='Budget Estimates'!J61 -> 2726000
E24: Advertise for tender for snakebite venom & anti-venom research Laboratories, Coldroom, Offices & conference /training facility | F24: Tender for snakebite venom & anti-venom research Laboratories, Coldroom, Offices & conference /training facility advertised | G24: Number of advertisements | H24: 3 | I24: Tender documents, PVs | V24: ='Budget Estimates'!J73 -> 250000
D25: Upgrading of the Herpatarium building | E25: Installation of HVAC system | F25: HVAC System installed | G25: Number of units | H25: 1 | I25: DOF, LPO issued, Delivery Notes | V25: ='Budget Estimates'!L77 -> 2400000
E26: Purchase of snake cages | F26: Snake cages & racks purchased | G26: Number of snake cages | H26: 196 | I26: DOF, LPO issued, Delivery Notes | V26: ='Budget Estimates'!L88 -> 4085000
E27: Installation of CCTV cameras and motion sensors | F27: CCTV cameras and motion sensors installed | G27: Number of CCTV cameras & motion sensors | H27: 4 | I27: DOF, LPO issued, Delivery Notes | V27: ='Budget Estimates'!L79 -> 1400000
E28: Purchase of snake enrichment devices | F28: Snake enrichment devices purchased | G28: Number of snakebite enrichment devices | I28: DOF, LPO issued, Delivery Notes | V28: ='Budget Estimates'!L80 -> 900000
D29: Initiate Process of land procurement and construction of animal housing facility for venom research & antivenom production | E29: Initiate purchase of atleast 20 acres piece of land for construction of animal facility for antivenom production | F29: Atleast 20 acres piece of land identified | G29: Number of acres of land identified | H29: 20 | I29: Site visits reports, Survey reports | V29: ='Budget Estimates'!L94 -> 1070200
E30: Construct horse stable, Phlebotomy rooms, plasma/sera isolation laboratories, offices and paddocks | F30: Horse stable, plebotomy rooms, plasma/sera isolation laboratory, paddocks and offices contracted
D31: Purchase of equipment for snakebite venom & antivenom Research & Development | E31: Procurement of fill & finish equipment & installation | F31: Fill & Finish equipment procured | G31: Number of packaging machines procured | H31: 2 | I31: DOF, LPO issued, Delivery Notes
E32: Procurement of Laboratory, cold room & phlebetomy facility equipment | F32: Laboratory, cold room & phlebetomy facility equipment procured | G32: Number of general laboratory equipment procured | H32: 18 | I32: DOF, LPO issued, Delivery Notes | V32: ='Budget Estimates'!L234 -> 158546020
E33: Procurement of audio visual equipment | F33: Audio visual equipment procured | G33: Number of Public address systems,video cameras & accessories, photo camera & accessories & video teleconferencing equipment | H33: 6 | I33: DOF, LPO issued, Delivery Notes | V33: ='Budget Estimates'!L110 -> 2218898
E34: Procurement of field vehicles & snakebite ambulances | F34: Field vehicles & snakebite ambulances procured | G34: Number of Field vehicles & snakebite ambulances | H34: 6 | I34: DOF, LPO issued, Delivery Notes | V34: ='Budget Estimates'!L115 -> 19200000
E35: Procurement of office furniture & equipment | F35: Office furniture & equipment procured | G35: Number of offices / counters Equipped | H35: 8 | I35: DOF, LPO issued, Delivery notes | V35: ='Budget Estimates'!M185 -> 2674597
E36: Procurement of software - Antivirus | F36: Software & licences procured | G36: Number of Software & licences procured | H36: 20 | I36: Licences Issued | V36: ='Budget Estimates'!L239 -> 420000
E37: Leverage IT infrastructure/ internet expansion & optimization at the new snakebite facilities | F37: IT infrastructure/ internet expansion & optimization at the new snakebite facilities Leveraged | G37: Nimber of offices leveraged | H37: 8 | I37: DOF, LPO issued, Delivery notes | V37: ='Budget Estimates'!M187 -> 13500000
D38: Servicing & Calibration of equipment | E38: Procurement of equipment maintenance services | F38: Equipment maintenance services procured | G38: Number of contracts signed | H38: 5 | I38: Signed Contract | V38: ='Budget Estimates'!L237 -> 6000000
E39: Procurement of Insurance services | F39: Insurance services procured | G39: Number of contracts signed | H39: 1 | I39: Signed Contract | V39: ='Budget Estimates'!L238 -> 2500000
B40: 6 | C40: Partnership on research and antivenom production | D40: Initiate partnership on research and antivenom production | E40: Identify antivenom commercial and manufacturing partners eg. Premium Serum & Vaccines PVT Ltd, Universal Corporation | F40: Identified antivenom commercial and manufacturing partners | G40: Number of Signed MoUs, Signed contracts | H40: 3 | I40: Meeting reports, Invoices for return air tickets, DSA | V40: ='Budget Estimates'!V20 -> 2480000
E41: Formulate snakebite management guidelines & policies | F41: Snake management Policies and Guidelines Formulated | G41: Number of Policies and guidelines | H41: 2 | I41: Attendance Register | V41: ='Budget Estimates'!V41 -> 11463200
E42: Mapping of snakebite partners,stakeholders & collaborators | F42: Snakebite Partners, Stakeholders and Partners mapped | G42: Number of snakebite partners & stakeholderds | H42: 3 | I42: Meeting reports | V42: ='Budget Estimates'!V59 -> 11600000
E43: Acquire statutory obligations and regulations | F43: Statutory Obligations and Regulatons acquired | G43: Number of permits and Licenses | H43: 3 | I43: Request Letter, Meeting reports | V43: ='Budget Estimates'!V81 -> 16397600
...

Sheet Budget Estimates
A1: Key Result Area: Modernization and expansion of infrastructure and equipment for antivenom research and production | I1: Key Result Area: Modernization and expansion of infrastructure and equipment for antivenom research and production | Q1: Key Result Area: Partnership on research and antivenom production
A2: Main Activity: Feasibility study for Fill & Finish | I2: Main Activity: Initiate the establishment of Snakebite Preclinical rodent & bio-containment facility | Q2: Main Activity:Initiate partnership on research and antivenom production
A3: Sub Activity 1: Visit to Anti Venom Commercial Partners | I3: Sub Activity 1: Develop architectural designs and estimated BQs for Snakebite Preclinical rodent & biocontainment facility | Q3: Sub Activity 1: Identify antivenom commercial and manufacturing partners eg. Premium Serum & Vaccines PVT Ltd, Universal Corporation
A4: India | B4: No. | C4: Pax/Item | D4: Rate | E4: Number | F4: No. of days | G4: Amount | Q4: Local | R4: No. | S4: Pax/Item | T4: Rate | U4: Number | V4: No. of days | W4: Amount
B5: 1 | C5: DG | D5: 74624 | E5: 1 | F5: 7 | G5: =D5*F5*E5 -> 522368 | I5: Architectural design | J5: (6-10% of the total cost) | K5: 10% of 10m | L5: =10%*10000000 -> 1000000 | R5: 1 | S5: DG | T5: 16800 | U5: 1 | V5: 7 | W5: =T5*V5*U5 -> 117600
B6: 2 | C6: CoR | D6: 56394 | E6: 1 | F6: 7 | G6: =D6*F6*E6 -> 394758 | I6: Structural design | J6: 3.5% -4.5% of the total Cost | L6: =4.5% *10000000 -> 450000 | R6: 2 | S6: CoR | T6: 14000 | U6: 1 | V6: 7 | W6: =T6*V6*U6 -> 98000
B7: 3 | C7: K-SRIC Lead | D7: 56394 | E7: 1 | F7: 7 | G7: =D7*F7*E7 -> 394758 | I7: BQ | J7: Ksh. 41,600 per sq metre | L7: 450000 | R7: 3 | S7: K-SRIC Lead | T7: 14000 | U7: 1 | V7: 7 | W7: =T7*V7*U7 -> 98000
B8: 4 | C8: K-SRIC Technical | D8: 47345 | E8: 2 | F8: 7 | G8: =D8*F8*E8 -> 662830 | I8: Workshop | L8: =L15 -> 480000 | R8: 4 | S8: K-SRIC Technical | T8: 11200 | U8: 4 | V8: 7 | W8: =T8*V8*U8 -> 313600
B9: 5 | C9: MPs | D9: 82000 | E9: 3 | F9: 7 | G9: =D9*F9*E9 -> 1722000 | L9: =SUM(L5:L8) -> 2380000 | R9: 5 | S9: Board Members | T9: 18200 | U9: 4 | V9: 7 | W9: =T9*V9*U9 -> 509600
B10: 6 | C10: Board Members | D10: 74624 | E10: 4 | F10: 7 | G10: =D10*F10*E10 -> 2089472 | R10: 6 | S10: Technical Staff | T10: 14000 | U10: 3 | V10: 7 | W10: =T10*V10*U10 -> 294000
I11: Details | J11: Unit Cost | K11: Number | L11: Amount | R11: 7 | S11: Support Staff | T11: 11200 | U11: 3 | V11: 7 | W11: =T11*V11*U11 -> 235200
I12: Per diem | J12: 14000 | K12: 20 | L12: =J12*K12 -> 280000 | W12: =SUM(W5:W11) -> 1666000
A13: Costa-Rica | B13: 1 | C13: DG | D13: 64000 | E13: 1 | F13: 7 | G13: =D13*F13*E13 -> 448000 | I13: Conference | J13: 5000 | K13: 20 | L13: =J13*K13 -> 100000
B14: 2 | C14: CoR | D14: 48656 | E14: 1 | F14: 7 | G14: =D14*F14*E14 -> 340592 | I14: Fuel cost & Vehicle maintenance | J14: 100000 | K14: 1 | L14: =J14*K14 -> 100000
B15: 3 | C15: K-SRIC Lead | D15: 48656 | E15: 1 | F15: 7 | G15: =D15*F15*E15 -> 340592 | I15: Total | L15: =SUM(L12:L14) -> 480000 | Q15: Details | S15: Pax | T15: Days | U15: Rate | V15: Amount
B16: 4 | C16: K-SRIC Technical | D16: 40918 | E16: 2 | F16: 7 | G16: =D16*F16*E16 -> 572852 | Q16: Conference costs | S16: 17 | T16: 7 | U16: 5000 | V16: =S16*T16* 5000 -> 595000
B17: 5 | C17: MPs | D17: 70427 | E17: 3 | F17: 7 | G17: =D17*F17*E17 -> 1478967 | I17: Sub Activity 2 : EIA for snakebite preclinical rodent & bio-containment facility | Q17: Perdiem | S17: 17 | T17: 7 | V17: =W12 -> 1666000
B18: 6 | C18: Board Members | D18: 70427 | E18: 4 | F18: 7 | G18: =D18*F18*E18 -> 1971956 | I18: Nema Permit- Corporate | J18: 50000 | Q18: Local Running | S18: 17 | T18: 7 | U18: 1000 | V18: =S18*T18*U18 -> 119000
C19: Total | G19: =SUM(G5:G18) -> 10939145 | I19: EIA Consultant | J19: 800000 | Q19: Fuel & Vehicle Maintenance | V19: 100000
I20: Workshop costs | J20: =L27 -> 1876000 | Q20: Total | V20: =SUM(V16:V19) -> 2480000
J21: =SUM(J18:J20) -> 2726000
B22: Local Running Costs | C22: no. of pax | D22: Number of Days | E22: amount | I22: Details- Two workshops | J22: Unit Cost | K22: Number | L22: Amount | Q22: Sub activity 2: Formulate snakebite management guidelines & policies
B23: 10000 | C23: 24 | D23: 14 | E23: =B23*C23*D23 -> 3360000 | I23: Per diem | J23: 14000 | K23: 30 | L23: =J23*K23 -> 420000 | Q23: Local | R23: No. | S23: Pax/Item | T23: Rate | U23: Number | V23: No. of days | W23: Amount
I24: Conference | J24: 5000 | K24: 30 | L24: =J24*K24 -> 150000 | R24: 1 | S24: DG | T24: 16800 | U24: 1 | V24: 21 | W24: =T24*V24*U24 -> 352800
B25: Flight Tickets | C25: India & Dubai | I25: Fuel cost & Vehicle maintenance | J25: 100000 | K25: 2 | L25: =J25*K25 -> 200000 | R25: 2 | S25: CoR | T25: 14000 | U25: 1 | V25: 21 | W25: =T25*V25*U25 -> 294000
B26: Details | D26: Number | E26: Price | F26: Amount | I26: Subsistence Allowance | J26: 4200 | K26: 40 | L26: =J26*K26 -> 168000 | R26: 3 | S26: K-SRIC Lead | T26: 14000 | U26: 1 | V26: 21 | W26: =T26*V26*U26 -> 294000
B27: Business class | D27: 14 | E27: 450000 | F27: =D27*E27 -> 6300000 | I27: Total | L27: =SUM(L23:L26)*2 -> 1876000 | R27: 4 | S27: K-SRIC Technical | T27: 11200 | U27: 15 | V27: 21 | W27: =T27*V27*U27 -> 3528000
B28: Premium Economy | D28: 4 | E28: 393450 | F28: =D28*E28 -> 1573800 | R28: 5 | S28: Board Members | T28: 18200 | U28: 4 | V28: 21 | W28: =T28*V28*U28 -> 1528800
B29: Economy | D29: 6 | E29: 300000 | F29: =D29*E29 -> 1800000 | I29: Sub Activity 3: Advertisement of tender for snakebite preclinical rodent & bio containment facility | R29: 6 | S29: Technical Staff | T29: 14000 | U29: 3 | V29: 21 | W29: =T29*V29*U29 -> 882000
B30: Total | F30: =SUM(F27:F29) -> 9673800 | I30: Details | J30: Amount | R30: 7 | S30: Support Staff | T30: 11200 | U30: 3 | V30: 21 | W30: =T30*V30*U30 -> 705600
B31: Total Cost | C31: =G19+E23+F30 -> 23972945 | I31: Newspaper Advertisement | J31: 250000 | W31: =SUM(W24:W30) -> 7585200
J32: =SUM(J31) -> 250000
A33: Sub Activity 2: Snakebite Envenoming (SBE) antivenom market analysis
A34: Local | B34: No. | C34: Pax/Item | D34: Rate | E34: Number | F34: No. of days | G34: Amount | I34: Sub Activity 4: Award contract for snakebite preclinical rodent & bio-containment facility | Q34: Details | S34: Pax | T34: Days | U34: Rate | V34: Amount
B35: 1 | C35: DG | D35: 16800 | E35: 1 | F35: 7 | G35: =D35*F35*E35 -> 117600 | I35: Opening & Evaluation of tender | Q35: Conference costs | S35: 28 | T35: 21 | U35: 5000 | V35: =S35*T35* 5000 -> 2940000
B36: 2 | C36: CoR | D36: 14000 | E36: 1 | F36: 7 | G36: =D36*F36*E36 -> 98000 | I36: Details- Two workshops | J36: Unit Cost | K36: Number | L36: Amount | Q36: Perdiem | S36: 28 | T36: 21 | V36: =W31 -> 7585200
B37: 3 | C37: K-SRIC Lead | D37: 14000 | E37: 1 | F37: 7 | G37: =D37*F37*E37 -> 98000 | I37: Per diem | J37: 14000 | K37: 20 | L37: =J37*K37 -> 280000 | Q37: Local Running | S37: 28 | T37: 21 | U37: 1000 | V37: =S37*T37*U37 -> 588000
B38: 4 | C38: K-SRIC Technical | D38: 11200 | E38: 2 | F38: 7 | G38: =D38*F38*E38 -> 156800 | I38: Conference | J38: 5000 | K38: 20 | L38: =J38*K38 -> 100000 | Q38: Fuel & Vehicle Maintenance | V38: 200000
B39: 5 | C39: Board Members | D39: 18200 | E39: 4 | F39: 7 | G39: =D39*F39*E39 -> 509600 | I39: Fuel cost & Vehicle maintenance | J39: 50000 | K39: 2 | L39: =J39*K39 -> 100000 | Q39: Stationery | V39: 50000
B40: 6 | C40: Technical Staff | D40: 14000 | E40: 3 | F40: 7 | G40: =D40*F40*E40 -> 294000 | I40: Stationery | J40: 50000 | K40: 2 | L40: =J40*K40 -> 100000 | Q40: Printing | V40: 100000
...
