Workbook

Sheet Sheet1
C2: TABLE I: STAFF ESTABLISHMENT AND PROJECTIONS-KENYA INSTITUTE OF PRIMATE RESEARCH (KIPRE)
A5: Programme Code | B5: Programme Title | C5: Designation /Position Title | D5: PRN | E5: Names | F5: Highest qualifications | G5: KIP Grade | H5: Job Group (KIP Grade) | I5: Career guideline page no. | J5: current grade | K5: Authorized Establishment | L5: In Post as at June 2025 | M5: 2025/2026 | N5: 2026/2027 | O5: 2027/2028 | P5: 2028/2029
M6: Funded positions | N6: Positions to be funded | O6: Positions to be funded
C7: OFFICE OF THE DIRECTOR GENERAL/ CEO
C8: Director General / CEO | D8: 19901899045 | E8: Dr. Mwethera, Peter Gichuhi | F8: =IF(D8="", "", VLOOKUP(D8, Sheet3!C:P, 14, FALSE) & ", " & DATEDIF(VLOOKUP(D8, Sheet3!C:N, 12, FALSE), TODAY(), "y") & " Years Experience") -> PhD, MSc, Bachelors, KCSE, KCPE, 36 Years Experience | H8: 1 | K8: 1 | L8: 1
C9: Technical Assistant | F9: =IF(D9="", "", VLOOKUP(D9, Sheet3!C:P, 14, FALSE) & ", " & DATEDIF(VLOOKUP(D9, Sheet3!C:N, 12, FALSE), TODAY(), "y") & " Years Experience") | H9: 0 | K9: 0 | L9: 0 | N9: 0
C10: Principal Office Administrator | F10: =IF(D10="", "", VLOOKUP(D10, Sheet3!C:P, 14, FALSE) & ", " & DATEDIF(VLOOKUP(D10, Sheet3!C:N, 12, FALSE), TODAY(), "y") & " Years Experience") | H10: 5 | K10: 1 | L10: 1
C11: Office Administrator/ Senior | D11: 19990495773 | E11: Mrs. Hassan, Hamida Adam | F11: =IF(D11="", "", VLOOKUP(D11, Sheet3!C:P, 14, FALSE) & ", " & DATEDIF(VLOOKUP(D11, Sheet3!C:N, 12, FALSE), TODAY(), "y") & " Years Experience") -> Dip, KCSE, KCPE, 27 Years Experience | H11: 7/6
C12: Principal Driver | F12: =IF(D12="", "", VLOOKUP(D12, Sheet3!C:P, 14, FALSE) & ", " & DATEDIF(VLOOKUP(D12, Sheet3!C:N, 12, FALSE), TODAY(), "y") & " Years Experience") | H12: 9 | K12: 1 | L12: 1
C13: Driver/Senior | F13: =IF(D13="", "", VLOOKUP(D13, Sheet3!C:P, 14, FALSE) & ", " & DATEDIF(VLOOKUP(D13, Sheet3!C:N, 12, FALSE), TODAY(), "y") & " Years Experience") | H13: 11/10
C14: Principal Office Assistant | F14: =IF(D14="", "", VLOOKUP(D14, Sheet3!C:P, 14, FALSE) & ", " & DATEDIF(VLOOKUP(D14, Sheet3!C:N, 12, FALSE), TODAY(), "y") & " Years Experience") | H14: 10 | K14: 1 | L14: 1
C15: Office Assistant/Senior | D15: 20220598130 | E15: Miss. Koech, Beatrice Chebet | F15: =IF(D15="", "", VLOOKUP(D15, Sheet3!C:P, 14, FALSE) & ", " & DATEDIF(VLOOKUP(D15, Sheet3!C:N, 12, FALSE), TODAY(), "y") & " Years Experience") -> KCSE, KCPE, 4 Years Experience | H15: 12/11
C16: CORPORATION SECRETARY AND DIRECTOR LEGAL SERVICES DIRECTORATE | F16: =IF(D16="", "", VLOOKUP(D16, Sheet3!C:P, 14, FALSE) & ", " & DATEDIF(VLOOKUP(D16, Sheet3!C:N, 12, FALSE), TODAY(), "y") & " Years Experience")
C17: Corporation Secretary and Director Legal Services | F17: =IF(D17="", "", VLOOKUP(D17, Sheet3!C:P, 14, FALSE) & ", " & DATEDIF(VLOOKUP(D17, Sheet3!C:N, 12, FALSE), TODAY(), "y") & " Years Experience") | H17: 2 | K17: 1 | L17: 0
C18: Deputy Director, Legal Services | F18: =IF(D18="", "", VLOOKUP(D18, Sheet3!C:P, 14, FALSE) & ", " & DATEDIF(VLOOKUP(D18, Sheet3!C:N, 12, FALSE), TODAY(), "y") & " Years Experience") | H18: 3 | K18: 1 | L18: 0
C19: Assistant Director | F19: =IF(D19="", "", VLOOKUP(D19, Sheet3!C:P, 14, FALSE) & ", " & DATEDIF(VLOOKUP(D19, Sheet3!C:N, 12, FALSE), TODAY(), "y") & " Years Experience") | H19: 4 | K19: 0 | L19: 0
C20: Principal Legal Officer | F20: =IF(D20="", "", VLOOKUP(D20, Sheet3!C:P, 14, FALSE) & ", " & DATEDIF(VLOOKUP(D20, Sheet3!C:N, 12, FALSE), TODAY(), "y") & " Years Experience") | H20: 5 | K20: 0 | L20: 0
C21: Legal Officer/Senior | F21: =IF(D21="", "", VLOOKUP(D21, Sheet3!C:P, 14, FALSE) & ", " & DATEDIF(VLOOKUP(D21, Sheet3!C:N, 12, FALSE), TODAY(), "y") & " Years Experience") | H21: 7/6 | K21: 0 | L21: 0
C22: Principal Assistant Legal Officer | F22: =IF(D22="", "", VLOOKUP(D22, Sheet3!C:P, 14, FALSE) & ", " & DATEDIF(VLOOKUP(D22, Sheet3!C:N, 12, FALSE), TODAY(), "y") & " Years Experience") | H22: 7 | K22: 1 | L22: 0
C23: Assistant Legal Officer / Senior | F23: =IF(D23="", "", VLOOKUP(D23, Sheet3!C:P, 14, FALSE) & ", " & DATEDIF(VLOOKUP(D23, Sheet3!C:N, 12, FALSE), TODAY(), "y") & " Years Experience") | H23: 9/8 | K23: 0 | L23: 0
C24: Assistant Office Administrator/ Senior | F24: =IF(D24="", "", VLOOKUP(D24, Sheet3!C:P, 14, FALSE) & ", " & DATEDIF(VLOOKUP(D24, Sheet3!C:N, 12, FALSE), TODAY(), "y") & " Years Experience") | H24: 9/8 | K24: 1 | L24: 0
C25: RESEARCH AND PRODUCT DEVELOPMENT DIRECTORATE | F25: =IF(D25="", "", VLOOKUP(D25, Sheet3!C:P, 14, FALSE) & ", " & DATEDIF(VLOOKUP(D25, Sheet3!C:N, 12, FALSE), TODAY(), "y") & " Years Experience")
C26: Director, Research and Product Development | F26: =IF(D26="", "", VLOOKUP(D26, Sheet3!C:P, 14, FALSE) & ", " & DATEDIF(VLOOKUP(D26, Sheet3!C:N, 12, FALSE), TODAY(), "y") & " Years Experience") | H26: 2 | K26: 1 | L26: 1
C27: Chief Research Scientist | F27: =IF(D27="", "", VLOOKUP(D27, Sheet3!C:P, 14, FALSE) & ", " & DATEDIF(VLOOKUP(D27, Sheet3!C:N, 12, FALSE), TODAY(), "y") & " Years Experience") | H27: 2 | K27: 1 | L27: 1
C28: Assistant Office Administrator/ Senior | F28: =IF(D28="", "", VLOOKUP(D28, Sheet3!C:P, 14, FALSE) & ", " & DATEDIF(VLOOKUP(D28, Sheet3!C:N, 12, FALSE), TODAY(), "y") & " Years Experience") | H28: 9/8 | K28: 1 | L28: 1
C29: Driver / Senior | F29: =IF(D29="", "", VLOOKUP(D29, Sheet3!C:P, 14, FALSE) & ", " & DATEDIF(VLOOKUP(D29, Sheet3!C:N, 12, FALSE), TODAY(), "y") & " Years Experience") | H29: 11/10 | K29: 1 | L29: 0
C30: Office Assistant / Senior | F30: =IF(D30="", "", VLOOKUP(D30, Sheet3!C:P, 14, FALSE) & ", " & DATEDIF(VLOOKUP(D30, Sheet3!C:N, 12, FALSE), TODAY(), "y") & " Years Experience") | H30: 12/11 | K30: 1 | L30: 0
C31: INFECTIOUS DISEASES AND ONE HEALTH DIVISION | F31: =IF(D31="", "", VLOOKUP(D31, Sheet3!C:P, 14, FALSE) & ", " & DATEDIF(VLOOKUP(D31, Sheet3!C:N, 12, FALSE), TODAY(), "y") & " Years Experience")
C32: Deputy Director, Infectious Diseases and One Health | F32: =IF(D32="", "", VLOOKUP(D32, Sheet3!C:P, 14, FALSE) & ", " & DATEDIF(VLOOKUP(D32, Sheet3!C:N, 12, FALSE), TODAY(), "y") & " Years Experience") | H32: 3 | K32: 1 | L32: 0
C33: Senior Principal, Research Scientist | F33: =IF(D33="", "", VLOOKUP(D33, Sheet3!C:P, 14, FALSE) & ", " & DATEDIF(VLOOKUP(D33, Sheet3!C:N, 12, FALSE), TODAY(), "y") & " Years Experience") | H33: 3 | K33: 1 | L33: 0
C34: VIROLOGY SECTION | F34: =IF(D34="", "", VLOOKUP(D34, Sheet3!C:P, 14, FALSE) & ", " & DATEDIF(VLOOKUP(D34, Sheet3!C:N, 12, FALSE), TODAY(), "y") & " Years Experience")
C35: Assistant Director, Research | F35: =IF(D35="", "", VLOOKUP(D35, Sheet3!C:P, 14, FALSE) & ", " & DATEDIF(VLOOKUP(D35, Sheet3!C:N, 12, FALSE), TODAY(), "y") & " Years Experience") | H35: 4 | K35: 1 | L35: 1
C36: Principal Research Scientist | F36: =IF(D36="", "", VLOOKUP(D36, Sheet3!C:P, 14, FALSE) & ", " & DATEDIF(VLOOKUP(D36, Sheet3!C:N, 12, FALSE), TODAY(), "y") & " Years Experience") | H36: 4 | K36: 1 | L36: 1
C37: Senior Research Scientist | F37: =IF(D37="", "", VLOOKUP(D37, Sheet3!C:P, 14, FALSE) & ", " & DATEDIF(VLOOKUP(D37, Sheet3!C:N, 12, FALSE), TODAY(), "y") & " Years Experience") | H37: 5 | K37: 2 | L37: 1
C38: Assistant Research Scientist / Research Scientist | F38: =IF(D38="", "", VLOOKUP(D38, Sheet3!C:P, 14, FALSE) & ", " & DATEDIF(VLOOKUP(D38, Sheet3!C:N, 12, FALSE), TODAY(), "y") & " Years Experience") | H38: 7/6 | K38: 2 | L38: 2
C39: Principal Laboratory Technician | F39: =IF(D39="", "", VLOOKUP(D39, Sheet3!C:P, 14, FALSE) & ", " & DATEDIF(VLOOKUP(D39, Sheet3!C:N, 12, FALSE), TODAY(), "y") & " Years Experience") | H39: 7 | K39: 2 | L39: 2
C40: Laboratory Technician/Senior | F40: =IF(D40="", "", VLOOKUP(D40, Sheet3!C:P, 14, FALSE) & ", " & DATEDIF(VLOOKUP(D40, Sheet3!C:N, 12, FALSE), TODAY(), "y") & " Years Experience") | H40: 9/8 | K40: 0 | L40: 0
C41: MICROBIOLOGY, PARASITOLOGY AND VECTOR BIOLOGY SECTION | F41: =IF(D41="", "", VLOOKUP(D41, Sheet3!C:P, 14, FALSE) & ", " & DATEDIF(VLOOKUP(D41, Sheet3!C:N, 12, FALSE), TODAY(), "y") & " Years Experience")
C42: Assistant Director, Research | F42: =IF(D42="", "", VLOOKUP(D42, Sheet3!C:P, 14, FALSE) & ", " & DATEDIF(VLOOKUP(D42, Sheet3!C:N, 12, FALSE), TODAY(), "y") & " Years Experience") | H42: 4 | K42: 1 | L42: 0
C43: Principal Research Scientist | F43: =IF(D43="", "", VLOOKUP(D43, Sheet3!C:P, 14, FALSE) & ", " & DATEDIF(VLOOKUP(D43, Sheet3!C:N, 12, FALSE), TODAY(), "y") & " Years Experience") | H43: 4 | K43: 1 | L43: 0
...

Sheet Sheet3
A1: S/No. | B1: {=+B1:H41H214B1:H47B1:H47H214B1:H47B1:H53H2B1:I47} -> #NAME? | C1: Payroll Number | D1: Full Name | F1: ID Number | G1: Gender | H1: Age | I1: Designation | J1: Department | K1: Job Group | L1: Employment Status | M1: ROD | N1: DOE | Q1: 0 | Y1: Terms of Employment | Z1: Ethnicity
D2: ADMINISTRATION & HUMAN RESOURCE | Q2: PhD | R2: Masters | S2: Bachelors/Higher Diploma | T2: Diploma | U2: Certificate | V2: KCSE | W2: KCPE | X2: Proffesional Qualification
A3: 1 | B3: 1 | C3: 19901899045 | D3: Dr. Mwethera, Peter Gichuhi | F3: 3731123 | G3: M | H3: 61 | I3: Director General - EL - C01AT | J3: Reproductive Health & Biology | K3: T | L3: 0 - Active | M3: 01/09/2029 | N3: 32908 | O3: Dr. Mwethera, Peter Gichuhi | P3: =SUBSTITUTE(TRIM( IF(COUNTIF(Q3:X3, "*Philosophy*"), "PhD ", "") & IF(COUNTIF(Q3:X3, "*Master*"), "MSc ", "") & IF(COUNTIF(Q3:X3, "*Bachelor*"), "Bachelors ", "") & IF(COUNTIF(Q3:X3, "*Diploma*"), "Dip ", "") & IF(COUNTIF(Q3:X3, "*KCSE*"), "KCSE ", "") & IF(COUNTIF(Q3:X3, "*KCPE*"), "KCPE ", "") & IF(COUNTIF(Q3:X3, "*IHRM*"), "IHRM ", "") & IF(COUNTIF(Q3:X3, "*HRMPB*"), "HRMPB ", "") & IF(COUNTIF(Q3:X3, "*KISM*"), "KISM ", "") & IF(COUNTIF(Q3:X3, "*ICPAK*"), "ICPAK ", "") & IF(COUNTIF(Q3:X3, "*CPA*"), "CPA ", "") & IF(COUNTIF(Q3:X3, "*Strategic Leadership*"), "SLDP ", "") & IF(COUNTIF(Q3:X3, "*Senior Management*"), "SMC ", "") & IF(COUNTIF(Q3:X3, "*Nursing*"), "NCK ", "") & IF(COUNTIF(Q3:X3, "*KMLTTB*"), "KMLTTB ", "") & IF(COUNTIF(Q3:X3, "*Cstat*"), "Cstat ", "") & IF(SUMPRODUCT(LEN(Q3:X3)-LEN(SUBSTITUTE(UPPER(Q3:X3),"CERTIFICATE","")))/11>0, SUMPRODUCT(LEN(Q3:X3)-LEN(SUBSTITUTE(UPPER(Q3:X3),"CERTIFICATE","")))/11 & " Certificates ", "") ), " ", ", ") -> PhD, MSc, Bachelors, KCSE, KCPE | Q3: PhD in Philosophy | R3: Master in Science | S3: Bachelor of Science | V3: KCSE | W3: KCPE | Y3: Local Contract | Z3: Kikuyu
A4: 2 | B4: 2 | C4: 19990495773 | D4: Mrs. Hassan, Hamida Adam | F4: 12701644 | G4: F | H4: 50 | I4: Senior Personal Assistant - EL - T02AN | J4: Administration & HR | K4: N | L4: 0 - Active | M4: 14/08/2034 | N4: 36167 | O4: Mrs. Hassan, Hamida Adam | P4: =SUBSTITUTE(TRIM( IF(COUNTIF(Q4:X4, "*Philosophy*"), "PhD ", "") & IF(COUNTIF(Q4:X4, "*Master*"), "MSc ", "") & IF(COUNTIF(Q4:X4, "*Bachelor*"), "Bachelors ", "") & IF(COUNTIF(Q4:X4, "*Diploma*"), "Dip ", "") & IF(COUNTIF(Q4:X4, "*KCSE*"), "KCSE ", "") & IF(COUNTIF(Q4:X4, "*KCPE*"), "KCPE ", "") & IF(COUNTIF(Q4:X4, "*IHRM*"), "IHRM ", "") & IF(COUNTIF(Q4:X4, "*HRMPB*"), "HRMPB ", "") & IF(COUNTIF(Q4:X4, "*KISM*"), "KISM ", "") & IF(COUNTIF(Q4:X4, "*ICPAK*"), "ICPAK ", "") & IF(COUNTIF(Q4:X4, "*CPA*"), "CPA ", "") & IF(COUNTIF(Q4:X4, "*Strategic Leadership*"), "SLDP ", "") & IF(COUNTIF(Q4:X4, "*Senior Management*"), "SMC ", "") & IF(COUNTIF(Q4:X4, "*Nursing*"), "NCK ", "") & IF(COUNTIF(Q4:X4, "*KMLTTB*"), "KMLTTB ", "") & IF(COUNTIF(Q4:X4, "*Cstat*"), "Cstat ", "") & IF(SUMPRODUCT(LEN(Q4:X4)-LEN(SUBSTITUTE(UPPER(Q4:X4),"CERTIFICATE","")))/11>0, SUMPRODUCT(LEN(Q4:X4)-LEN(SUBSTITUTE(UPPER(Q4:X4),"CERTIFICATE","")))/11 & " Certificates ", "") ), " ", ", ") -> Dip, KCSE, KCPE | T4: Diploma in HRM, PR | V4: KCSE | W4: KCPE | Y4: Permanent | Z4: Luhya
A5: 3 | B5: 3 | C5: 20114215626 | D5: Mr. Manene, Patrick Kimathi | F5: 13361887 | G5: M | H5: 53 | I5: Administrative Officer [1] - EL - C01AN | J5: Administration & HR | K5: N | L5: 0 - Active | M5: 05/04/2032 | N5: 40546 | O5: Mr. Manene, Patrick Kimathi | P5: =SUBSTITUTE(TRIM( IF(COUNTIF(Q5:X5, "*Philosophy*"), "PhD ", "") & IF(COUNTIF(Q5:X5, "*Master*"), "MSc ", "") & IF(COUNTIF(Q5:X5, "*Bachelor*"), "Bachelors ", "") & IF(COUNTIF(Q5:X5, "*Diploma*"), "Dip ", "") & IF(COUNTIF(Q5:X5, "*KCSE*"), "KCSE ", "") & IF(COUNTIF(Q5:X5, "*KCPE*"), "KCPE ", "") & IF(COUNTIF(Q5:X5, "*IHRM*"), "IHRM ", "") & IF(COUNTIF(Q5:X5, "*HRMPB*"), "HRMPB ", "") & IF(COUNTIF(Q5:X5, "*KISM*"), "KISM ", "") & IF(COUNTIF(Q5:X5, "*ICPAK*"), "ICPAK ", "") & IF(COUNTIF(Q5:X5, "*CPA*"), "CPA ", "") & IF(COUNTIF(Q5:X5, "*Strategic Leadership*"), "SLDP ", "") & IF(COUNTIF(Q5:X5, "*Senior Management*"), "SMC ", "") & IF(COUNTIF(Q5:X5, "*Nursing*"), "NCK ", "") & IF(COUNTIF(Q5:X5, "*KMLTTB*"), "KMLTTB ", "") & IF(COUNTIF(Q5:X5, "*Cstat*"), "Cstat ", "") & IF(SUMPRODUCT(LEN(Q5:X5)-LEN(SUBSTITUTE(UPPER(Q5:X5),"CERTIFICATE","")))/11>0, SUMPRODUCT(LEN(Q5:X5)-LEN(SUBSTITUTE(UPPER(Q5:X5),"CERTIFICATE","")))/11 & " Certificates ", "") ), " ", ", ") -> MSc, Bachelors, Dip, KCSE, KCPE, IHRM, HRMPB, SLDP, SMC | R5: Master in Public Policy and Administration | S5: Bachelor of Arts | T5: Diploma in Human Resource Management | V5: KCSE | W5: KCPE | X5: IHRM, HRMPB, KSG (Strategic Leadership Development Programme, Senior Management Course) | Y5: Permanent | Z5: Meru
A6: 4 | B6: 4 | C6: 20060933912 | D6: Mrs. Maimuna, Juma Alhamid | F6: 23888972 | G6: F | H6: 43 | I6: Human Resource Officer [2] - EL - C04AM | J6: Administration & HR | K6: M | L6: 0 - Active | M6: 24/05/2041 | N6: 38724 | O6: Mrs. Maimuna, Juma Alhamid | P6: =SUBSTITUTE(TRIM( IF(COUNTIF(Q6:X6, "*Philosophy*"), "PhD ", "") & IF(COUNTIF(Q6:X6, "*Master*"), "MSc ", "") & IF(COUNTIF(Q6:X6, "*Bachelor*"), "Bachelors ", "") & IF(COUNTIF(Q6:X6, "*Diploma*"), "Dip ", "") & IF(COUNTIF(Q6:X6, "*KCSE*"), "KCSE ", "") & IF(COUNTIF(Q6:X6, "*KCPE*"), "KCPE ", "") & IF(COUNTIF(Q6:X6, "*IHRM*"), "IHRM ", "") & IF(COUNTIF(Q6:X6, "*HRMPB*"), "HRMPB ", "") & IF(COUNTIF(Q6:X6, "*KISM*"), "KISM ", "") & IF(COUNTIF(Q6:X6, "*ICPAK*"), "ICPAK ", "") & IF(COUNTIF(Q6:X6, "*CPA*"), "CPA ", "") & IF(COUNTIF(Q6:X6, "*Strategic Leadership*"), "SLDP ", "") & IF(COUNTIF(Q6:X6, "*Senior Management*"), "SMC ", "") & IF(COUNTIF(Q6:X6, "*Nursing*"), "NCK ", "") & IF(COUNTIF(Q6:X6, "*KMLTTB*"), "KMLTTB ", "") & IF(COUNTIF(Q6:X6, "*Cstat*"), "Cstat ", "") & IF(SUMPRODUCT(LEN(Q6:X6)-LEN(SUBSTITUTE(UPPER(Q6:X6),"CERTIFICATE","")))/11>0, SUMPRODUCT(LEN(Q6:X6)-LEN(SUBSTITUTE(UPPER(Q6:X6),"CERTIFICATE","")))/11 & " Certificates ", "") ), " ", ", ") -> Bachelors, KCSE, KCPE, KISM | S6: Bachelorof Business Management ( Supplies and Procurement option) | V6: KCSE | W6: KCPE | X6: KISM | Y6: Permanent | Z6: Bajun
A7: 5 | B7: 5 | C7: 20210646216 | D7: Mrs. Kamanda, Cynicah Nyaboke | F7: 24212658 | G7: F | H7: 40 | I7: Accountant [1] - EL - D01AM | J7: Administration & HR | K7: M | L7: 0 - Active | M7: 31/07/2027 | N7: 44197 | O7: Mrs. Kamanda, Cynicah Nyaboke | P7: =SUBSTITUTE(TRIM( IF(COUNTIF(Q7:X7, "*Philosophy*"), "PhD ", "") & IF(COUNTIF(Q7:X7, "*Master*"), "MSc ", "") & IF(COUNTIF(Q7:X7, "*Bachelor*"), "Bachelors ", "") & IF(COUNTIF(Q7:X7, "*Diploma*"), "Dip ", "") & IF(COUNTIF(Q7:X7, "*KCSE*"), "KCSE ", "") & IF(COUNTIF(Q7:X7, "*KCPE*"), "KCPE ", "") & IF(COUNTIF(Q7:X7, "*IHRM*"), "IHRM ", "") & IF(COUNTIF(Q7:X7, "*HRMPB*"), "HRMPB ", "") & IF(COUNTIF(Q7:X7, "*KISM*"), "KISM ", "") & IF(COUNTIF(Q7:X7, "*ICPAK*"), "ICPAK ", "") & IF(COUNTIF(Q7:X7, "*CPA*"), "CPA ", "") & IF(COUNTIF(Q7:X7, "*Strategic Leadership*"), "SLDP ", "") & IF(COUNTIF(Q7:X7, "*Senior Management*"), "SMC ", "") & IF(COUNTIF(Q7:X7, "*Nursing*"), "NCK ", "") & IF(COUNTIF(Q7:X7, "*KMLTTB*"), "KMLTTB ", "") & IF(COUNTIF(Q7:X7, "*Cstat*"), "Cstat ", "") & IF(SUMPRODUCT(LEN(Q7:X7)-LEN(SUBSTITUTE(UPPER(Q7:X7),"CERTIFICATE","")))/11>0, SUMPRODUCT(LEN(Q7:X7)-LEN(SUBSTITUTE(UPPER(Q7:X7),"CERTIFICATE","")))/11 & " Certificates ", "") ), " ", ", ") -> MSc, Bachelors, Dip, KCSE, KCPE, ICPAK, CPA, 1, Certificates | R7: Master of Business Administration,Finace Option | S7: Bachelor of Arts in Commerce | T7: Diploma in Business Management in TEP | U7: Certificate in Public Accounts | V7: KCSE | W7: KCPE | X7: ICPAK | Y7: Local Contract | Z7: Kisii
A8: 6 | B8: 6 | C8: 20160708902 | D8: Mr. Ochien'g, Zaddock Ojall | F8: 24938714 | G8: M | H8: 38 | I8: Administrative Officer [3] - EL - C01AL | J8: Administration & HR | K8: L | L8: 0 - Active | M8: 31/07/2027 | N8: 42377 | O8: Mr. Ochien'g, Zaddock Ojall | P8: =SUBSTITUTE(TRIM( IF(COUNTIF(Q8:X8, "*Philosophy*"), "PhD ", "") & IF(COUNTIF(Q8:X8, "*Master*"), "MSc ", "") & IF(COUNTIF(Q8:X8, "*Bachelor*"), "Bachelors ", "") & IF(COUNTIF(Q8:X8, "*Diploma*"), "Dip ", "") & IF(COUNTIF(Q8:X8, "*KCSE*"), "KCSE ", "") & IF(COUNTIF(Q8:X8, "*KCPE*"), "KCPE ", "") & IF(COUNTIF(Q8:X8, "*IHRM*"), "IHRM ", "") & IF(COUNTIF(Q8:X8, "*HRMPB*"), "HRMPB ", "") & IF(COUNTIF(Q8:X8, "*KISM*"), "KISM ", "") & IF(COUNTIF(Q8:X8, "*ICPAK*"), "ICPAK ", "") & IF(COUNTIF(Q8:X8, "*CPA*"), "CPA ", "") & IF(COUNTIF(Q8:X8, "*Strategic Leadership*"), "SLDP ", "") & IF(COUNTIF(Q8:X8, "*Senior Management*"), "SMC ", "") & IF(COUNTIF(Q8:X8, "*Nursing*"), "NCK ", "") & IF(COUNTIF(Q8:X8, "*KMLTTB*"), "KMLTTB ", "") & IF(COUNTIF(Q8:X8, "*Cstat*"), "Cstat ", "") & IF(SUMPRODUCT(LEN(Q8:X8)-LEN(SUBSTITUTE(UPPER(Q8:X8),"CERTIFICATE","")))/11>0, SUMPRODUCT(LEN(Q8:X8)-LEN(SUBSTITUTE(UPPER(Q8:X8),"CERTIFICATE","")))/11 & " Certificates ", "") ), " ", ", ") -> Bachelors, KCSE, KCPE | S8: Bachelor of Arts In Human Resource | V8: KCSE | W8: KCPE | Y8: Local Contract | Z8: Luo
A9: 7 | B9: 7 | C9: 20220598180 | D9: Mr. Owuor, John Robert | F9: 31860798 | G9: M | H9: 30 | I9: Human Resource Officer [3] - EL - C04AL | J9: Administration & HR | K9: L | L9: 0 - Active | M9: 30/01/2028 | N9: 44563 | O9: Mr. Owuor, John Robert | P9: =SUBSTITUTE(TRIM( IF(COUNTIF(Q9:X9, "*Philosophy*"), "PhD ", "") & IF(COUNTIF(Q9:X9, "*Master*"), "MSc ", "") & IF(COUNTIF(Q9:X9, "*Bachelor*"), "Bachelors ", "") & IF(COUNTIF(Q9:X9, "*Diploma*"), "Dip ", "") & IF(COUNTIF(Q9:X9, "*KCSE*"), "KCSE ", "") & IF(COUNTIF(Q9:X9, "*KCPE*"), "KCPE ", "") & IF(COUNTIF(Q9:X9, "*IHRM*"), "IHRM ", "") & IF(COUNTIF(Q9:X9, "*HRMPB*"), "HRMPB ", "") & IF(COUNTIF(Q9:X9, "*KISM*"), "KISM ", "") & IF(COUNTIF(Q9:X9, "*ICPAK*"), "ICPAK ", "") & IF(COUNTIF(Q9:X9, "*CPA*"), "CPA ", "") & IF(COUNTIF(Q9:X9, "*Strategic Leadership*"), "SLDP ", "") & IF(COUNTIF(Q9:X9, "*Senior Management*"), "SMC ", "") & IF(COUNTIF(Q9:X9, "*Nursing*"), "NCK ", "") & IF(COUNTIF(Q9:X9, "*KMLTTB*"), "KMLTTB ", "") & IF(COUNTIF(Q9:X9, "*Cstat*"), "Cstat ", "") & IF(SUMPRODUCT(LEN(Q9:X9)-LEN(SUBSTITUTE(UPPER(Q9:X9),"CERTIFICATE","")))/11>0, SUMPRODUCT(LEN(Q9:X9)-LEN(SUBSTITUTE(UPPER(Q9:X9),"CERTIFICATE","")))/11 & " Certificates ", "") ), " ", ", ") -> Bachelors, KCSE, KCPE | S9: Bachelor of Business Administration,with IT(Finance Option) | V9: KCSE | W9: KCPE | Y9: Local Contract | Z9: Luo
A10: 8 | B10: 8 | C10: 19990495812 | D10: Ms. Rotich, Celestine Jepkoech | F10: 20257607 | G10: F | H10: 48 | I10: Librarian [2] - EL - M05AK | J10: Administration & HR | K10: K | L10: 0 - Active | M10: 27/11/2036 | N10: 36166 | O10: Ms. Rotich, Celestine Jepkoech | P10: =SUBSTITUTE(TRIM( IF(COUNTIF(Q10:X10, "*Philosophy*"), "PhD ", "") & IF(COUNTIF(Q10:X10, "*Master*"), "MSc ", "") & IF(COUNTIF(Q10:X10, "*Bachelor*"), "Bachelors ", "") & IF(COUNTIF(Q10:X10, "*Diploma*"), "Dip ", "") & IF(COUNTIF(Q10:X10, "*KCSE*"), "KCSE ", "") & IF(COUNTIF(Q10:X10, "*KCPE*"), "KCPE ", "") & IF(COUNTIF(Q10:X10, "*IHRM*"), "IHRM ", "") & IF(COUNTIF(Q10:X10, "*HRMPB*"), "HRMPB ", "") & IF(COUNTIF(Q10:X10, "*KISM*"), "KISM ", "") & IF(COUNTIF(Q10:X10, "*ICPAK*"), "ICPAK ", "") & IF(COUNTIF(Q10:X10, "*CPA*"), "CPA ", "") & IF(COUNTIF(Q10:X10, "*Strategic Leadership*"), "SLDP ", "") & IF(COUNTIF(Q10:X10, "*Senior Management*"), "SMC ", "") & IF(COUNTIF(Q10:X10, "*Nursing*"), "NCK ", "") & IF(COUNTIF(Q10:X10, "*KMLTTB*"), "KMLTTB ", "") & IF(COUNTIF(Q10:X10, "*Cstat*"), "Cstat ", "") & IF(SUMPRODUCT(LEN(Q10:X10)-LEN(SUBSTITUTE(UPPER(Q10:X10),"CERTIFICATE","")))/11>0, SUMPRODUCT(LEN(Q10:X10)-LEN(SUBSTITUTE(UPPER(Q10:X10),"CERTIFICATE","")))/11 & " Certificates ", "") ), " ", ", ") -> Dip, KCSE, KCPE | S10: Higher Diploma in Archives and Records Management | V10: KCSE | W10: KCPE | Y10: Permanent | Z10: Kalenjin
A11: 9 | B11: 9 | C11: 20077018333 | D11: Mrs. Muthoni, Elizabeth Ng'ang'a | F11: 10998397 | G11: F | H11: 53 | I11: Telephone Officer [1] - EL - M09AJ | J11: Administration & HR | K11: J | L11: 0 - Active | M11: 19/12/2031 | N11: 39083 | O11: Mrs. Muthoni, Elizabeth Ng'ang'a | P11: =SUBSTITUTE(TRIM( IF(COUNTIF(Q11:X11, "*Philosophy*"), "PhD ", "") & IF(COUNTIF(Q11:X11, "*Master*"), "MSc ", "") & IF(COUNTIF(Q11:X11, "*Bachelor*"), "Bachelors ", "") & IF(COUNTIF(Q11:X11, "*Diploma*"), "Dip ", "") & IF(COUNTIF(Q11:X11, "*KCSE*"), "KCSE ", "") & IF(COUNTIF(Q11:X11, "*KCPE*"), "KCPE ", "") & IF(COUNTIF(Q11:X11, "*IHRM*"), "IHRM ", "") & IF(COUNTIF(Q11:X11, "*HRMPB*"), "HRMPB ", "") & IF(COUNTIF(Q11:X11, "*KISM*"), "KISM ", "") & IF(COUNTIF(Q11:X11, "*ICPAK*"), "ICPAK ", "") & IF(COUNTIF(Q11:X11, "*CPA*"), "CPA ", "") & IF(COUNTIF(Q11:X11, "*Strategic Leadership*"), "SLDP ", "") & IF(COUNTIF(Q11:X11, "*Senior Management*"), "SMC ", "") & IF(COUNTIF(Q11:X11, "*Nursing*"), "NCK ", "") & IF(COUNTIF(Q11:X11, "*KMLTTB*"), "KMLTTB ", "") & IF(COUNTIF(Q11:X11, "*Cstat*"), "Cstat ", "") & IF(SUMPRODUCT(LEN(Q11:X11)-LEN(SUBSTITUTE(UPPER(Q11:X11),"CERTIFICATE","")))/11>0, SUMPRODUCT(LEN(Q11:X11)-LEN(SUBSTITUTE(UPPER(Q11:X11),"CERTIFICATE","")))/11 & " Certificates ", "") ), " ", ", ") -> Dip, KCSE, KCPE | T11: Diploma in Telephone Receptionist | V11: KCSE | W11: KCPE | Y11: Permanent | Z11: Kikuyu
A12: 10 | B12: 10 | C12: 20077018202 | D12: Ms. Lithira, Sabina Nkoyai | F12: 13133273 | G12: F | H12: 51 | I12: Telephone Officer [2] - EL - M09AH | J12: Administration & HR | K12: H | L12: 0 - Active | M12: 27/08/2033 | N12: 39417 | O12: Ms. Lithira, Sabina Nkoyai | P12: =SUBSTITUTE(TRIM( IF(COUNTIF(Q12:X12, "*Philosophy*"), "PhD ", "") & IF(COUNTIF(Q12:X12, "*Master*"), "MSc ", "") & IF(COUNTIF(Q12:X12, "*Bachelor*"), "Bachelors ", "") & IF(COUNTIF(Q12:X12, "*Diploma*"), "Dip ", "") & IF(COUNTIF(Q12:X12, "*KCSE*"), "KCSE ", "") & IF(COUNTIF(Q12:X12, "*KCPE*"), "KCPE ", "") & IF(COUNTIF(Q12:X12, "*IHRM*"), "IHRM ", "") & IF(COUNTIF(Q12:X12, "*HRMPB*"), "HRMPB ", "") & IF(COUNTIF(Q12:X12, "*KISM*"), "KISM ", "") & IF(COUNTIF(Q12:X12, "*ICPAK*"), "ICPAK ", "") & IF(COUNTIF(Q12:X12, "*CPA*"), "CPA ", "") & IF(COUNTIF(Q12:X12, "*Strategic Leadership*"), "SLDP ", "") & IF(COUNTIF(Q12:X12, "*Senior Management*"), "SMC ", "") & IF(COUNTIF(Q12:X12, "*Nursing*"), "NCK ", "") & IF(COUNTIF(Q12:X12, "*KMLTTB*"), "KMLTTB ", "") & IF(COUNTIF(Q12:X12, "*Cstat*"), "Cstat ", "") & IF(SUMPRODUCT(LEN(Q12:X12)-LEN(SUBSTITUTE(UPPER(Q12:X12),"CERTIFICATE","")))/11>0, SUMPRODUCT(LEN(Q12:X12)-LEN(SUBSTITUTE(UPPER(Q12:X12),"CERTIFICATE","")))/11 & " Certificates ", "") ), " ", ", ") -> KCSE, KCPE, 1, Certificates | U12: Certificate in Telephone Teceptionist and Supervision | V12: KCSE | W12: KCPE | Y12: Permanent | Z12: Meru
A13: 11 | B13: 11 | C13: 20220598130 | D13: Miss. Koech, Beatrice Chebet | F13: 35698228 | G13: F | H13: 27 | I13: Office Assistant [2] - EL - T04DH | J13: Administration & HR | K13: H | L13: 0 - Active | M13: 30/01/2028 | N13: 44563 | O13: Miss. Koech, Beatrice Chebet | P13: =SUBSTITUTE(TRIM( IF(COUNTIF(Q13:X13, "*Philosophy*"), "PhD ", "") & IF(COUNTIF(Q13:X13, "*Master*"), "MSc ", "") & IF(COUNTIF(Q13:X13, "*Bachelor*"), "Bachelors ", "") & IF(COUNTIF(Q13:X13, "*Diploma*"), "Dip ", "") & IF(COUNTIF(Q13:X13, "*KCSE*"), "KCSE ", "") & IF(COUNTIF(Q13:X13, "*KCPE*"), "KCPE ", "") & IF(COUNTIF(Q13:X13, "*IHRM*"), "IHRM ", "") & IF(COUNTIF(Q13:X13, "*HRMPB*"), "HRMPB ", "") & IF(COUNTIF(Q13:X13, "*KISM*"), "KISM ", "") & IF(COUNTIF(Q13:X13, "*ICPAK*"), "ICPAK ", "") & IF(COUNTIF(Q13:X13, "*CPA*"), "CPA ", "") & IF(COUNTIF(Q13:X13, "*Strategic Leadership*"), "SLDP ", "") & IF(COUNTIF(Q13:X13, "*Senior Management*"), "SMC ", "") & IF(COUNTIF(Q13:X13, "*Nursing*"), "NCK ", "") & IF(COUNTIF(Q13:X13, "*KMLTTB*"), "KMLTTB ", "") & IF(COUNTIF(Q13:X13, "*Cstat*"), "Cstat ", "") & IF(SUMPRODUCT(LEN(Q13:X13)-LEN(SUBSTITUTE(UPPER(Q13:X13),"CERTIFICATE","")))/11>0, SUMPRODUCT(LEN(Q13:X13)-LEN(SUBSTITUTE(UPPER(Q13:X13),"CERTIFICATE","")))/11 & " Certificates ", "") ), " ", ", ") -> KCSE, KCPE | V13: KCSE | W13: KCPE | Y13: Local Contract | Z13: Kalenjin
A14: 12 | B14: 12 | C14: 20077018391 | D14: Mrs. Kassim, Kulthum Mohamed | F14: 11625899 | G14: F | H14: 52 | I14: Clerical Officer - EL - T03AG | J14: Administration & HR | K14: G | L14: 0 - Active | M14: 30/04/2032 | N14: 39083 | O14: Mrs. Kassim, Kulthum Mohamed | P14: =SUBSTITUTE(TRIM( IF(COUNTIF(Q14:X14, "*Philosophy*"), "PhD ", "") & IF(COUNTIF(Q14:X14, "*Master*"), "MSc ", "") & IF(COUNTIF(Q14:X14, "*Bachelor*"), "Bachelors ", "") & IF(COUNTIF(Q14:X14, "*Diploma*"), "Dip ", "") & IF(COUNTIF(Q14:X14, "*KCSE*"), "KCSE ", "") & IF(COUNTIF(Q14:X14, "*KCPE*"), "KCPE ", "") & IF(COUNTIF(Q14:X14, "*IHRM*"), "IHRM ", "") & IF(COUNTIF(Q14:X14, "*HRMPB*"), "HRMPB ", "") & IF(COUNTIF(Q14:X14, "*KISM*"), "KISM ", "") & IF(COUNTIF(Q14:X14, "*ICPAK*"), "ICPAK ", "") & IF(COUNTIF(Q14:X14, "*CPA*"), "CPA ", "") & IF(COUNTIF(Q14:X14, "*Strategic Leadership*"), "SLDP ", "") & IF(COUNTIF(Q14:X14, "*Senior Management*"), "SMC ", "") & IF(COUNTIF(Q14:X14, "*Nursing*"), "NCK ", "") & IF(COUNTIF(Q14:X14, "*KMLTTB*"), "KMLTTB ", "") & IF(COUNTIF(Q14:X14, "*Cstat*"), "Cstat ", "") & IF(SUMPRODUCT(LEN(Q14:X14)-LEN(SUBSTITUTE(UPPER(Q14:X14),"CERTIFICATE","")))/11>0, SUMPRODUCT(LEN(Q14:X14)-LEN(SUBSTITUTE(UPPER(Q14:X14),"CERTIFICATE","")))/11 & " Certificates ", "") ), " ", ", ") -> Dip, KCSE, KCPE | T14: Diploma in Human Resource | V14: KCSE | W14: KCPE | Y14: Permanent | Z14: Bajun
A15: 13 | B15: 13 | C15: 20240300989 | D15: Miss. Opanga, Brenda Kwamboka | F15: 36675697 | G15: F | H15: 26 | I15: Clerical Officer - EL - T03AG | J15: Administration & HR | K15: G | L15: 0 - Active | M15: 22/01/2028 | N15: 45334 | O15: Miss. Opanga, Brenda Kwamboka | P15: =SUBSTITUTE(TRIM( IF(COUNTIF(Q15:X15, "*Philosophy*"), "PhD ", "") & IF(COUNTIF(Q15:X15, "*Master*"), "MSc ", "") & IF(COUNTIF(Q15:X15, "*Bachelor*"), "Bachelors ", "") & IF(COUNTIF(Q15:X15, "*Diploma*"), "Dip ", "") & IF(COUNTIF(Q15:X15, "*KCSE*"), "KCSE ", "") & IF(COUNTIF(Q15:X15, "*KCPE*"), "KCPE ", "") & IF(COUNTIF(Q15:X15, "*IHRM*"), "IHRM ", "") & IF(COUNTIF(Q15:X15, "*HRMPB*"), "HRMPB ", "") & IF(COUNTIF(Q15:X15, "*KISM*"), "KISM ", "") & IF(COUNTIF(Q15:X15, "*ICPAK*"), "ICPAK ", "") & IF(COUNTIF(Q15:X15, "*CPA*"), "CPA ", "") & IF(COUNTIF(Q15:X15, "*Strategic Leadership*"), "SLDP ", "") & IF(COUNTIF(Q15:X15, "*Senior Management*"), "SMC ", "") & IF(COUNTIF(Q15:X15, "*Nursing*"), "NCK ", "") & IF(COUNTIF(Q15:X15, "*KMLTTB*"), "KMLTTB ", "") & IF(COUNTIF(Q15:X15, "*Cstat*"), "Cstat ", "") & IF(SUMPRODUCT(LEN(Q15:X15)-LEN(SUBSTITUTE(UPPER(Q15:X15),"CERTIFICATE","")))/11>0, SUMPRODUCT(LEN(Q15:X15)-LEN(SUBSTITUTE(UPPER(Q15:X15),"CERTIFICATE","")))/11 & " Certificates ", "") ), " ", ", ") -> KCSE, KCPE | V15: KCSE | W15: KCPE | Y15: Local Contract | Z15: Kisii
F16: ANIMANL SCIENCE WELFARE & ETHICS | P16: =SUBSTITUTE(TRIM( IF(COUNTIF(Q16:X16, "*Philosophy*"), "PhD ", "") & IF(COUNTIF(Q16:X16, "*Master*"), "MSc ", "") & IF(COUNTIF(Q16:X16, "*Bachelor*"), "Bachelors ", "") & IF(COUNTIF(Q16:X16, "*Diploma*"), "Dip ", "") & IF(COUNTIF(Q16:X16, "*KCSE*"), "KCSE ", "") & IF(COUNTIF(Q16:X16, "*KCPE*"), "KCPE ", "") & IF(COUNTIF(Q16:X16, "*IHRM*"), "IHRM ", "") & IF(COUNTIF(Q16:X16, "*HRMPB*"), "HRMPB ", "") & IF(COUNTIF(Q16:X16, "*KISM*"), "KISM ", "") & IF(COUNTIF(Q16:X16, "*ICPAK*"), "ICPAK ", "") & IF(COUNTIF(Q16:X16, "*CPA*"), "CPA ", "") & IF(COUNTIF(Q16:X16, "*Strategic Leadership*"), "SLDP ", "") & IF(COUNTIF(Q16:X16, "*Senior Management*"), "SMC ", "") & IF(COUNTIF(Q16:X16, "*Nursing*"), "NCK ", "") & IF(COUNTIF(Q16:X16, "*KMLTTB*"), "KMLTTB ", "") & IF(COUNTIF(Q16:X16, "*Cstat*"), "Cstat ", "") & IF(SUMPRODUCT(LEN(Q16:X16)-LEN(SUBSTITUTE(UPPER(Q16:X16),"CERTIFICATE","")))/11>0, SUMPRODUCT(LEN(Q16:X16)-LEN(SUBSTITUTE(UPPER(Q16:X16),"CERTIFICATE","")))/11 & " Certificates ", "") ), " ", ", ") -> KCSE | V16: KCSE
A17: 14 | B17: 14 | C17: 19871318408 | D17: Dr. Chivatsi, Chai Daniel | F17: 5336502 | G17: M | H17: 65 | I17: Chief Veterinary Officer - EL - H04AQ | J17: Animal Science &Welfare ethics | K17: Q | L17: 0 - Active | M17: 01/07/2025 | N17: 31930 | O17: Dr. Chivatsi, Chai Daniel | P17: =SUBSTITUTE(TRIM( IF(COUNTIF(Q17:X17, "*Philosophy*"), "PhD ", "") & IF(COUNTIF(Q17:X17, "*Master*"), "MSc ", "") & IF(COUNTIF(Q17:X17, "*Bachelor*"), "Bachelors ", "") & IF(COUNTIF(Q17:X17, "*Diploma*"), "Dip ", "") & IF(COUNTIF(Q17:X17, "*KCSE*"), "KCSE ", "") & IF(COUNTIF(Q17:X17, "*KCPE*"), "KCPE ", "") & IF(COUNTIF(Q17:X17, "*IHRM*"), "IHRM ", "") & IF(COUNTIF(Q17:X17, "*HRMPB*"), "HRMPB ", "") & IF(COUNTIF(Q17:X17, "*KISM*"), "KISM ", "") & IF(COUNTIF(Q17:X17, "*ICPAK*"), "ICPAK ", "") & IF(COUNTIF(Q17:X17, "*CPA*"), "CPA ", "") & IF(COUNTIF(Q17:X17, "*Strategic Leadership*"), "SLDP ", "") & IF(COUNTIF(Q17:X17, "*Senior Management*"), "SMC ", "") & IF(COUNTIF(Q17:X17, "*Nursing*"), "NCK ", "") & IF(COUNTIF(Q17:X17, "*KMLTTB*"), "KMLTTB ", "") & IF(COUNTIF(Q17:X17, "*Cstat*"), "Cstat ", "") & IF(SUMPRODUCT(LEN(Q17:X17)-LEN(SUBSTITUTE(UPPER(Q17:X17),"CERTIFICATE","")))/11>0, SUMPRODUCT(LEN(Q17:X17)-LEN(SUBSTITUTE(UPPER(Q17:X17),"CERTIFICATE","")))/11 & " Certificates ", "") ), " ", ", ") -> MSc, Bachelors, KCSE, KCPE, SMC, 1, Certificates | R17: Master of Science in Veterinary Pathology and Diagnostics | S17: Bachelor of Veterinary Medicine | U17: Advanced Certificate of Education | V17: KCSE | W17: KCPE | X17: Senior Management Course | Y17: Permanent | Z17: Mijikenda
A18: 15 | B18: 15 | C18: 20077017769 | D18: Dr. Akinyi, Mercy Yvonne | F18: 21963939 | G18: F | H18: 44 | I18: Senior Research Scientist [2] - ET - R01AP | J18: Animal Science &Welfare ethics | K18: P | L18: 0 - Active | M18: 30/01/2051 | N18: 39427 | O18: Mrs. Akinyi, Mercy Yvonne | P18: =SUBSTITUTE(TRIM( IF(COUNTIF(Q18:X18, "*Philosophy*"), "PhD ", "") & IF(COUNTIF(Q18:X18, "*Master*"), "MSc ", "") & IF(COUNTIF(Q18:X18, "*Bachelor*"), "Bachelors ", "") & IF(COUNTIF(Q18:X18, "*Diploma*"), "Dip ", "") & IF(COUNTIF(Q18:X18, "*KCSE*"), "KCSE ", "") & IF(COUNTIF(Q18:X18, "*KCPE*"), "KCPE ", "") & IF(COUNTIF(Q18:X18, "*IHRM*"), "IHRM ", "") & IF(COUNTIF(Q18:X18, "*HRMPB*"), "HRMPB ", "") & IF(COUNTIF(Q18:X18, "*KISM*"), "KISM ", "") & IF(COUNTIF(Q18:X18, "*ICPAK*"), "ICPAK ", "") & IF(COUNTIF(Q18:X18, "*CPA*"), "CPA ", "") & IF(COUNTIF(Q18:X18, "*Strategic Leadership*"), "SLDP ", "") & IF(COUNTIF(Q18:X18, "*Senior Management*"), "SMC ", "") & IF(COUNTIF(Q18:X18, "*Nursing*"), "NCK ", "") & IF(COUNTIF(Q18:X18, "*KMLTTB*"), "KMLTTB ", "") & IF(COUNTIF(Q18:X18, "*Cstat*"), "Cstat ", "") & IF(SUMPRODUCT(LEN(Q18:X18)-LEN(SUBSTITUTE(UPPER(Q18:X18),"CERTIFICATE","")))/11>0, SUMPRODUCT(LEN(Q18:X18)-LEN(SUBSTITUTE(UPPER(Q18:X18),"CERTIFICATE","")))/11 & " Certificates ", "") ), " ", ", ") -> PhD, MSc, Bachelors, KCSE, KCPE, 1, Certificates | Q18: Doctor of Philosophy | R18: Master of Science in Medical physiology | S18: Bachelor o of veterinary medicine | V18: KCSE | W18: KCPE | X18: Certificate of Registration of a Veterinary Surgeon | Y18: Permanent | Z18: Luo
A19: 16 | B19: 16 | C19: 20030731445 | D19: Mr. Kariuki, Kenneth Waititu | F19: 20742989 | G19: M | H19: 47 | I19: Senior Laboratory Technologist - EL - L07CM | J19: Animal Science &Welfare ethics | K19: M | L19: 0 - Active | M19: 09/10/2037 | N19: 37867 | O19: Mr. Kariuki, Kenneth Waititu | P19: =SUBSTITUTE(TRIM( IF(COUNTIF(Q19:X19, "*Philosophy*"), "PhD ", "") & IF(COUNTIF(Q19:X19, "*Master*"), "MSc ", "") & IF(COUNTIF(Q19:X19, "*Bachelor*"), "Bachelors ", "") & IF(COUNTIF(Q19:X19, "*Diploma*"), "Dip ", "") & IF(COUNTIF(Q19:X19, "*KCSE*"), "KCSE ", "") & IF(COUNTIF(Q19:X19, "*KCPE*"), "KCPE ", "") & IF(COUNTIF(Q19:X19, "*IHRM*"), "IHRM ", "") & IF(COUNTIF(Q19:X19, "*HRMPB*"), "HRMPB ", "") & IF(COUNTIF(Q19:X19, "*KISM*"), "KISM ", "") & IF(COUNTIF(Q19:X19, "*ICPAK*"), "ICPAK ", "") & IF(COUNTIF(Q19:X19, "*CPA*"), "CPA ", "") & IF(COUNTIF(Q19:X19, "*Strategic Leadership*"), "SLDP ", "") & IF(COUNTIF(Q19:X19, "*Senior Management*"), "SMC ", "") & IF(COUNTIF(Q19:X19, "*Nursing*"), "NCK ", "") & IF(COUNTIF(Q19:X19, "*KMLTTB*"), "KMLTTB ", "") & IF(COUNTIF(Q19:X19, "*Cstat*"), "Cstat ", "") & IF(SUMPRODUCT(LEN(Q19:X19)-LEN(SUBSTITUTE(UPPER(Q19:X19),"CERTIFICATE","")))/11>0, SUMPRODUCT(LEN(Q19:X19)-LEN(SUBSTITUTE(UPPER(Q19:X19),"CERTIFICATE","")))/11 & " Certificates ", "") ), " ", ", ") -> MSc, Bachelors, Dip, KCSE, KCPE | R19: Master of Science in Medical Microbiology | S19: Bachelor of Science in Public Health | T19: Diploma in Medical Laboratory Technology | V19: KCSE | W19: KCPE | Y19: Permanent | Z19: Kikuyu
A20: 17 | B20: 17 | C20: 20178600817 | D20: Mr. Nashon, Wanjala Wavumbah | F20: 28951215 | G20: M | H20: 33 | I20: Veterinary Officer - EL - H04AM | J20: Animal Science &Welfare ethics | K20: M | L20: 0 - Active | M20: 30/11/2027 | N20: 42747 | O20: Mr. Nashon, Wanjala Wavumbah | P20: =SUBSTITUTE(TRIM( IF(COUNTIF(Q20:X20, "*Philosophy*"), "PhD ", "") & IF(COUNTIF(Q20:X20, "*Master*"), "MSc ", "") & IF(COUNTIF(Q20:X20, "*Bachelor*"), "Bachelors ", "") & IF(COUNTIF(Q20:X20, "*Diploma*"), "Dip ", "") & IF(COUNTIF(Q20:X20, "*KCSE*"), "KCSE ", "") & IF(COUNTIF(Q20:X20, "*KCPE*"), "KCPE ", "") & IF(COUNTIF(Q20:X20, "*IHRM*"), "IHRM ", "") & IF(COUNTIF(Q20:X20, "*HRMPB*"), "HRMPB ", "") & IF(COUNTIF(Q20:X20, "*KISM*"), "KISM ", "") & IF(COUNTIF(Q20:X20, "*ICPAK*"), "ICPAK ", "") & IF(COUNTIF(Q20:X20, "*CPA*"), "CPA ", "") & IF(COUNTIF(Q20:X20, "*Strategic Leadership*"), "SLDP ", "") & IF(COUNTIF(Q20:X20, "*Senior Management*"), "SMC ", "") & IF(COUNTIF(Q20:X20, "*Nursing*"), "NCK ", "") & IF(COUNTIF(Q20:X20, "*KMLTTB*"), "KMLTTB ", "") & IF(COUNTIF(Q20:X20, "*Cstat*"), "Cstat ", "") & IF(SUMPRODUCT(LEN(Q20:X20)-LEN(SUBSTITUTE(UPPER(Q20:X20),"CERTIFICATE","")))/11>0, SUMPRODUCT(LEN(Q20:X20)-LEN(SUBSTITUTE(UPPER(Q20:X20),"CERTIFICATE","")))/11 & " Certificates ", "") ), " ", ", ") -> MSc, Bachelors, KCSE, KCPE, 1, Certificates | R20: Master of Science in Veterinary Epidemiology and Economics. | S20: Bachelor of veterinary medicine | V20: KCSE | W20: KCPE | X20: Certificate of Registration of a Veterinary Surgeon | Y20: Local Contract | Z20: Luhya
A21: 18 | B21: 18 | C21: 20178600833 | D21: Mrs. Mwadime, Janet Mghambi | F21: 28189079 | G21: F | H21: 34 | I21: Veterinary Officer - EL - H04AM | J21: Animal Science &Welfare ethics | K21: M | L21: 0 - Active | M21: 30/11/2027 | N21: 42747 | O21: Mrs. Mwadime, Janet Mghambi | P21: =SUBSTITUTE(TRIM( IF(COUNTIF(Q21:X21, "*Philosophy*"), "PhD ", "") & IF(COUNTIF(Q21:X21, "*Master*"), "MSc ", "") & IF(COUNTIF(Q21:X21, "*Bachelor*"), "Bachelors ", "") & IF(COUNTIF(Q21:X21, "*Diploma*"), "Dip ", "") & IF(COUNTIF(Q21:X21, "*KCSE*"), "KCSE ", "") & IF(COUNTIF(Q21:X21, "*KCPE*"), "KCPE ", "") & IF(COUNTIF(Q21:X21, "*IHRM*"), "IHRM ", "") & IF(COUNTIF(Q21:X21, "*HRMPB*"), "HRMPB ", "") & IF(COUNTIF(Q21:X21, "*KISM*"), "KISM ", "") & IF(COUNTIF(Q21:X21, "*ICPAK*"), "ICPAK ", "") & IF(COUNTIF(Q21:X21, "*CPA*"), "CPA ", "") & IF(COUNTIF(Q21:X21, "*Strategic Leadership*"), "SLDP ", "") & IF(COUNTIF(Q21:X21, "*Senior Management*"), "SMC ", "") & IF(COUNTIF(Q21:X21, "*Nursing*"), "NCK ", "") & IF(COUNTIF(Q21:X21, "*KMLTTB*"), "KMLTTB ", "") & IF(COUNTIF(Q21:X21, "*Cstat*"), "Cstat ", "") & IF(SUMPRODUCT(LEN(Q21:X21)-LEN(SUBSTITUTE(UPPER(Q21:X21),"CERTIFICATE","")))/11>0, SUMPRODUCT(LEN(Q21:X21)-LEN(SUBSTITUTE(UPPER(Q21:X21),"CERTIFICATE","")))/11 & " Certificates ", "") ), " ", ", ") -> MSc, Bachelors, KCSE, KCPE, 1, Certificates | R21: Master of Science of Health of Acquatic Animal Resources | S21: Bachelor of veterinary medicine | V21: KCSE | W21: KCPE | X21: Certificate of Registration of a Veterinary Surgeon | Y21: Local Contract | Z21: Taita
A22: 19 | B22: 19 | C22: 20010746137 | D22: Mrs. Kavurani, Rose Owino | F22: 13634152 | G22: F | H22: 49 | I22: Animal Health Technologist [1] - EL - H03FL | J22: Animal Science &Welfare ethics | K22: L | L22: 0 - Active | M22: 20/12/2035 | N22: 36896 | O22: Mrs. Kavurani, Rose Owino | P22: =SUBSTITUTE(TRIM( IF(COUNTIF(Q22:X22, "*Philosophy*"), "PhD ", "") & IF(COUNTIF(Q22:X22, "*Master*"), "MSc ", "") & IF(COUNTIF(Q22:X22, "*Bachelor*"), "Bachelors ", "") & IF(COUNTIF(Q22:X22, "*Diploma*"), "Dip ", "") & IF(COUNTIF(Q22:X22, "*KCSE*"), "KCSE ", "") & IF(COUNTIF(Q22:X22, "*KCPE*"), "KCPE ", "") & IF(COUNTIF(Q22:X22, "*IHRM*"), "IHRM ", "") & IF(COUNTIF(Q22:X22, "*HRMPB*"), "HRMPB ", "") & IF(COUNTIF(Q22:X22, "*KISM*"), "KISM ", "") & IF(COUNTIF(Q22:X22, "*ICPAK*"), "ICPAK ", "") & IF(COUNTIF(Q22:X22, "*CPA*"), "CPA ", "") & IF(COUNTIF(Q22:X22, "*Strategic Leadership*"), "SLDP ", "") & IF(COUNTIF(Q22:X22, "*Senior Management*"), "SMC ", "") & IF(COUNTIF(Q22:X22, "*Nursing*"), "NCK ", "") & IF(COUNTIF(Q22:X22, "*KMLTTB*"), "KMLTTB ", "") & IF(COUNTIF(Q22:X22, "*Cstat*"), "Cstat ", "") & IF(SUMPRODUCT(LEN(Q22:X22)-LEN(SUBSTITUTE(UPPER(Q22:X22),"CERTIFICATE","")))/11>0, SUMPRODUCT(LEN(Q22:X22)-LEN(SUBSTITUTE(UPPER(Q22:X22),"CERTIFICATE","")))/11 & " Certificates ", "") ), " ", ", ") -> MSc, Bachelors, Dip, KCSE, KCPE, 1, Certificates | R22: Master of Science in Molecular Biology and Bionformatics | S22: Bachelor of Science in Medical Microbiology | T22: Higher Diploma in Biotechnology, Diploma in Applied Biology. | U22: Certificate in Science Laboratory Technician. | V22: KCSE | W22: KCPE | Y22: Permanent | Z22: Luhya
A23: 20 | B23: 20 | C23: 20220597833 | D23: Mrs. Woche, Fatuma Galgalo | F23: 34811881 | G23: F | H23: 28 | I23: Assistant Research Scientist - EL - R01BL | J23: Animal Science &Welfare ethics | K23: L | L23: 0 - Active | M23: 30/01/2028 | N23: 44564 | O23: Mrs. Woche, Fatuma Galgalo | P23: =SUBSTITUTE(TRIM( IF(COUNTIF(Q23:X23, "*Philosophy*"), "PhD ", "") & IF(COUNTIF(Q23:X23, "*Master*"), "MSc ", "") & IF(COUNTIF(Q23:X23, "*Bachelor*"), "Bachelors ", "") & IF(COUNTIF(Q23:X23, "*Diploma*"), "Dip ", "") & IF(COUNTIF(Q23:X23, "*KCSE*"), "KCSE ", "") & IF(COUNTIF(Q23:X23, "*KCPE*"), "KCPE ", "") & IF(COUNTIF(Q23:X23, "*IHRM*"), "IHRM ", "") & IF(COUNTIF(Q23:X23, "*HRMPB*"), "HRMPB ", "") & IF(COUNTIF(Q23:X23, "*KISM*"), "KISM ", "") & IF(COUNTIF(Q23:X23, "*ICPAK*"), "ICPAK ", "") & IF(COUNTIF(Q23:X23, "*CPA*"), "CPA ", "") & IF(COUNTIF(Q23:X23, "*Strategic Leadership*"), "SLDP ", "") & IF(COUNTIF(Q23:X23, "*Senior Management*"), "SMC ", "") & IF(COUNTIF(Q23:X23, "*Nursing*"), "NCK ", "") & IF(COUNTIF(Q23:X23, "*KMLTTB*"), "KMLTTB ", "") & IF(COUNTIF(Q23:X23, "*Cstat*"), "Cstat ", "") & IF(SUMPRODUCT(LEN(Q23:X23)-LEN(SUBSTITUTE(UPPER(Q23:X23),"CERTIFICATE","")))/11>0, SUMPRODUCT(LEN(Q23:X23)-LEN(SUBSTITUTE(UPPER(Q23:X23),"CERTIFICATE","")))/11 & " Certificates ", "") ), " ", ", ") -> Bachelors, KCSE, KCPE | S23: Bachelor of Science in Animal Science | V23: KCSE | W23: KCPE | Y23: Local Contract | Z23: Burji
A24: 21 | B24: 21 | C24: 20089224039 | D24: Ms. Kimiti, Priscila Wangari | F24: 22245948 | G24: F | H24: 46 | I24: Senior Animal Health Assistant - EL - H03EJ | J24: Animal Science &Welfare ethics | K24: J | L24: 0 - Active | M24: 06/07/2038 | N24: 39479 | O24: Ms. Kimiti, Priscila Wangari | P24: =SUBSTITUTE(TRIM( IF(COUNTIF(Q24:X24, "*Philosophy*"), "PhD ", "") & IF(COUNTIF(Q24:X24, "*Master*"), "MSc ", "") & IF(COUNTIF(Q24:X24, "*Bachelor*"), "Bachelors ", "") & IF(COUNTIF(Q24:X24, "*Diploma*"), "Dip ", "") & IF(COUNTIF(Q24:X24, "*KCSE*"), "KCSE ", "") & IF(COUNTIF(Q24:X24, "*KCPE*"), "KCPE ", "") & IF(COUNTIF(Q24:X24, "*IHRM*"), "IHRM ", "") & IF(COUNTIF(Q24:X24, "*HRMPB*"), "HRMPB ", "") & IF(COUNTIF(Q24:X24, "*KISM*"), "KISM ", "") & IF(COUNTIF(Q24:X24, "*ICPAK*"), "ICPAK ", "") & IF(COUNTIF(Q24:X24, "*CPA*"), "CPA ", "") & IF(COUNTIF(Q24:X24, "*Strategic Leadership*"), "SLDP ", "") & IF(COUNTIF(Q24:X24, "*Senior Management*"), "SMC ", "") & IF(COUNTIF(Q24:X24, "*Nursing*"), "NCK ", "") & IF(COUNTIF(Q24:X24, "*KMLTTB*"), "KMLTTB ", "") & IF(COUNTIF(Q24:X24, "*Cstat*"), "Cstat ", "") & IF(SUMPRODUCT(LEN(Q24:X24)-LEN(SUBSTITUTE(UPPER(Q24:X24),"CERTIFICATE","")))/11>0, SUMPRODUCT(LEN(Q24:X24)-LEN(SUBSTITUTE(UPPER(Q24:X24),"CERTIFICATE","")))/11 & " Certificates ", "") ), " ", ", ") -> KCSE, KCPE, 2, Certificates | U24: Certificate in Animal Health | V24: KCSE | W24: KCPE | X24: Certificate in Baboon Insertable Cardiac Monitor Project | Y24: Permanent | Z24: Kikuyu
A25: 22 | B25: 22 | C25: 20114215537 | D25: Mr. Adino, Thomas Agutu | F25: 10344158 | G25: M | H25: 55 | I25: Senior Animal Health Assistant - EL - H03EJ | J25: Animal Science &Welfare ethics | K25: J | L25: 0 - Active | M25: 22/07/2029 | N25: 40549 | O25: Mr. Adino, Thomas Agutu | P25: =SUBSTITUTE(TRIM( IF(COUNTIF(Q25:X25, "*Philosophy*"), "PhD ", "") & IF(COUNTIF(Q25:X25, "*Master*"), "MSc ", "") & IF(COUNTIF(Q25:X25, "*Bachelor*"), "Bachelors ", "") & IF(COUNTIF(Q25:X25, "*Diploma*"), "Dip ", "") & IF(COUNTIF(Q25:X25, "*KCSE*"), "KCSE ", "") & IF(COUNTIF(Q25:X25, "*KCPE*"), "KCPE ", "") & IF(COUNTIF(Q25:X25, "*IHRM*"), "IHRM ", "") & IF(COUNTIF(Q25:X25, "*HRMPB*"), "HRMPB ", "") & IF(COUNTIF(Q25:X25, "*KISM*"), "KISM ", "") & IF(COUNTIF(Q25:X25, "*ICPAK*"), "ICPAK ", "") & IF(COUNTIF(Q25:X25, "*CPA*"), "CPA ", "") & IF(COUNTIF(Q25:X25, "*Strategic Leadership*"), "SLDP ", "") & IF(COUNTIF(Q25:X25, "*Senior Management*"), "SMC ", "") & IF(COUNTIF(Q25:X25, "*Nursing*"), "NCK ", "") & IF(COUNTIF(Q25:X25, "*KMLTTB*"), "KMLTTB ", "") & IF(COUNTIF(Q25:X25, "*Cstat*"), "Cstat ", "") & IF(SUMPRODUCT(LEN(Q25:X25)-LEN(SUBSTITUTE(UPPER(Q25:X25),"CERTIFICATE","")))/11>0, SUMPRODUCT(LEN(Q25:X25)-LEN(SUBSTITUTE(UPPER(Q25:X25),"CERTIFICATE","")))/11 & " Certificates ", "") ), " ", ", ") -> Bachelors, Dip, KCSE, KCPE, 1, Certificates | S25: Bachelor of Science of Technology and Applied Biology | T25: Diploma in Technology (INDUSTRIAL AND APPLIED BIOLOGY) | U25: Certificate in Medical Laboratory Science lab | V25: KCSE | W25: KCPE | Y25: Permanent | Z25: Luo
A26: 23 | B26: 23 | C26: 20142576250 | D26: Ms. Jerono, Caroline | F26: 26426983 | G26: F | H26: 36 | I26: Laboratory Technologist [3] - EL - L07CJ | J26: Animal Science &Welfare ethics | K26: J | L26: 0 - Active | M26: 09/05/2048 | N26: 41640 | O26: Ms. Jerono, Caroline | P26: =SUBSTITUTE(TRIM( IF(COUNTIF(Q26:X26, "*Philosophy*"), "PhD ", "") & IF(COUNTIF(Q26:X26, "*Master*"), "MSc ", "") & IF(COUNTIF(Q26:X26, "*Bachelor*"), "Bachelors ", "") & IF(COUNTIF(Q26:X26, "*Diploma*"), "Dip ", "") & IF(COUNTIF(Q26:X26, "*KCSE*"), "KCSE ", "") & IF(COUNTIF(Q26:X26, "*KCPE*"), "KCPE ", "") & IF(COUNTIF(Q26:X26, "*IHRM*"), "IHRM ", "") & IF(COUNTIF(Q26:X26, "*HRMPB*"), "HRMPB ", "") & IF(COUNTIF(Q26:X26, "*KISM*"), "KISM ", "") & IF(COUNTIF(Q26:X26, "*ICPAK*"), "ICPAK ", "") & IF(COUNTIF(Q26:X26, "*CPA*"), "CPA ", "") & IF(COUNTIF(Q26:X26, "*Strategic Leadership*"), "SLDP ", "") & IF(COUNTIF(Q26:X26, "*Senior Management*"), "SMC ", "") & IF(COUNTIF(Q26:X26, "*Nursing*"), "NCK ", "") & IF(COUNTIF(Q26:X26, "*KMLTTB*"), "KMLTTB ", "") & IF(COUNTIF(Q26:X26, "*Cstat*"), "Cstat ", "") & IF(SUMPRODUCT(LEN(Q26:X26)-LEN(SUBSTITUTE(UPPER(Q26:X26),"CERTIFICATE","")))/11>0, SUMPRODUCT(LEN(Q26:X26)-LEN(SUBSTITUTE(UPPER(Q26:X26),"CERTIFICATE","")))/11 & " Certificates ", "") ), " ", ", ") -> Bachelors, Dip, KCSE, KCPE | S26: Bachelor of Science of Technology in Biotechnology | T26: Diploma in Applied Biology | V26: KCSE | W26: KCPE | Y26: Permanent | Z26: Kalenjin
A27: 24 | B27: 24 | C27: 20152655226 | D27: Mr. Omondi, Hillary Ochieng | F27: 25584197 | G27: M | H27: 37 | I27: Senior Animal Health Assistant - EL - H03EJ | J27: Animal Science &Welfare ethics | K27: J | L27: 0 - Active | M27: 30/06/2025 | N27: 13/08/2015 | O27: Mr. Omondi, Hillary Ochieng | P27: =SUBSTITUTE(TRIM( IF(COUNTIF(Q27:X27, "*Philosophy*"), "PhD ", "") & IF(COUNTIF(Q27:X27, "*Master*"), "MSc ", "") & IF(COUNTIF(Q27:X27, "*Bachelor*"), "Bachelors ", "") & IF(COUNTIF(Q27:X27, "*Diploma*"), "Dip ", "") & IF(COUNTIF(Q27:X27, "*KCSE*"), "KCSE ", "") & IF(COUNTIF(Q27:X27, "*KCPE*"), "KCPE ", "") & IF(COUNTIF(Q27:X27, "*IHRM*"), "IHRM ", "") & IF(COUNTIF(Q27:X27, "*HRMPB*"), "HRMPB ", "") & IF(COUNTIF(Q27:X27, "*KISM*"), "KISM ", "") & IF(COUNTIF(Q27:X27, "*ICPAK*"), "ICPAK ", "") & IF(COUNTIF(Q27:X27, "*CPA*"), "CPA ", "") & IF(COUNTIF(Q27:X27, "*Strategic Leadership*"), "SLDP ", "") & IF(COUNTIF(Q27:X27, "*Senior Management*"), "SMC ", "") & IF(COUNTIF(Q27:X27, "*Nursing*"), "NCK ", "") & IF(COUNTIF(Q27:X27, "*KMLTTB*"), "KMLTTB ", "") & IF(COUNTIF(Q27:X27, "*Cstat*"), "Cstat ", "") & IF(SUMPRODUCT(LEN(Q27:X27)-LEN(SUBSTITUTE(UPPER(Q27:X27),"CERTIFICATE","")))/11>0, SUMPRODUCT(LEN(Q27:X27)-LEN(SUBSTITUTE(UPPER(Q27:X27),"CERTIFICATE","")))/11 & " Certificates ", "") ), " ", ", ") -> Dip, KCSE, KCPE | T27: Diploma in Technology (Industrial and Applied Biology | V27: KCSE | W27: KCPE | Y27: Local Contract | Z27: Luo
A28: 25 | B28: 25 | C28: 20178600980 | D28: Ms. Kigen, Daisy Jebet | F28: 22538194 | G28: F | H28: 44 | I28: Senior Animal Health Assistant - EL - H03EJ | J28: Animal Science &Welfare ethics | K28: J | L28: 0 - Active | M28: 01/05/2027 | N28: 42830 | O28: Ms. Kigen, Daisy Jebet | P28: =SUBSTITUTE(TRIM( IF(COUNTIF(Q28:X28, "*Philosophy*"), "PhD ", "") & IF(COUNTIF(Q28:X28, "*Master*"), "MSc ", "") & IF(COUNTIF(Q28:X28, "*Bachelor*"), "Bachelors ", "") & IF(COUNTIF(Q28:X28, "*Diploma*"), "Dip ", "") & IF(COUNTIF(Q28:X28, "*KCSE*"), "KCSE ", "") & IF(COUNTIF(Q28:X28, "*KCPE*"), "KCPE ", "") & IF(COUNTIF(Q28:X28, "*IHRM*"), "IHRM ", "") & IF(COUNTIF(Q28:X28, "*HRMPB*"), "HRMPB ", "") & IF(COUNTIF(Q28:X28, "*KISM*"), "KISM ", "") & IF(COUNTIF(Q28:X28, "*ICPAK*"), "ICPAK ", "") & IF(COUNTIF(Q28:X28, "*CPA*"), "CPA ", "") & IF(COUNTIF(Q28:X28, "*Strategic Leadership*"), "SLDP ", "") & IF(COUNTIF(Q28:X28, "*Senior Management*"), "SMC ", "") & IF(COUNTIF(Q28:X28, "*Nursing*"), "NCK ", "") & IF(COUNTIF(Q28:X28, "*KMLTTB*"), "KMLTTB ", "") & IF(COUNTIF(Q28:X28, "*Cstat*"), "Cstat ", "") & IF(SUMPRODUCT(LEN(Q28:X28)-LEN(SUBSTITUTE(UPPER(Q28:X28),"CERTIFICATE","")))/11>0, SUMPRODUCT(LEN(Q28:X28)-LEN(SUBSTITUTE(UPPER(Q28:X28),"CERTIFICATE","")))/11 & " Certificates ", "") ), " ", ", ") -> Dip, KCSE, KCPE | T28: Diploma in Community Nutrition | V28: KCSE | W28: KCPE | Y28: Local Contract | Z28: Kalenjin
A29: 26 | B29: 26 | C29: 19920654349 | D29: Mr. Githinji, James Ndungu | F29: 11652898 | G29: M | H29: 55 | I29: Animal Health Assistant [1] - EL - H03EH | J29: Animal Science &Welfare ethics | K29: H | L29: 0 - Active | M29: 05/11/2029 | N29: 33640 | O29: Mr. Githinji, James Ndungu | P29: =SUBSTITUTE(TRIM( IF(COUNTIF(Q29:X29, "*Philosophy*"), "PhD ", "") & IF(COUNTIF(Q29:X29, "*Master*"), "MSc ", "") & IF(COUNTIF(Q29:X29, "*Bachelor*"), "Bachelors ", "") & IF(COUNTIF(Q29:X29, "*Diploma*"), "Dip ", "") & IF(COUNTIF(Q29:X29, "*KCSE*"), "KCSE ", "") & IF(COUNTIF(Q29:X29, "*KCPE*"), "KCPE ", "") & IF(COUNTIF(Q29:X29, "*IHRM*"), "IHRM ", "") & IF(COUNTIF(Q29:X29, "*HRMPB*"), "HRMPB ", "") & IF(COUNTIF(Q29:X29, "*KISM*"), "KISM ", "") & IF(COUNTIF(Q29:X29, "*ICPAK*"), "ICPAK ", "") & IF(COUNTIF(Q29:X29, "*CPA*"), "CPA ", "") & IF(COUNTIF(Q29:X29, "*Strategic Leadership*"), "SLDP ", "") & IF(COUNTIF(Q29:X29, "*Senior Management*"), "SMC ", "") & IF(COUNTIF(Q29:X29, "*Nursing*"), "NCK ", "") & IF(COUNTIF(Q29:X29, "*KMLTTB*"), "KMLTTB ", "") & IF(COUNTIF(Q29:X29, "*Cstat*"), "Cstat ", "") & IF(SUMPRODUCT(LEN(Q29:X29)-LEN(SUBSTITUTE(UPPER(Q29:X29),"CERTIFICATE","")))/11>0, SUMPRODUCT(LEN(Q29:X29)-LEN(SUBSTITUTE(UPPER(Q29:X29),"CERTIFICATE","")))/11 & " Certificates ", "") ), " ", ", ") -> KCSE, KCPE, 1, Certificates | V29: KCSE | W29: KCPE | X29: Certificate in Baboon Insertable Cardiac Monitor Project | Y29: Permanent | Z29: Kikuyu
A30: 27 | B30: 27 | C30: 19980490640 | D30: Ms. Nzuve, Mary Ngusye | F30: 13706972 | G30: F | H30: 49 | I30: Laboratory Assistant [2] - EL - L07BH | J30: Animal Science &Welfare ethics | K30: H | L30: 0 - Active | M30: 25/05/2035 | N30: 36016 | O30: Ms. Nzuve, Mary Ngusye | P30: =SUBSTITUTE(TRIM( IF(COUNTIF(Q30:X30, "*Philosophy*"), "PhD ", "") & IF(COUNTIF(Q30:X30, "*Master*"), "MSc ", "") & IF(COUNTIF(Q30:X30, "*Bachelor*"), "Bachelors ", "") & IF(COUNTIF(Q30:X30, "*Diploma*"), "Dip ", "") & IF(COUNTIF(Q30:X30, "*KCSE*"), "KCSE ", "") & IF(COUNTIF(Q30:X30, "*KCPE*"), "KCPE ", "") & IF(COUNTIF(Q30:X30, "*IHRM*"), "IHRM ", "") & IF(COUNTIF(Q30:X30, "*HRMPB*"), "HRMPB ", "") & IF(COUNTIF(Q30:X30, "*KISM*"), "KISM ", "") & IF(COUNTIF(Q30:X30, "*ICPAK*"), "ICPAK ", "") & IF(COUNTIF(Q30:X30, "*CPA*"), "CPA ", "") & IF(COUNTIF(Q30:X30, "*Strategic Leadership*"), "SLDP ", "") & IF(COUNTIF(Q30:X30, "*Senior Management*"), "SMC ", "") & IF(COUNTIF(Q30:X30, "*Nursing*"), "NCK ", "") & IF(COUNTIF(Q30:X30, "*KMLTTB*"), "KMLTTB ", "") & IF(COUNTIF(Q30:X30, "*Cstat*"), "Cstat ", "") & IF(SUMPRODUCT(LEN(Q30:X30)-LEN(SUBSTITUTE(UPPER(Q30:X30),"CERTIFICATE","")))/11>0, SUMPRODUCT(LEN(Q30:X30)-LEN(SUBSTITUTE(UPPER(Q30:X30),"CERTIFICATE","")))/11 & " Certificates ", "") ), " ", ", ") -> KCSE, KCPE, 1, Certificates | U30: Certificate in Medical Laboratory Science | V30: KCSE | W30: KCPE | Y30: Permanent | Z30: Kamba
A31: 28 | B31: 28 | C31: 20060933768 | D31: Mr. Alembi, Jason Emmanuel | F31: 13501715 | G31: M | H31: 50 | I31: Animal Health Assistant [1] - EL - H03EH | J31: Animal Science &Welfare ethics | K31: H | L31: 0 - Active | M31: 04/08/2034 | N31: 38907 | O31: Mr. Alembi, Jason Emmanuel | P31: =SUBSTITUTE(TRIM( IF(COUNTIF(Q31:X31, "*Philosophy*"), "PhD ", "") & IF(COUNTIF(Q31:X31, "*Master*"), "MSc ", "") & IF(COUNTIF(Q31:X31, "*Bachelor*"), "Bachelors ", "") & IF(COUNTIF(Q31:X31, "*Diploma*"), "Dip ", "") & IF(COUNTIF(Q31:X31, "*KCSE*"), "KCSE ", "") & IF(COUNTIF(Q31:X31, "*KCPE*"), "KCPE ", "") & IF(COUNTIF(Q31:X31, "*IHRM*"), "IHRM ", "") & IF(COUNTIF(Q31:X31, "*HRMPB*"), "HRMPB ", "") & IF(COUNTIF(Q31:X31, "*KISM*"), "KISM ", "") & IF(COUNTIF(Q31:X31, "*ICPAK*"), "ICPAK ", "") & IF(COUNTIF(Q31:X31, "*CPA*"), "CPA ", "") & IF(COUNTIF(Q31:X31, "*Strategic Leadership*"), "SLDP ", "") & IF(COUNTIF(Q31:X31, "*Senior Management*"), "SMC ", "") & IF(COUNTIF(Q31:X31, "*Nursing*"), "NCK ", "") & IF(COUNTIF(Q31:X31, "*KMLTTB*"), "KMLTTB ", "") & IF(COUNTIF(Q31:X31, "*Cstat*"), "Cstat ", "") & IF(SUMPRODUCT(LEN(Q31:X31)-LEN(SUBSTITUTE(UPPER(Q31:X31),"CERTIFICATE","")))/11>0, SUMPRODUCT(LEN(Q31:X31)-LEN(SUBSTITUTE(UPPER(Q31:X31),"CERTIFICATE","")))/11 & " Certificates ", "") ), " ", ", ") -> KCSE, KCPE, 1, Certificates | U31: Certificate in Store Keeping | V31: KCSE | W31: KCPE | Y31: Permanent | Z31: Luhya
A32: 29 | B32: 29 | C32: 20077018155 | D32: Mr. Ngacha, James Gichuru | F32: 14705584 | G32: M | H32: 48 | I32: Curatorial Assistant [2] - EL - M16BH | J32: Animal Science &Welfare ethics | K32: H | L32: 0 - Active | M32: 14/09/2036 | N32: 39084 | O32: Mr. Ngacha, James Gichuru | P32: =SUBSTITUTE(TRIM( IF(COUNTIF(Q32:X32, "*Philosophy*"), "PhD ", "") & IF(COUNTIF(Q32:X32, "*Master*"), "MSc ", "") & IF(COUNTIF(Q32:X32, "*Bachelor*"), "Bachelors ", "") & IF(COUNTIF(Q32:X32, "*Diploma*"), "Dip ", "") & IF(COUNTIF(Q32:X32, "*KCSE*"), "KCSE ", "") & IF(COUNTIF(Q32:X32, "*KCPE*"), "KCPE ", "") & IF(COUNTIF(Q32:X32, "*IHRM*"), "IHRM ", "") & IF(COUNTIF(Q32:X32, "*HRMPB*"), "HRMPB ", "") & IF(COUNTIF(Q32:X32, "*KISM*"), "KISM ", "") & IF(COUNTIF(Q32:X32, "*ICPAK*"), "ICPAK ", "") & IF(COUNTIF(Q32:X32, "*CPA*"), "CPA ", "") & IF(COUNTIF(Q32:X32, "*Strategic Leadership*"), "SLDP ", "") & IF(COUNTIF(Q32:X32, "*Senior Management*"), "SMC ", "") & IF(COUNTIF(Q32:X32, "*Nursing*"), "NCK ", "") & IF(COUNTIF(Q32:X32, "*KMLTTB*"), "KMLTTB ", "") & IF(COUNTIF(Q32:X32, "*Cstat*"), "Cstat ", "") & IF(SUMPRODUCT(LEN(Q32:X32)-LEN(SUBSTITUTE(UPPER(Q32:X32),"CERTIFICATE","")))/11>0, SUMPRODUCT(LEN(Q32:X32)-LEN(SUBSTITUTE(UPPER(Q32:X32),"CERTIFICATE","")))/11 & " Certificates ", "") ), " ", ", ") -> KCSE, KCPE | V32: KCSE | W32: KCPE | Y32: Permanent | Z32: Kikuyu
A33: 30 | B33: 30 | C33: 20077018309 | D33: Mr. Nayok, Collins Melubo | F33: 22657472 | G33: M | H33: 47 | I33: Office Assistant [2] - EL - T04DH | J33: Animal Science &Welfare ethics | K33: H | L33: 0 - Active | M33: 07/02/2038 | N33: 39083 | O33: Mr. Nayok, Collins Melubo | P33: =SUBSTITUTE(TRIM( IF(COUNTIF(Q33:X33, "*Philosophy*"), "PhD ", "") & IF(COUNTIF(Q33:X33, "*Master*"), "MSc ", "") & IF(COUNTIF(Q33:X33, "*Bachelor*"), "Bachelors ", "") & IF(COUNTIF(Q33:X33, "*Diploma*"), "Dip ", "") & IF(COUNTIF(Q33:X33, "*KCSE*"), "KCSE ", "") & IF(COUNTIF(Q33:X33, "*KCPE*"), "KCPE ", "") & IF(COUNTIF(Q33:X33, "*IHRM*"), "IHRM ", "") & IF(COUNTIF(Q33:X33, "*HRMPB*"), "HRMPB ", "") & IF(COUNTIF(Q33:X33, "*KISM*"), "KISM ", "") & IF(COUNTIF(Q33:X33, "*ICPAK*"), "ICPAK ", "") & IF(COUNTIF(Q33:X33, "*CPA*"), "CPA ", "") & IF(COUNTIF(Q33:X33, "*Strategic Leadership*"), "SLDP ", "") & IF(COUNTIF(Q33:X33, "*Senior Management*"), "SMC ", "") & IF(COUNTIF(Q33:X33, "*Nursing*"), "NCK ", "") & IF(COUNTIF(Q33:X33, "*KMLTTB*"), "KMLTTB ", "") & IF(COUNTIF(Q33:X33, "*Cstat*"), "Cstat ", "") & IF(SUMPRODUCT(LEN(Q33:X33)-LEN(SUBSTITUTE(UPPER(Q33:X33),"CERTIFICATE","")))/11>0, SUMPRODUCT(LEN(Q33:X33)-LEN(SUBSTITUTE(UPPER(Q33:X33),"CERTIFICATE","")))/11 & " Certificates ", "") ), " ", ", ") -> KCSE, KCPE, 1, Certificates | U33: Certificate in Library Studies | V33: KCSE | W33: KCPE | Y33: Permanent | Z33: Maasai
A34: 31 | B34: 31 | C34: 20089223821 | D34: Mr. Kiage, Walter Omaribah | F34: 22145871 | G34: M | H34: 44 | I34: Animal Health Assistant [1] - EL - H03EH | J34: Animal Science &Welfare ethics | K34: H | L34: 0 - Active | M34: 03/10/2040 | N34: 39454 | O34: Mr. Kiage, Walter Omaribah | P34: =SUBSTITUTE(TRIM( IF(COUNTIF(Q34:X34, "*Philosophy*"), "PhD ", "") & IF(COUNTIF(Q34:X34, "*Master*"), "MSc ", "") & IF(COUNTIF(Q34:X34, "*Bachelor*"), "Bachelors ", "") & IF(COUNTIF(Q34:X34, "*Diploma*"), "Dip ", "") & IF(COUNTIF(Q34:X34, "*KCSE*"), "KCSE ", "") & IF(COUNTIF(Q34:X34, "*KCPE*"), "KCPE ", "") & IF(COUNTIF(Q34:X34, "*IHRM*"), "IHRM ", "") & IF(COUNTIF(Q34:X34, "*HRMPB*"), "HRMPB ", "") & IF(COUNTIF(Q34:X34, "*KISM*"), "KISM ", "") & IF(COUNTIF(Q34:X34, "*ICPAK*"), "ICPAK ", "") & IF(COUNTIF(Q34:X34, "*CPA*"), "CPA ", "") & IF(COUNTIF(Q34:X34, "*Strategic Leadership*"), "SLDP ", "") & IF(COUNTIF(Q34:X34, "*Senior Management*"), "SMC ", "") & IF(COUNTIF(Q34:X34, "*Nursing*"), "NCK ", "") & IF(COUNTIF(Q34:X34, "*KMLTTB*"), "KMLTTB ", "") & IF(COUNTIF(Q34:X34, "*Cstat*"), "Cstat ", "") & IF(SUMPRODUCT(LEN(Q34:X34)-LEN(SUBSTITUTE(UPPER(Q34:X34),"CERTIFICATE","")))/11>0, SUMPRODUCT(LEN(Q34:X34)-LEN(SUBSTITUTE(UPPER(Q34:X34),"CERTIFICATE","")))/11 & " Certificates ", "") ), " ", ", ") -> KCSE, KCPE, 1, Certificates | U34: Certificate in Technical Education | V34: KCSE | W34: KCPE | Y34: Permanent | Z34: Kisii
A35: 32 | B35: 32 | C35: 20210646208 | D35: Mr. Gahoyo, Furaha Ali | F35: 14620321 | G35: M | H35: 49 | I35: Animal Health Assistant [1] - EL - H03EH | J35: Animal Science &Welfare ethics | K35: H | L35: 0 - Active | M35: 31/08/2027 | N35: 44197 | O35: Mr. Gahoyo, Furaha Ali | P35: =SUBSTITUTE(TRIM( IF(COUNTIF(Q35:X35, "*Philosophy*"), "PhD ", "") & IF(COUNTIF(Q35:X35, "*Master*"), "MSc ", "") & IF(COUNTIF(Q35:X35, "*Bachelor*"), "Bachelors ", "") & IF(COUNTIF(Q35:X35, "*Diploma*"), "Dip ", "") & IF(COUNTIF(Q35:X35, "*KCSE*"), "KCSE ", "") & IF(COUNTIF(Q35:X35, "*KCPE*"), "KCPE ", "") & IF(COUNTIF(Q35:X35, "*IHRM*"), "IHRM ", "") & IF(COUNTIF(Q35:X35, "*HRMPB*"), "HRMPB ", "") & IF(COUNTIF(Q35:X35, "*KISM*"), "KISM ", "") & IF(COUNTIF(Q35:X35, "*ICPAK*"), "ICPAK ", "") & IF(COUNTIF(Q35:X35, "*CPA*"), "CPA ", "") & IF(COUNTIF(Q35:X35, "*Strategic Leadership*"), "SLDP ", "") & IF(COUNTIF(Q35:X35, "*Senior Management*"), "SMC ", "") & IF(COUNTIF(Q35:X35, "*Nursing*"), "NCK ", "") & IF(COUNTIF(Q35:X35, "*KMLTTB*"), "KMLTTB ", "") & IF(COUNTIF(Q35:X35, "*Cstat*"), "Cstat ", "") & IF(SUMPRODUCT(LEN(Q35:X35)-LEN(SUBSTITUTE(UPPER(Q35:X35),"CERTIFICATE","")))/11>0, SUMPRODUCT(LEN(Q35:X35)-LEN(SUBSTITUTE(UPPER(Q35:X35),"CERTIFICATE","")))/11 & " Certificates ", "") ), " ", ", ") -> Dip, KCSE, KCPE | T35: Ordinary Diploma in Clearing,Forwarding and Shipping Procedure. | V35: KCSE | W35: KCPE | Y35: Local Contract | Z35: Mijikenda
A36: 33 | B36: 33 | C36: 20000078914 | D36: Mr. Karongo, Stephen Kinyanjui | F36: 10141052 | G36: M | H36: 56 | I36: Animal Health Assistant [2] - EL - H03EG | J36: Animal Science &Welfare ethics | K36: G | L36: 0 - Active | M36: 16/04/2029 | N36: 36532 | O36: Mr. Karongo, Stephen Kinyanjui | P36: =SUBSTITUTE(TRIM( IF(COUNTIF(Q36:X36, "*Philosophy*"), "PhD ", "") & IF(COUNTIF(Q36:X36, "*Master*"), "MSc ", "") & IF(COUNTIF(Q36:X36, "*Bachelor*"), "Bachelors ", "") & IF(COUNTIF(Q36:X36, "*Diploma*"), "Dip ", "") & IF(COUNTIF(Q36:X36, "*KCSE*"), "KCSE ", "") & IF(COUNTIF(Q36:X36, "*KCPE*"), "KCPE ", "") & IF(COUNTIF(Q36:X36, "*IHRM*"), "IHRM ", "") & IF(COUNTIF(Q36:X36, "*HRMPB*"), "HRMPB ", "") & IF(COUNTIF(Q36:X36, "*KISM*"), "KISM ", "") & IF(COUNTIF(Q36:X36, "*ICPAK*"), "ICPAK ", "") & IF(COUNTIF(Q36:X36, "*CPA*"), "CPA ", "") & IF(COUNTIF(Q36:X36, "*Strategic Leadership*"), "SLDP ", "") & IF(COUNTIF(Q36:X36, "*Senior Management*"), "SMC ", "") & IF(COUNTIF(Q36:X36, "*Nursing*"), "NCK ", "") & IF(COUNTIF(Q36:X36, "*KMLTTB*"), "KMLTTB ", "") & IF(COUNTIF(Q36:X36, "*Cstat*"), "Cstat ", "") & IF(SUMPRODUCT(LEN(Q36:X36)-LEN(SUBSTITUTE(UPPER(Q36:X36),"CERTIFICATE","")))/11>0, SUMPRODUCT(LEN(Q36:X36)-LEN(SUBSTITUTE(UPPER(Q36:X36),"CERTIFICATE","")))/11 & " Certificates ", "") ), " ", ", ") -> KCPE | W36: KCPE | Y36: Permanent | Z36: Kikuyu
A37: 34 | B37: 34 | C37: 20178600786 | D37: Mr. Loitareng, Sammy Poghon | F37: 35374930 | G37: M | H37: 32 | I37: Senior Auxiliary staff - EL - T04CG | J37: Animal Science &Welfare ethics | K37: G | L37: 0 - Active | M37: 30/11/2027 | N37: 42898 | O37: Mr. Loitareng, Sammy Poghon | P37: =SUBSTITUTE(TRIM( IF(COUNTIF(Q37:X37, "*Philosophy*"), "PhD ", "") & IF(COUNTIF(Q37:X37, "*Master*"), "MSc ", "") & IF(COUNTIF(Q37:X37, "*Bachelor*"), "Bachelors ", "") & IF(COUNTIF(Q37:X37, "*Diploma*"), "Dip ", "") & IF(COUNTIF(Q37:X37, "*KCSE*"), "KCSE ", "") & IF(COUNTIF(Q37:X37, "*KCPE*"), "KCPE ", "") & IF(COUNTIF(Q37:X37, "*IHRM*"), "IHRM ", "") & IF(COUNTIF(Q37:X37, "*HRMPB*"), "HRMPB ", "") & IF(COUNTIF(Q37:X37, "*KISM*"), "KISM ", "") & IF(COUNTIF(Q37:X37, "*ICPAK*"), "ICPAK ", "") & IF(COUNTIF(Q37:X37, "*CPA*"), "CPA ", "") & IF(COUNTIF(Q37:X37, "*Strategic Leadership*"), "SLDP ", "") & IF(COUNTIF(Q37:X37, "*Senior Management*"), "SMC ", "") & IF(COUNTIF(Q37:X37, "*Nursing*"), "NCK ", "") & IF(COUNTIF(Q37:X37, "*KMLTTB*"), "KMLTTB ", "") & IF(COUNTIF(Q37:X37, "*Cstat*"), "Cstat ", "") & IF(SUMPRODUCT(LEN(Q37:X37)-LEN(SUBSTITUTE(UPPER(Q37:X37),"CERTIFICATE","")))/11>0, SUMPRODUCT(LEN(Q37:X37)-LEN(SUBSTITUTE(UPPER(Q37:X37),"CERTIFICATE","")))/11 & " Certificates ", "") ), " ", ", ") -> KCSE, KCPE | V37: KCSE | W37: KCPE | Y37: Local Contract | Z37: Maasai
