Workbook

Sheet financial statement 2018
A1: ALPHA ROYALWOMEN GROUP
A2: BALANCE AS AT 30TH SEPTEMBER 2018
A3: FINANCIAL STATEMENT
C4: Kshs. | D4: Kshs.
A5: Balance Brought Forward | D5: ='[1]Financial statement'!$D$16 -> 0
A6: Total share Contribution | D6: =Contributions!P18 -> 694600
A7: CSR Contribution | D7: =Welfare!O17 -> 66000
A8: Commission | B8: 1 | D8: =B71 -> 66192.76
A10: Cash at Bank | B10: 1 | C10: =B22 -> 1589565
A11: Deposits | B11: 2 | C11: =B27 -> 1000000
A12: Debtor | B12: 3 | C12: =B40 -> 284000
A13: loan Balances | B13: 4 | C13: =B44 -> 100000
B14: 5 | C14: 0
C15: =C10+C11+C12+C13 -> 2973565 | D15: =SUM(D5:D14) -> 826792.76
A19: NOTE '1 | B19: Kshs.
A20: KCB BALANCES | B20: 881124
A21: CBA BALANCES | B21: 708441
B22: =B20+B21 -> 1589565
A24: NOTE '2
A25: Being cash Deposited with Zimele | B25: 500000
A26: Being Cash Deposited with CIC | B26: 500000
A27: Total | B27: =B25+B26 -> 1000000
A30: NOTE '3 | B30: Kshs.
A31: Aisha Muthoni | B31: -66000
A32: Khadijah Jaber | B32: -38500
A33: Maimuna Juma | B33: -54500
A34: Patience Ndonye | B34: -41000
A35: Rabia Salim | B35: -11000
A36: Rehema Ali | B36: -44000
A37: Sheila Mwalekwa | B37: -16000
A38: Commissions Maimuna | B38: -3000
A39: Commissions Aisha | B39: -10000
A40: Total | B40: =-SUM(B31:B39) -> 284000
A42: NOTE '4 | B42: Kshs
A43: Loan balance Aisha | B43: 100000
A44: Total | B44: 100000
A48: NOTE '5 | B48: Kshs.
A49: Commission | B49: 28000
A50: Zimele Earnings | B50: 2000
A51: CIC Earnings | B51: 3000
...

Sheet Statement 2021
B3: ALPHA ROYAL WOMEN GROUP
B5: FINANCIAL STATEMENT AS AT 30.09.2021
D7: DR | E7: CR
A8: Total shares contribution | E8: 3445000
A9: CSR Contribution | E9: 297500
A10: Commission | E10: 74000
A11: ICEA LION interest | E11: 127436
A12: Zimelee interest | E12: 87493
A13: Admin fee | B13: Note 2 | E13: 15500
A14: Creditors
A15: AMINA SALIM | E15: 5000
A16: Nuru Kibirige | E16: 10100
A17: overdrawn | E17: 9500
A18: Zimelee | B18: Note 1 | D18: 366796.4
A19: House Deposit | D19: 1440000
A20: Loan Balancies | D20: 616000
A21: Cash in NCBA | D21: 288914
A22: Cash in KCB | D22: 198982.05
A24: DEBTORS CONTRIBUTION
A25: Aisha Muthoni | B25: -155000
A26: FATMA SHAFFY | B26: -30000
A27: KHADIJA JABER | B27: -95000
A28: Maimuna Juma | B28: -58000
A29: NURU ZUHUDI | B29: -60000
A30: Patience Ndonye | B30: -125000
A31: Rehema Ali | B31: -80000
A32: RIZIKI KAGUA | B32: -95000
A33: Sheila Mwalekwa | B33: -60000
A34: ZUHURA SUMBA | B34: -50000 | D34: 808300
A35: Rabia refund of contr | D35: 104500
A36: DEBTOR CSR
A37: Suspence | B37: 2536.55
A38: Aisha Muthoni | B38: -15500
A39: Amina Salim | B39: -500
A40: Fatma Shaffy | B40: -3500
A41: Khadija Jaber | B41: -8000
A42: Maimuna Juma | B42: -6000
A43: Nuru Zuhudi | B43: -6000
A44: Patience Ndonye | B44: -16000
A45: Rehema Ali | B45: -10000
...

Sheet statememnt 2020
A1: ALPHA ROYAL WOMEN GROUP
A2: STATEMENT OF ACCOUNTS
A3: STATUS OF CHAMA 2020
A4: Item | B4: Description | C4: 2020 | D4: 2019 | E4: 2018 | F4: 2017
A5: Contributions | B5: Expected Total Savings | C5: =40000*14 -> 560000 | D5: =(60000*14) -> 840000 | E5: =(60000*14) -> 840000 | F5: =5000*9*14 -> 630000
B6: Actual Members Savings | D6: =Contributions!P18 -> 694600 | E6: 882000 | F6: =[2]Sheet1!$K$28 -> 0
B7: Account Status | D7: =D6-D5 -> -145400 | E7: =E6-E5 -> 42000 | F7: =F6-F5 -> -630000
B8: Éxpected Cummulative Balance | D8: =F5+E5+D5 -> 2310000
B9: Cummulative Balances | D9: =Contributions!S18 -> 2179100
B10: Net Position | D10: =D9-D8 -> -130900
A12: Welfare (CSR) | B12: Expected Total Savings | C12: =500*8 -> 4000 | D12: =12*500*14 -> 84000 | E12: =11*500*14 -> 77000
B13: Actual Members Savings | D13: =Welfare!O17 -> 66000 | E13: =[2]CSR!$N$28 -> 0
B14: Account Status | D14: =D13-D12 -> -18000 | E14: =E13-E12 -> -77000
B15: Éxpected Cummulative Balance | D15: =E12+D12 -> 161000
B16: Cummulative Balances | D16: =Welfare!P17 -> 138500
B17: Net Position | D17: =D16-D15 -> -22500
A19: Registration | B19: Expected Total Savings | C19: =14*1000 -> 14000 | D19: =14*1000 -> 14000
B20: Actual Members Savings | C20: =Contributions!B18 -> 14000 | D20: =Contributions!B18 -> 14000
B21: Éxpected Cummulative Balance | C21: =D19 -> 14000 | D21: =E19+D19 -> 14000
B22: Net Position | C22: =C20-C21 -> 0 | D22: =D20-D21 -> 0
A24: Investments
A25: ICEA | B25: Deposits | C25: 500000 | D25: 500000 | E25: 500000
B26: Earnings | C26: 37564.4 | D26: =56117.16-21071.72 -> 35045.44 | E26: 21071.52
B27: Cummulative Income | C27: =D27+C26 -> 93681.36 | D27: =E26+D26 -> 56116.96
A29: Zimele | B29: Deposits | C29: 500000 | D29: 500000
B30: Earnings | C30: 49159.14 | D30: 3151
B31: Cummulative Income | C31: =C30+D31 -> 52310.14 | D31: =E30+D30 -> 3151
A33: Bank Account Balances | B33: KCB | C33: 3664 | D33: 881124 | E33: 981830
B34: CBA | C34: 708441 | D34: 316236 | E34: 0 | G34: =C48-D27 -> -18552.56
B35: Total | C35: =C33+C34 -> 712105 | D35: =D33+D34 -> 1197360 | E35: =E33+E34 -> 981830 | G35: =52310-D31 -> 49159
A37: Total Cash Position | B37: Bank Total | C37: =C35 -> 712105 | D37: =D35 -> 1197360
B38: Deposit Total | C38: =C29+C25 -> 1000000 | D38: =D29+D25 -> 1000000
B39: Loans Out | D39: =100000 -> 100000
B40: Total | D40: =D37+D38+D39 -> 2297360
B42: Members Contribution | D42: =D9+D21+D16 -> 2331600
B43: +Excesses | D43: 34600
B44: Less Expenses | D44: =-11636 -> -11636
B45: Total | D45: =SUM(D42:D44) -> 2354564
A47: Income Statements
A48: Income Statement | B48: ICEA | C48: =C26 -> 37564.4 | D48: =D26 -> 35045.44 | E48: 21071.52 | F48: 0
...

Sheet Welfare
A2: Name | B2: Bal B/F | C2: 43374 | D2: 43405 | E2: 43435 | F2: 43466 | G2: 43497 | H2: 43525 | I2: 43556 | J2: 43586 | K2: 43617 | L2: 43647 | M2: 43678 | N2: 43709 | O2: Total | P2: Grand Total | Q2: Amount Expected | R2: Deficit | S2: 43739 | T2: 43770 | U2: 43800 | V2: 43831 | W2: 43862 | X2: 43891 | Y2: 43922 | Z2: 43952 | AA2: 43983 | AB2: 44013 | AC2: 44044 | AD2: 44075 | AE2: Total | AF2: Expected Amount | AG2: Grand Total | AH2: Amount Expected | AI2: Deficit | AJ2: 44105 | AK2: 44136 | AL2: 44166 | AM2: 44197 | AN2: 44228 | AO2: 44256 | AP2: 44287 | AQ2: 44317 | AR2: 44348 | AS2: 44378 | AT2: 44409 | AU2: 44440 | AV2: Total | AW2: Expected Amount | AX2: Grand Total | AY2: Amount Expected | AZ2: Deficit | BA2: 44470 | BB2: 44501 | BC2: 44531 | BD2: 44562 | BE2: 44593 | BF2: 44621 | BG2: 44652 | BH2: 44682 | BI2: 44713 | BJ2: 44743 | BK2: 44774 | BL2: 44805 | BM2: Total | BN2: Expected Amount | BO2: Grand Total | BP2: Amount Expected | BQ2: Deficit
A3: Aisha Muthoni | B3: 6000 | O3: =SUM(C3:N3) -> 0 | P3: =SUM(B3:N3) -> 6000 | Q3: =5500+6000 -> 11500 | R3: =P3-Q3 -> -5500 | AE3: =SUM(S3:AD3) -> 0 | AF3: 4000 | AG3: =AE3+P3 -> 6000 | AH3: =Q3+AF3 -> 15500 | AI3: =AG3-AH3 -> -9500 | AV3: =SUM(AJ3:AU3) -> 0 | AW3: =500*12 -> 6000 | AX3: =AV3+AG3 -> 6000 | AY3: =AH3+AW3 -> 21500 | AZ3: =AX3-AY3 -> -15500 | BM3: =SUM(BA3:BL3) -> 0 | BN3: 0 | BO3: =BM3+AX3 -> 6000 | BP3: =AY3+BN3 -> 21500 | BQ3: =BO3-BP3 -> -15500
A4: Amina Salim | B4: 5500 | C4: 500 | D4: 500 | E4: 500 | F4: 500 | G4: 500 | H4: 500 | I4: 500 | J4: 500 | K4: 500 | L4: 500 | M4: 500 | N4: 500 | O4: =SUM(C4:N4) -> 6000 | P4: =SUM(B4:N4) -> 11500 | Q4: =5500+6000 -> 11500 | R4: =P4-Q4 -> 0 | S4: 500 | T4: 500 | U4: 500 | X4: 500 | Y4: 500 | Z4: 500 | AA4: 500 | AE4: =SUM(S4:AD4) -> 3500 | AF4: 4000 | AG4: =AE4+P4 -> 15000 | AH4: =Q4+AF4 -> 15500 | AI4: =AG4-AH4 -> -500 | AJ4: 500 | AK4: 500 | AL4: 500 | AM4: 500 | AN4: 500 | AO4: 1000 | AP4: 500 | AS4: 1000 | AT4: 500 | AU4: 500 | AV4: =SUM(AJ4:AU4) -> 6000 | AW4: =500*12 -> 6000 | AX4: =AV4+AG4 -> 21000 | AY4: =AH4+AW4 -> 21500 | AZ4: =AX4-AY4 -> -500 | BM4: =SUM(BA4:BL4) -> 0 | BN4: 0 | BO4: =BM4+AX4 -> 21000 | BP4: =AY4+BN4 -> 21500 | BQ4: =BO4-BP4 -> -500
A5: Fatma Shaffy | B5: 5500 | M5: 1000 | N5: 5000 | O5: =SUM(C5:N5) -> 6000 | P5: =SUM(B5:N5) -> 11500 | Q5: =5500+6000 -> 11500 | R5: =P5-Q5 -> 0 | V5: 500 | AA5: 500 | AB5: 500 | AD5: 2500 | AE5: =SUM(S5:AD5) -> 4000 | AF5: 4000 | AG5: =AE5+P5 -> 15500 | AH5: =Q5+AF5 -> 15500 | AI5: =AG5-AH5 -> 0 | AJ5: 1000 | AK5: 500 | AL5: 500 | AQ5: 500 | AV5: =SUM(AJ5:AU5) -> 2500 | AW5: =500*12 -> 6000 | AX5: =AV5+AG5 -> 18000 | AY5: =AH5+AW5 -> 21500 | AZ5: =AX5-AY5 -> -3500 | BA5: 3500 | BB5: 1000 | BC5: 500 | BD5: 500 | BE5: 500 | BF5: 500 | BG5: 500 | BH5: 500 | BI5: 500 | BJ5: 500 | BK5: 500 | BL5: 500 | BM5: =SUM(BA5:BL5) -> 9500 | BN5: =500*12 -> 6000 | BO5: =BM5+AX5 -> 27500 | BP5: =AY5+BN5 -> 27500 | BQ5: =BO5-BP5 -> 0
A6: Janet Dali | B6: 5500 | L6: 6000 | O6: =SUM(C6:N6) -> 6000 | P6: =SUM(B6:N6) -> 11500 | Q6: =5500+6000 -> 11500 | R6: =P6-Q6 -> 0 | AE6: =SUM(S6:AD6) -> 0 | AF6: 4000 | AG6: =AE6+P6 -> 11500 | AH6: =Q6+AF6 -> 15500 | AI6: =AG6-AH6 -> -4000 | AJ6: 4000 | AU6: 6000 | AV6: =SUM(AJ6:AU6) -> 10000 | AW6: =500*12 -> 6000 | AX6: =AV6+AG6 -> 21500 | AY6: =AH6+AW6 -> 21500 | AZ6: =AX6-AY6 -> 0 | BM6: =SUM(BA6:BL6) -> 0 | BN6: =500*12 -> 6000 | BO6: =BM6+AX6 -> 21500 | BP6: =AY6+BN6 -> 27500 | BQ6: =BO6-BP6 -> -6000
A7: Khadija Jaber | B7: 4000 | C7: 1500 | D7: 1000 | E7: 500 | G7: 1000 | N7: 3500 | O7: =SUM(C7:N7) -> 7500 | P7: =SUM(B7:N7) -> 11500 | Q7: =5500+6000 -> 11500 | R7: =P7-Q7 -> 0 | U7: 1000 | V7: 1000 | AE7: =SUM(S7:AD7) -> 2000 | AF7: 4000 | AG7: =AE7+P7 -> 13500 | AH7: =Q7+AF7 -> 15500 | AI7: =AG7-AH7 -> -2000 | AV7: =SUM(AJ7:AU7) -> 0 | AW7: =500*12 -> 6000 | AX7: =AV7+AG7 -> 13500 | AY7: =AH7+AW7 -> 21500 | AZ7: =AX7-AY7 -> -8000 | BM7: =SUM(BA7:BL7) -> 0 | BN7: =500*12 -> 6000 | BO7: =BM7+AX7 -> 13500 | BP7: =AY7+BN7 -> 27500 | BQ7: =BO7-BP7 -> -14000
A8: Maimuna Juma | B8: 5500 | C8: 500 | D8: 500 | N8: 3000 | O8: =SUM(C8:N8) -> 4000 | P8: =SUM(B8:N8) -> 9500 | Q8: =5500+6000 -> 11500 | R8: =P8-Q8 -> -2000 | AE8: =SUM(S8:AD8) -> 0 | AF8: 4000 | AG8: =AE8+P8 -> 9500 | AH8: =Q8+AF8 -> 15500 | AI8: =AG8-AH8 -> -6000 | AJ8: 6000 | AV8: =SUM(AJ8:AU8) -> 6000 | AW8: =500*12 -> 6000 | AX8: =AV8+AG8 -> 15500 | AY8: =AH8+AW8 -> 21500 | AZ8: =AX8-AY8 -> -6000 | BM8: =SUM(BA8:BL8) -> 0 | BN8: =500*12 -> 6000 | BO8: =BM8+AX8 -> 15500 | BP8: =AY8+BN8 -> 27500 | BQ8: =BO8-BP8 -> -12000
A9: Nuru Kibirige | B9: 5500 | C9: 500 | D9: 500 | E9: 500 | F9: 500 | G9: 500 | H9: 500 | I9: 500 | J9: 500 | K9: 2000 | O9: =SUM(C9:N9) -> 6000 | P9: =SUM(B9:N9) -> 11500 | Q9: =5500+6000 -> 11500 | R9: =P9-Q9 -> 0 | AC9: 2000 | AD9: 2000 | AE9: =SUM(S9:AD9) -> 4000 | AF9: 4000 | AG9: =AE9+P9 -> 15500 | AH9: =Q9+AF9 -> 15500 | AI9: =AG9-AH9 -> 0 | AS9: 6000 | AV9: =SUM(AJ9:AU9) -> 6000 | AW9: =500*12 -> 6000 | AX9: =AV9+AG9 -> 21500 | AY9: =AH9+AW9 -> 21500 | AZ9: =AX9-AY9 -> 0 | BK9: 500 | BL9: 5500 | BM9: =SUM(BA9:BL9) -> 6000 | BN9: =500*12 -> 6000 | BO9: =BM9+AX9 -> 27500 | BP9: =AY9+BN9 -> 27500 | BQ9: =BO9-BP9 -> 0
A10: Nuru Zuhudi | B10: 7500 | C10: 500 | D10: 0 | E10: 500 | F10: 500 | G10: 500 | H10: 500 | I10: 500 | K10: 500 | L10: 500 | N10: 1000 | O10: =SUM(C10:N10) -> 5000 | P10: =SUM(B10:N10) -> 12500 | Q10: =5500+6000 -> 11500 | R10: =P10-Q10 -> 1000 | AE10: =SUM(S10:AD10) -> 0 | AF10: 4000 | AG10: =AE10+P10 -> 12500 | AH10: =Q10+AF10 -> 15500 | AI10: =AG10-AH10 -> -3000 | AJ10: 3000 | AV10: =SUM(AJ10:AU10) -> 3000 | AW10: =500*12 -> 6000 | AX10: =AV10+AG10 -> 15500 | AY10: =AH10+AW10 -> 21500 | AZ10: =AX10-AY10 -> -6000 | BM10: =SUM(BA10:BL10) -> 0 | BN10: =500*12 -> 6000 | BO10: =BM10+AX10 -> 15500 | BP10: =AY10+BN10 -> 27500 | BQ10: =BO10-BP10 -> -12000
A11: Patience Ndonye | B11: 5500 | O11: =SUM(C11:N11) -> 0 | P11: =SUM(B11:N11) -> 5500 | Q11: =5500+6000 -> 11500 | R11: =P11-Q11 -> -6000 | AE11: =SUM(S11:AD11) -> 0 | AF11: 4000 | AG11: =AE11+P11 -> 5500 | AH11: =Q11+AF11 -> 15500 | AI11: =AG11-AH11 -> -10000 | AV11: =SUM(AJ11:AU11) -> 0 | AW11: =500*12 -> 6000 | AX11: =AV11+AG11 -> 5500 | AY11: =AH11+AW11 -> 21500 | AZ11: =AX11-AY11 -> -16000 | BM11: =SUM(BA11:BL11) -> 0 | BN11: =500*12 -> 6000 | BO11: =BM11+AX11 -> 5500 | BP11: =AY11+BN11 -> 27500 | BQ11: =BO11-BP11 -> -22000
A12: Rabia Salim | B12: 5500 | C12: 500 | E12: 500 | G12: 1000 | H12: 500 | I12: 500 | J12: 500 | K12: 500 | L12: 1000 | M12: 500 | N12: 500 | O12: =SUM(C12:N12) -> 6000 | P12: =SUM(B12:N12) -> 11500 | Q12: =5500+6000 -> 11500 | R12: =P12-Q12 -> 0 | T12: 500 | U12: 500 | V12: 500 | AA12: 500 | AB12: 500 | AE12: =SUM(S12:AD12) -> 2500 | AF12: 4000 | AG12: =AE12+P12 -> 14000 | AH12: =Q12+AF12 -> 15500 | AI12: =AG12-AH12 -> -1500 | AV12: =SUM(AJ12:AU12) -> 0 | AW12: =500*5 -> 2500 | AX12: =AV12+AG12 -> 14000 | AY12: =AH12+AW12 -> 18000 | AZ12: =AX12-AY12 -> -4000 | BM12: =SUM(BA12:BL12) -> 0 | BN12: 0 | BO12: =BM12+AX12 -> 14000 | BP12: =AY12+BN12 -> 18000 | BQ12: =BO12-BP12 -> -4000
A13: Rehema Ali | B13: 0 | C13: 5000 | F13: 2500 | O13: =SUM(C13:N13) -> 7500 | P13: =SUM(B13:N13) -> 7500 | Q13: =5500+6000 -> 11500 | R13: =P13-Q13 -> -4000 | AA13: 4000 | AE13: =SUM(S13:AD13) -> 4000 | AF13: 4000 | AG13: =AE13+P13 -> 11500 | AH13: =Q13+AF13 -> 15500 | AI13: =AG13-AH13 -> -4000 | AV13: =SUM(AJ13:AU13) -> 0 | AW13: =500*12 -> 6000 | AX13: =AV13+AG13 -> 11500 | AY13: =AH13+AW13 -> 21500 | AZ13: =AX13-AY13 -> -10000 | BL13: 16000 | BM13: =SUM(BA13:BL13) -> 16000 | BN13: =500*12 -> 6000 | BO13: =BM13+AX13 -> 27500 | BP13: =AY13+BN13 -> 27500 | BQ13: =BO13-BP13 -> 0
A14: Riziki Kagua | B14: 5500 | C14: 500 | D14: 500 | E14: 500 | F14: 500 | G14: 500 | H14: 500 | I14: 500 | J14: 500 | K14: 500 | L14: 500 | M14: 500 | N14: 500 | O14: =SUM(C14:N14) -> 6000 | P14: =SUM(B14:N14) -> 11500 | Q14: =5500+6000 -> 11500 | R14: =P14-Q14 -> 0 | S14: 500 | AE14: =SUM(S14:AD14) -> 500 | AF14: 4000 | AG14: =AE14+P14 -> 12000 | AH14: =Q14+AF14 -> 15500 | AI14: =AG14-AH14 -> -3500 | AV14: =SUM(AJ14:AU14) -> 0 | AW14: =500*12 -> 6000 | AX14: =AV14+AG14 -> 12000 | AY14: =AH14+AW14 -> 21500 | AZ14: =AX14-AY14 -> -9500 | BE14: 12000 | BM14: =SUM(BA14:BL14) -> 12000 | BN14: =500*12 -> 6000 | BO14: =BM14+AX14 -> 24000 | BP14: =AY14+BN14 -> 27500 | BQ14: =BO14-BP14 -> -3500
A15: Sheila Mwalekwa | B15: 5500 | O15: =SUM(C15:N15) -> 0 | P15: =SUM(B15:N15) -> 5500 | Q15: =5500+6000 -> 11500 | R15: =P15-Q15 -> -6000 | AD15: 10000 | AE15: =SUM(S15:AD15) -> 10000 | AF15: 4000 | AG15: =AE15+P15 -> 15500 | AH15: =Q15+AF15 -> 15500 | AI15: =AG15-AH15 -> 0 | AV15: =SUM(AJ15:AU15) -> 0 | AW15: =500*12 -> 6000 | AX15: =AV15+AG15 -> 15500 | AY15: =AH15+AW15 -> 21500 | AZ15: =AX15-AY15 -> -6000 | BA15: 6000 | BL15: 6000 | BM15: =SUM(BA15:BL15) -> 12000 | BN15: =500*12 -> 6000 | BO15: =BM15+AX15 -> 27500 | BP15: =AY15+BN15 -> 27500 | BQ15: =BO15-BP15 -> 0
A16: Zuhura Sumba | B16: 5500 | D16: 1000 | G16: 1000 | H16: 1000 | K16: 2000 | N16: 1000 | O16: =SUM(C16:N16) -> 6000 | P16: =SUM(B16:N16) -> 11500 | Q16: =5500+6000 -> 11500 | R16: =P16-Q16 -> 0 | X16: 1000 | AA16: 1000 | AE16: =SUM(S16:AD16) -> 2000 | AF16: 4000 | AG16: =AE16+P16 -> 13500 | AH16: =Q16+AF16 -> 15500 | AI16: =AG16-AH16 -> -2000 | AV16: =SUM(AJ16:AU16) -> 0 | AW16: =500*12 -> 6000 | AX16: =AV16+AG16 -> 13500 | AY16: =AH16+AW16 -> 21500 | AZ16: =AX16-AY16 -> -8000 | BM16: =SUM(BA16:BL16) -> 0 | BN16: =500*12 -> 6000 | BO16: =BM16+AX16 -> 13500 | BP16: =AY16+BN16 -> 27500 | BQ16: =BO16-BP16 -> -14000 | BR16: 9500 | BS16: bal 4500
A17: Total | B17: =SUM(B2:B16) -> 72500 | C17: =SUM(C2:C16) -> 52874 | D17: =SUM(D2:D16) -> 47405 | E17: =SUM(E2:E16) -> 46435 | F17: =SUM(F2:F16) -> 47966 | G17: =SUM(G2:G16) -> 48497 | H17: =SUM(H2:H16) -> 47025 | I17: =SUM(I2:I16) -> 46056 | ... S17: =SUM(S2:S16) -> 44739 | AI17: =AE17-AH17 -> 0 | AV17: =SUM(AV3:AV16) -> 33500 | AW17: =SUM(AW3:AW16) -> 80500 | AY17: =SUM(AY3:AY16) -> 297500 | BM17: =SUM(BM3:BM16) -> 55500 | BN17: =SUM(BN3:BN16) -> 66000 | BP17: =SUM(BP3:BP16) -> 363500
AA20: 16500

Sheet Loans
A1: Date | B1: Name | C1: Amount | D1: Commissions | E1: Total Obligation | F1: Paid | G1: Commissions Earned | H1: Balance
B2: Fatma Shaffi | C2: 60000 | D2: 6000 | E2: =C2+D2 -> 66000 | F2: 66000 | G2: =F2-C2 -> 6000 | H2: =E2-F2 -> 0
B3: Nuru Kibirige | C3: 60000 | D3: 6000 | E3: =C3+D3 -> 66000 | F3: 66000 | G3: =F3-C3 -> 6000 | H3: =E3-F3 -> 0
B4: Aisha Muthoni | C4: 100000 | D4: 5000 | E4: =C4+D4 -> 105000 | F4: 105000 | G4: =F4-C4 -> 5000 | H4: =E4-F4 -> 0
B5: Maimuna Juma | C5: 60000 | D5: 6000 | E5: =C5+D5 -> 66000 | F5: 66000 | G5: =F5-C5 -> 6000 | H5: =E5-F5 -> 0
B6: Khadija Bajaber | C6: 100000 | D6: =C6*10% -> 10000 | E6: =C6+D6 -> 110000 | F6: 88000 | G6: =F6-C6 -> -12000 | H6: =E6-F6 -> 22000 | I6: Khadija Jabir said she cleared to ask Janet
B7: Nuru Mohammed | C7: 150000 | D7: =C7*10% -> 15000 | E7: =C7+D7 -> 165000 | F7: 165000 | G7: 13500 | H7: =E7-F7 -> 0 | I7: paid balance loan of 16500 in october 2022( had paid 148500 earlier and cleared the 16500
B8: Nuru Kibirige | C8: 120000 | D8: =C8*10% -> 12000 | E8: =C8+D8 -> 132000 | F8: 132000 | G8: =F8-C8 -> 12000 | H8: =E8-F8 -> 0
B9: Nyevu Kagua | C9: 90000 | D9: =C9*10% -> 9000 | E9: =C9+D9 -> 99000 | G9: =F9-C9 -> -90000 | H9: =E9-F9 -> 99000
B10: Rabia Salim | C10: 100000 | D10: =C10*10% -> 10000 | E10: =C10+D10 -> 110000 | F10: 45000 | G10: =F10-C10 -> -55000 | H10: =E10-F10 -> 65000 | I10: offset agaist her shares
B11: Fatma Shaffi | C11: 100000 | D11: =C11*10% -> 10000 | E11: =C11+D11 -> 110000 | F11: 66000 | G11: =F11-C11 -> -34000 | H11: =E11-F11 -> 44000 | I11: fatma siad she cleared
B12: Maimuna Juma | C12: 150000 | D12: =C12*10% -> 15000 | E12: =C12+D12 -> 165000 | F12: 165000 | G12: =F12-C12 -> 15000 | H12: 85000 | I12: cleared in october
A13: 2021 | B13: Fatma Shaffi | C13: 100000 | D13: =C13*10% -> 10000 | E13: =C13+D13 -> 110000 | F13: 30000 | G13: =F13-C13 -> -70000 | H13: =E13-F13 -> 80000 | I13: cleared in october
A14: 2021 | B14: Janet Dali | C14: 200000 | D14: =C14*10% -> 20000 | E14: =C14+D14 -> 220000 | F14: 88000 | G14: =F14-C14 -> -112000 | H14: =E14-F14 -> 132000
A15: 2021 | B15: Maimuna Juma | C15: 200000 | D15: =C15*10% -> 20000 | E15: =C15+D15 -> 220000 | G15: =F15-C15 -> -200000 | H15: =E15-F15 -> 220000
B16: Total | C16: =SUM(C2:C15) -> 1590000 | D16: =SUM(D2:D15) -> 154000 | E16: =SUM(E2:E15) -> 1744000 | F16: =SUM(F2:F15) -> 1082000 | G16: =SUM(G2:G7) -> 24500 | H16: =SUM(H6:H15) -> 747000
B23: Nyevu Kagua | C23: 90000 | D23: 9000 | E23: =C23+D23 -> 99000 | F23: 99000 | G23: =F23-C23 -> 9000 | H23: =E23-F23 -> 0 | K23: paid in february 2022 99000 | P23: cleared
B24: Maimuna Juma | C24: 150000 | D24: 15000 | E24: =C24+D24 -> 165000 | F24: 165000 | G24: 15000 | K24: paid in october 21the balance of 85000 | P24: cleared
A25: 2021 | B25: Fatma Shaffi | C25: 100000 | D25: =C25*10% -> 10000 | E25: =C25+D25 -> 110000 | F25: 110000 | G25: =F25-C25 -> 10000 | H25: =E25-F25 -> 0 | K25: paid the balance of 80000 in october 2021 | P25: cleared | Q25: paid 30000 last financial year
A26: 2021 | B26: Janet Dali | C26: 200000 | D26: =C26*10% -> 20000 | E26: =C26+D26 -> 220000 | F26: 220000 | G26: =F26-C26 -> 20000 | H26: =E26-F26 -> 0 | K26: paid 88000 last financial year and cleared 132000 on 16th june 2022
A27: 2021 | B27: Maimuna Juma | C27: 200000 | D27: =C27*10% -> 20000 | E27: =C27+D27 -> 220000 | F27: 170000 | G27: =F27-C27 -> -30000 | H27: =E27-F27 -> 50000 | K27: paid 170,000 balance 50,000
B28: Total | C28: =SUM(C23:C27) -> 740000 | D28: =SUM(D23:D27) -> 74000 | E28: =SUM(E23:E27) -> 814000 | F28: =SUM(F24:F27) -> 665000 | G28: =SUM(G14:G19) -> -287500 | H28: =SUM(H23:H27) -> 50000

Sheet Contributions
A1: 2019 | W1: 2019 | X1: 2019 | Y1: 2020 | Z1: 2020 | AA1: 2020 | AB1: 2020 | AC1: 2020 | AD1: 2020 | AE1: 2020 | AF1: 2020 | AG1: 2020 | AN1: 2020 | AO1: 2020 | AP1: 2020 | AQ1: 2021 | AR1: 2021 | AS1: 2021 | AT1: 2021 | AU1: 2021 | AV1: 2021 | AW1: 2021 | AX1: 2021 | AY1: 2021 | BF1: 44470 | BG1: 44501 | BH1: 44531 | BI1: 44562 | BJ1: 44593 | BK1: 44621 | BL1: 44652 | BM1: 44682 | BN1: 44713 | BO1: 44743 | BP1: 44774 | BQ1: 44805 | BS1: Total Expected | BU1: Cummulative
A2: Name | B2: Membership | C2: Bal B/F | D2: Oct | E2: Nov | F2: Dec | G2: Jan | H2: Feb | I2: Mar | J2: Apr | K2: May | L2: Jun | M2: Jul | N2: Aug | O2: Sep | P2: Total | Q2: Amount Expected | R2: Deficit | S2: Total | T2: Total Expected | U2: BALANCE B/F | V2: Oct | W2: Nov | X2: Dec | Y2: Jan | Z2: Feb | AA2: Mar | AB2: Apr | AC2: May | AD2: Jun | AE2: Jul | AF2: Aug | AG2: Sep | AH2: Total | AI2: Amount Expected 2020 | AJ2: Deficit | AK2: Total | AL2: Total Expected | AM2: BALANCE B/F | AN2: Oct | AO2: Nov | AP2: Dec | AQ2: Jan | AR2: Feb | AS2: Mar | AT2: Apr | AU2: May | AV2: Jun | AW2: Jul | AX2: Aug | AY2: Sep | AZ2: Total | BA2: Amount Expected 2020 | BB2: Deficit | BC2: Total | BD2: Total Expected | BE2: BALANCE B/F | BR2: Total Paid | BS2: Amount Expected 2020 | BT2: Deficit | BU2: Total | BV2: Total Expected | BW2: BALANCE B/F
A3: Aisha Muthoni | B3: 1000 | C3: 110000 | P3: =SUM(D3:O3) -> 0 | Q3: =12*5000 -> 60000 | R3: =P3-Q3 -> -60000 | S3: =SUM(C3:O3) -> 110000 | T3: =105000+Q3 -> 165000 | U3: =S3-T3 -> -55000 | Z3: 0 | AA3: 0 | AB3: 0 | AC3: 0 | AH3: =SUM(V3:AG3) -> 0 | AI3: 40000 | AJ3: =AH3-AI3 -> -40000 | AK3: =S3+AH3 -> 110000 | AL3: =T3+AI3 -> 205000 | AM3: =AK3-AL3 -> -95000 | AZ3: =SUM(AN3:AY3) -> 0 | BA3: 60000 | BB3: =AZ3-BA3 -> -60000 | BC3: =AK3+AZ3 -> 110000 | BD3: =AL3+BA3 -> 265000 | BE3: =BC3-BD3 -> -155000 | BF3: 120000 | BR3: =SUM(BF3:BQ3) -> 120000 | BS3: 0 | BT3: 0 | BU3: =BC3+BR3 -> 230000 | BV3: =BD3+BS3 -> 265000 | BW3: =BU3-BV3 -> -35000
A4: AMINA SALIM | B4: 1000 | C4: 105000 | D4: 5000 | E4: 5000 | F4: 5000 | G4: 5000 | H4: 5000 | I4: 5000 | J4: 5000 | K4: 5000 | L4: 5000 | M4: 5000 | N4: 5000 | O4: 5000 | P4: =SUM(D4:O4) -> 60000 | Q4: =12*5000 -> 60000 | R4: =P4-Q4 -> 0 | S4: =SUM(C4:O4) -> 165000 | T4: =105000+Q4 -> 165000 | U4: =S4-T4 -> 0 | V4: 5000 | W4: 5000 | X4: 5000 | Y4: 5000 | Z4: 0 | AA4: 0 | AB4: 0 | AC4: 0 | AD4: 5000 | AE4: 5000 | AF4: 5000 | AG4: 5000 | AH4: =SUM(V4:AG4) -> 40000 | AI4: 40000 | AJ4: =AH4-AI4 -> 0 | AK4: =S4+AH4 -> 205000 | AL4: =T4+AI4 -> 205000 | AM4: =AK4-AL4 -> 0 | AN4: 5000 | AO4: 5000 | AP4: 5000 | AQ4: 5000 | AR4: 5000 | AS4: 10000 | AT4: 5000 | AW4: 10000 | AX4: 5000 | AY4: 10000 | AZ4: =SUM(AN4:AY4) -> 65000 | BA4: 60000 | BB4: =AZ4-BA4 -> 5000 | BC4: =AK4+AZ4 -> 270000 | BD4: =AL4+BA4 -> 265000 | BE4: =BC4-BD4 -> 5000 | BR4: 0 | BS4: 0 | BT4: =BR4-BS4 -> 0 | BU4: 270000 | BV4: =BD4+BS4 -> 265000 | BW4: =BU4-BV4 -> 5000
A5: FATMA SHAFFY | B5: 1000 | C5: 105000 | M5: 2000 | N5: 58000 | P5: =SUM(D5:O5) -> 60000 | Q5: =12*5000 -> 60000 | R5: =P5-Q5 -> 0 | S5: =SUM(C5:O5) -> 165000 | T5: =105000+Q5 -> 165000 | U5: =S5-T5 -> 0 | X5: 5000 | Y5: 5500 | Z5: 0 | AA5: 0 | AB5: 0 | AC5: 0 | AD5: 5500 | AE5: 5500 | AF5: 0 | AG5: 18500 | AH5: =SUM(V5:AG5) -> 40000 | AI5: 40000 | AJ5: =AH5-AI5 -> 0 | AK5: =S5+AH5 -> 205000 | AL5: =T5+AI5 -> 205000 | AM5: =AK5-AL5 -> 0 | AN5: 10000 | AO5: 5000 | AP5: 5000 | AU5: 5000 | AW5: 5000 | AZ5: =SUM(AN5:AY5) -> 30000 | BA5: 60000 | BB5: =AZ5-BA5 -> -30000 | BC5: =AK5+AZ5 -> 235000 | BD5: =AL5+BA5 -> 265000 | BE5: =BC5-BD5 -> -30000 | BF5: 30000 | BG5: 10000 | BH5: 5000 | BI5: 5000 | BJ5: 5000 | BK5: 5000 | BL5: 5000 | BM5: 5000 | BN5: 5000 | BO5: 5000 | BP5: 5000 | BQ5: 5000 | BR5: =SUM(BF5:BQ5) -> 90000 | BS5: 60000 | BT5: =BR5-BS5 -> 30000 | BU5: =BC5+BR5 -> 325000 | BV5: =BD5+BS5 -> 325000 | BW5: =BU5-BV5 -> 0
A6: Janet Dali | B6: 1000 | C6: 109500 | F6: ='Janet Dali'!C3 -> 15000 | M6: 54000 | P6: =SUM(D6:O6) -> 69000 | Q6: =12*5000 -> 60000 | R6: =P6-Q6 -> 9000 | S6: =SUM(C6:O6) -> 178500 | T6: =105000+Q6 -> 165000 | U6: =S6-T6 -> 13500 | Z6: 0 | AA6: 0 | AB6: 0 | AC6: 0 | AH6: =SUM(V6:AG6) -> 0 | AI6: 40000 | AJ6: =AH6-AI6 -> -40000 | AK6: =S6+AH6 -> 178500 | AL6: =T6+AI6 -> 205000 | AM6: =AK6-AL6 -> -26500 | AN6: 26500 | AY6: 60000 | AZ6: =SUM(AN6:AY6) -> 86500 | BA6: 60000 | BB6: =AZ6-BA6 -> 26500 | BC6: =AK6+AZ6 -> 265000 | BD6: =AL6+BA6 -> 265000 | BE6: =BC6-BD6 -> 0 | BJ6: 11000 | BN6: 38500 | BR6: =SUM(BF6:BQ6) -> 49500 | BS6: 60000 | BT6: =BR6-BS6 -> -10500 | BU6: =BC6+BR6 -> 314500 | BV6: =BD6+BS6 -> 325000 | BW6: =BU6-BV6 -> -10500
A7: KHADIJA JABER | B7: 1000 | C7: 105000 | E7: 10000 | F7: 5000 | H7: 10000 | O7: 35000 | P7: =SUM(D7:O7) -> 60000 | Q7: =12*5000 -> 60000 | R7: =P7-Q7 -> 0 | S7: =SUM(C7:O7) -> 165000 | T7: =105000+Q7 -> 165000 | U7: =S7-T7 -> 0 | W7: 5000 | Z7: 0 | AA7: 0 | AB7: 0 | AC7: 0 | AH7: =SUM(V7:AG7) -> 5000 | AI7: 40000 | AJ7: =AH7-AI7 -> -35000 | AK7: =S7+AH7 -> 170000 | AL7: =T7+AI7 -> 205000 | AM7: =AK7-AL7 -> -35000 | AZ7: =SUM(AN7:AY7) -> 0 | BA7: 60000 | BB7: =AZ7-BA7 -> -60000 | BC7: =AK7+AZ7 -> 170000 | BD7: =AL7+BA7 -> 265000 | BE7: =BC7-BD7 -> -95000 | BF7: 55400 | BG7: 47600 | BM7: 50000 | BR7: =SUM(BF7:BQ7) -> 153000 | BS7: 60000 | BT7: =BR7-BS7 -> 93000 | BU7: =BC7+BR7 -> 323000 | BV7: =BD7+BS7 -> 325000 | BW7: =BU7-BV7 -> -2000
A8: Maimuna Juma | B8: 1000 | C8: 105000 | D8: 5000 | E8: 5500 | O8: 30000 | P8: =SUM(D8:O8) -> 40500 | Q8: =12*5000 -> 60000 | R8: =P8-Q8 -> -19500 | S8: =SUM(C8:O8) -> 145500 | T8: =105000+Q8 -> 165000 | U8: =S8-T8 -> -19500 | Z8: 0 | AA8: 0 | AB8: 0 | AC8: 0 | AH8: =SUM(V8:AG8) -> 0 | AI8: 40000 | AJ8: =AH8-AI8 -> -40000 | AK8: =S8+AH8 -> 145500 | AL8: =T8+AI8 -> 205000 | AM8: =AK8-AL8 -> -59500 | AN8: 61500 | AZ8: =SUM(AN8:AY8) -> 61500 | BA8: 60000 | BB8: =AZ8-BA8 -> 1500 | BC8: =AK8+AZ8 -> 207000 | BD8: =AL8+BA8 -> 265000 | BE8: =BC8-BD8 -> -58000 | BM8: 110500 | BR8: =SUM(BF8:BQ8) -> 110500 | BS8: 60000 | BT8: =BR8-BS8 -> 50500 | BU8: =BC8+BR8 -> 317500 | BV8: =BD8+BS8 -> 325000 | BW8: =BU8-BV8 -> -7500
A9: Nuru Kibirige | B9: 1000 | C9: 105000 | D9: 5000 | E9: 5000 | F9: 5000 | G9: 7500 | H9: 5000 | I9: 5000 | J9: 5000 | K9: 25000 | L9: 7600 | M9: ='Nuru K'!G8 -> 0 | P9: =SUM(D9:O9) -> 70100 | Q9: =12*5000 -> 60000 | R9: =P9-Q9 -> 10100 | S9: =SUM(C9:O9) -> 175100 | T9: =105000+Q9 -> 165000 | U9: =S9-T9 -> 10100 | Z9: 0 | AA9: 0 | AB9: 0 | AC9: 0 | AF9: 23000 | AG9: 23000 | AH9: =SUM(V9:AG9) -> 46000 | AI9: 40000 | AJ9: =AH9-AI9 -> 6000 | AK9: =S9+AH9 -> 221100 | AL9: =T9+AI9 -> 205000 | AM9: =AK9-AL9 -> 16100 | AW9: 34000 | AX9: 20000 | AZ9: =SUM(AN9:AY9) -> 54000 | BA9: 60000 | BB9: =AZ9-BA9 -> -6000 | BC9: =AK9+AZ9 -> 275100 | BD9: =AL9+BA9 -> 265000 | BE9: =BC9-BD9 -> 10100 | BF9: 5500 | BJ9: 17000 | BM9: 10000 | BN9: 12500 | BO9: 5500 | BP9: 5000 | BR9: =SUM(BF9:BQ9) -> 55500 | BS9: 60000 | BT9: =BR9-BS9 -> -4500 | BU9: =BC9+BR9 -> 330600 | BV9: =BD9+BS9 -> 325000 | BW9: =BU9-BV9 -> 5600
A10: NURU ZUHUDI | B10: 1000 | C10: 105000 | D10: 5000 | E10: 5000 | F10: 5000 | G10: 5000 | H10: 5000 | I10: 5000 | J10: 5000 | L10: 5000 | M10: 5000 | N10: 5000 | O10: 10000 | P10: =SUM(D10:O10) -> 60000 | Q10: =12*5000 -> 60000 | R10: =P10-Q10 -> 0 | S10: =SUM(C10:O10) -> 165000 | T10: =105000+Q10 -> 165000 | U10: =S10-T10 -> 0 | Z10: 0 | AA10: 0 | AB10: 0 | AC10: 0 | AH10: =SUM(V10:AG10) -> 0 | AI10: 40000 | AJ10: =AH10-AI10 -> -40000 | AK10: =S10+AH10 -> 165000 | AL10: =T10+AI10 -> 205000 | AM10: =AK10-AL10 -> -40000 | AN10: 40000 | AZ10: =SUM(AN10:AY10) -> 40000 | BA10: 60000 | BB10: =AZ10-BA10 -> -20000 | BC10: =AK10+AZ10 -> 205000 | BD10: =AL10+BA10 -> 265000 | BE10: =BC10-BD10 -> -60000 | BF10: 60000 | BR10: =SUM(BF10:BQ10) -> 60000 | BS10: 0 | BT10: 0 | BU10: =BC10+BR10 -> 265000 | BV10: =BD10+BS10 -> 265000 | BW10: =BU10-BV10 -> 0
A11: Patience Ndonye | B11: 1000 | C11: 105000 | D11: 5000 | O11: 20000 | P11: =SUM(D11:O11) -> 25000 | Q11: =12*5000 -> 60000 | R11: =P11-Q11 -> -35000 | S11: =SUM(C11:O11) -> 130000 | T11: =105000+Q11 -> 165000 | U11: =S11-T11 -> -35000 | Z11: 0 | AA11: 0 | AB11: 0 | AC11: 0 | AD11: 10000 | AH11: =SUM(V11:AG11) -> 10000 | AI11: 40000 | AJ11: =AH11-AI11 -> -30000 | AK11: =S11+AH11 -> 140000 | AL11: =T11+AI11 -> 205000 | AM11: =AK11-AL11 -> -65000 | AZ11: =SUM(AN11:AY11) -> 0 | BA11: 60000 | BB11: =AZ11-BA11 -> -60000 | BC11: =AK11+AZ11 -> 140000 | BD11: =AL11+BA11 -> 265000 | BE11: =BC11-BD11 -> -125000 | BN11: 87000 | BQ11: 74500 | BR11: =SUM(BF11:BQ11) -> 161500 | BS11: 60000 | BT11: =BR11-BS11 -> 101500 | BU11: =BC11+BR11 -> 301500 | BV11: =BD11+BS11 -> 325000 | BW11: =BU11-BV11 -> -23500
A12: Rabia Salim | B12: 1000 | C12: 105000 | D12: 5000 | F12: 5000 | H12: 10000 | I12: 5000 | J12: 5000 | K12: 5000 | L12: 5000 | M12: 10000 | N12: 5000 | O12: 5000 | P12: =SUM(D12:O12) -> 60000 | Q12: =12*5000 -> 60000 | R12: =P12-Q12 -> 0 | S12: =SUM(C12:O12) -> 165000 | T12: =105000+Q12 -> 165000 | U12: =S12-T12 -> 0 | V12: 0 | W12: 5000 | X12: 5000 | Y12: 5000 | Z12: 0 | AA12: 0 | AB12: 0 | AC12: 0 | AD12: 5000 | AE12: 5000 | AH12: =SUM(V12:AG12) -> 25000 | AI12: 40000 | AJ12: =AH12-AI12 -> -15000 | AK12: =S12+AH12 -> 190000 | AL12: =T12+AI12 -> 205000 | AM12: =AK12-AL12 -> -15000 | AZ12: =SUM(AN12:AY12) -> 0 | BA12: 60000 | BB12: =AZ12-BA12 -> -60000 | BC12: =AK12+AZ12 -> 190000 | BD12: 0 | BE12: =BC12-BD12 -> 190000 | BR12: =SUM(BF12:BQ12) -> 0 | BS12: 0 | BT12: =BR12-BS12 -> 0 | BU12: =BC12+BR12 -> 190000 | BV12: =BD12+BS12 -> 0 | BW12: =BU12-BV12 -> 190000
A13: Rehema Ali | B13: 1000 | C13: 105000 | D13: 5000 | E13: 5000 | F13: 5000 | G13: 5000 | P13: =SUM(D13:O13) -> 20000 | Q13: =12*5000 -> 60000 | R13: =P13-Q13 -> -40000 | S13: =SUM(C13:O13) -> 125000 | T13: =105000+Q13 -> 165000 | U13: =S13-T13 -> -40000 | Z13: 0 | AA13: 0 | AB13: 0 | AC13: 0 | AD13: 30000 | AH13: =SUM(V13:AG13) -> 30000 | AI13: 40000 | AJ13: =AH13-AI13 -> -10000 | AK13: =S13+AH13 -> 155000 | AL13: =T13+AI13 -> 205000 | AM13: =AK13-AL13 -> -50000 | AN13: 30000 | AZ13: =SUM(AN13:AY13) -> 30000 | BA13: 60000 | BB13: =AZ13-BA13 -> -30000 | BC13: =AK13+AZ13 -> 185000 | BD13: =AL13+BA13 -> 265000 | BE13: =BC13-BD13 -> -80000 | BF13: 78000 | BN13: 56000 | BQ13: 6000 | BR13: =SUM(BF13:BQ13) -> 140000 | BS13: 60000 | BT13: =BR13-BS13 -> 80000 | BU13: =BC13+BR13 -> 325000 | BV13: =BD13+BS13 -> 325000 | BW13: =BU13-BV13 -> 0
A14: RIZIKI KAGUA | B14: 1000 | C14: 105000 | D14: 5000 | E14: 5000 | F14: 5000 | G14: 5000 | H14: 5000 | I14: 5000 | J14: 5000 | K14: 5000 | L14: 5000 | M14: 5000 | N14: 5000 | O14: 5000 | P14: =SUM(D14:O14) -> 60000 | Q14: =12*5000 -> 60000 | R14: =P14-Q14 -> 0 | S14: =SUM(C14:O14) -> 165000 | T14: =105000+Q14 -> 165000 | U14: =S14-T14 -> 0 | V14: 5000 | Z14: 0 | AA14: 0 | AB14: 0 | AC14: 0 | AH14: =SUM(V14:AG14) -> 5000 | AI14: 40000 | AJ14: =AH14-AI14 -> -35000 | AK14: =S14+AH14 -> 170000 | AL14: =T14+AI14 -> 205000 | AM14: =AK14-AL14 -> -35000 | AZ14: =SUM(AN14:AY14) -> 0 | BA14: 60000 | BB14: =AZ14-BA14 -> -60000 | BC14: =AK14+AZ14 -> 170000 | BD14: =AL14+BA14 -> 265000 | BE14: =BC14-BD14 -> -95000 | BJ14: 120000 | BR14: =SUM(BF14:BQ14) -> 120000 | BS14: 60000 | BT14: =BR14-BS14 -> 60000 | BU14: =BC14+BR14 -> 290000 | BV14: =BD14+BS14 -> 325000 | BW14: =BU14-BV14 -> -35000
A15: Sheila Mwalekwa | B15: 1000 | C15: 105000 | J15: 50000 | P15: =SUM(D15:O15) -> 50000 | Q15: =12*5000 -> 60000 | R15: =P15-Q15 -> -10000 | S15: =SUM(C15:O15) -> 155000 | T15: =105000+Q15 -> 165000 | U15: =S15-T15 -> -10000 | Z15: 0 | AA15: 0 | AB15: 0 | AC15: 0 | AG15: 50000 | AH15: =SUM(V15:AG15) -> 50000 | AI15: 40000 | AJ15: =AH15-AI15 -> 10000 | AK15: =S15+AH15 -> 205000 | AL15: =T15+AI15 -> 205000 | AM15: =AK15-AL15 -> 0 | AZ15: =SUM(AN15:AY15) -> 0 | BA15: 60000 | BB15: =AZ15-BA15 -> -60000 | BC15: =AK15+AZ15 -> 205000 | BD15: =AL15+BA15 -> 265000 | BE15: =BC15-BD15 -> -60000 | BF15: 60000 | BK15: 15000 | BL15: 29000 | BM15: 5500 | BP15: 5500 | BQ15: 5000 | BR15: =SUM(BF15:BQ15) -> 120000 | BS15: 60000 | BT15: =BR15-BS15 -> 60000 | BU15: =BC15+BR15 -> 325000 | BV15: =BD15+BS15 -> 325000 | BW15: =BU15-BV15 -> 0
A16: ZUHURA SUMBA | B16: 1000 | C16: 105000 | E16: 10000 | H16: 10000 | I16: 10000 | L16: 20000 | O16: 10000 | P16: =SUM(D16:O16) -> 60000 | Q16: =12*5000 -> 60000 | R16: =Q16-P16 -> 0 | S16: =SUM(C16:O16) -> 165000 | T16: =105000+Q16 -> 165000 | U16: =S16-T16 -> 0 | Z16: 0 | AA16: 10000 | AB16: 0 | AC16: 0 | AD16: 10000 | AH16: =SUM(V16:AG16) -> 20000 | AI16: 40000 | AJ16: =AH16-AI16 -> -20000 | AK16: =S16+AH16 -> 185000 | AL16: =T16+AI16 -> 205000 | AM16: =AK16-AL16 -> -20000 | AS16: 30000 | AZ16: =SUM(AN16:AY16) -> 30000 | BA16: 60000 | BB16: =AZ16-BA16 -> -30000 | BC16: =AK16+AZ16 -> 215000 | BD16: =AL16+BA16 -> 265000 | BE16: =BC16-BD16 -> -50000 | BF16: 50000 | BI16: 10000 | BM16: 39500 | BR16: =SUM(BF16:BQ16) -> 99500 | BS16: 60000 | BT16: =BR16-BS16 -> 39500 | BU16: =BC16+BR16 -> 314500 | BV16: =BD16+BS16 -> 325000 | BW16: =BU16-BV16 -> -10500 | BX16: 10500
A17: UNKNOWN | C17: 5000 | P17: =SUM(D17:O17) -> 0 | S17: =SUM(C17:O17) -> 5000 | U17: =S17-T17 -> 5000 | Z17: 0 | AA17: 0 | AB17: 0 | AC17: 0 | AH17: =SUM(V17:AG17) -> 0 | AI17: 40000 | AJ17: =AH17-AI17 -> -40000 | AK17: =S17+AH17 -> 5000 | AL17: =T17+AI17 -> 40000 | AM17: =AK17-AL17 -> -35000 | AZ17: =SUM(AN17:AY17) -> 0 | BR17: =SUM(BF17:BQ17) -> 0 | BS17: 60000 | BT17: =BR17-BS17 -> -60000 | BU17: =BC17+BR17 -> 0 | BV17: =BD17+BS17 -> 60000 | BW17: =BU17-BV17 -> -60000
A18: TOTAL | B18: =SUM(B3:B17) -> 14000 | C18: =SUM(C3:C17) -> 1484500 | D18: =SUM(D3:D17) -> 40000 | E18: =SUM(E3:E17) -> 50500 | F18: =SUM(F3:F17) -> 50000 | G18: =SUM(G3:G17) -> 27500 | H18: =SUM(H3:H17) -> 50000 | I18: =SUM(I3:I17) -> 35000 | ... V18: =SUM(V3:V17) -> 10000 | AZ18: =SUM(AZ3:AZ17) -> 397000 | BA18: =SUM(BA3:BA17) -> 840000 | BC18: =SUM(BC3:BC17) -> 2842100 | BD18: =SUM(BD3:BD17) -> 3445000 | BR18: =SUM(BF18:BQ18) -> 0 | BU18: =BC18+BS18 -> 2842100
U20: =U6+U9+V4+V14 -> 33600
A21: Loans Issued
A23: Name | D23: Amount | E23: Commission | F23: Paid | G23: Balance
A24: Fatma Shaffi | D24: 60000 | E24: 6000 | F24: 66000 | G24: 0
A25: Nuru Kibirige | D25: 60000 | E25: 6000 | F25: 66000 | G25: 0
A26: Aisha Muthoni | D26: 100000 | E26: 10000 | F26: 0 | G26: 100000
A27: Maimuna Juma | D27: 60000 | E27: 6000 | F27: 63000 | G27: 60000
A28: Total | D28: =SUM(D24:D27) -> 280000 | E28: =SUM(E24:E27) -> 28000 | G28: =SUM(G24:G27) -> 160000

Sheet Aisha Muthoni Statement
A1: Receipts 2020
A2: Date | B2: Credit | C2: Name
A3: 22062020 | B3: 105000 | C3: Aisha
A11: Contributions
A12: Describtion | B12: Loans Issued | C12: Loans | D12: Contributions | E12: Welfare
A13: Balance B/F | C13: -105000 | D13: -55000 | E13: -5500
A14: OCT | C14: 0 | D14: 0 | E14: 0
A15: NOV | C15: 0 | D15: 0 | E15: 0
A16: DEC | C16: 0 | D16: 0 | E16: 0
A17: JAN | C17: 0 | D17: 0 | E17: 0
A18: FEB | C18: 0 | D18: 0 | E18: 0
A19: MAR | C19: 0 | D19: 0 | E19: 0
A20: APR | C20: 0 | D20: 0 | E20: 0
A21: MAY | C21: 0 | D21: 0 | E21: 0
A22: JUN | C22: 105000 | D22: 0 | E22: 0
A23: JUL | C23: 0 | D23: 0 | E23: 0
A24: AUG | C24: 0 | D24: 0 | E24: 0
A25: SEP | C25: 0 | D25: 0 | E25: 0
A26: Total Amount | C26: =SUM(C14:C25) -> 105000 | D26: =SUM(D13:D25) -> -55000 | E26: =SUM(E13:E25) -> -5500
A27: Amount Expected | C27: 105000 | D27: =5000*(COUNT(D14:D25)-4) -> 40000 | E27: =500*(COUNT(E14:E25)-4) -> 4000
A28: Amount Owed 2020 | C28: =C27-C26 -> 0 | D28: =D27-D26 -> 95000 | E28: =E27-E26-F13 -> 9500
A29: Total Owed | C29: =C28+D28+E28 -> 104500

Sheet Amina Statement
A1: Receipts 2020
A2: Date | B2: Credit | C2: Name
A3: 16102019 | B3: 10960 | C3: Amina Salim
A4: 4112019 | B4: 10960 | C4: Amina+Rabia
A5: 3122019 | B5: 5500 | C5: Rabia
A6: 13122019 | B6: 5500 | C6: Amina Salim
A7: 2012020 | B7: 5500 | C7: Amina
A8: 3022020 | B8: 5500 | C8: Amina
A9: 2032020 | B9: 5500 | C9: Amina
A11: Contributions
A12: Describtion | B12: Loans Issued | C12: Loans | D12: Contributions | E12: Welfare
A13: Balance B/F | C13: 0 | D13: 0 | E13: 0
A14: OCT | C14: 0 | D14: 5000 | E14: 500
A15: NOV | C15: 0 | D15: 5000 | E15: 500
A16: DEC | C16: 0 | D16: 5000 | E16: 500
A17: JAN | C17: 0 | D17: 5000 | E17: 500
A18: FEB | C18: 0 | D18: 0 | E18: 0
A19: MAR | C19: 0 | D19: 0 | E19: 0
A20: APR | C20: 0 | D20: 0 | E20: 0
A21: MAY | C21: 0 | D21: 0 | E21: 0
A22: JUN | C22: 0 | D22: 5000 | E22: 500
A23: JUL | C23: 0 | D23: 5000 | E23: 500
A24: AUG | C24: 0 | D24: 0 | E24: 0
A25: SEP | C25: 0 | D25: 0 | E25: 0
A26: Total Amount | C26: =SUM(C13:C25) -> 0 | D26: =SUM(D13:D25) -> 30000 | E26: =SUM(E13:E25) -> 3000
A27: Amount Expected | C27: 0 | D27: =5000*(COUNT(D14:D25)-4) -> 40000 | E27: =500*(COUNT(E14:E25)-4) -> 4000
A28: Amount Owed 2020 | C28: =C27-C26 -> 0 | D28: =D27-D26-E13 -> 10000 | E28: =E27-E26-F13 -> 1000
A29: Total Owed | C29: =C28+D28+E28 -> 11000

Sheet Fatma Shaffi Statement
A1: Receipts 2020
A2: Date | B2: Credit
A3: 3122019 | B3: 5000
A4: 20122019 | B4: 6000
A5: 31012020 | B5: 6000
A6: 11032020 | B6: 6000
B7: 80000
B8: 7000
B9: 5500
B10: 5500 | E10: oct 2019 to sept 2020
A11: Contributions
A12: Describtion | B12: Loans Issued | C12: Loans | D12: Contributions | E12: Welfare
A13: Balance B/F | C13: 0 | D13: 0 | E13: 0
A14: OCT | C14: 0 | D14: 0 | E14: 0
A15: NOV | C15: 0 | D15: 0 | E15: 0
A16: DEC | C16: 0 | D16: 5000 | E16: 0
A17: JAN | C17: 0 | D17: 5500 | E17: 500
A18: FEB | C18: 0 | D18: 0 | E18: 0
A19: MAR | B19: 110000 | C19: 0 | D19: 0 | E19: 0
A20: APR | C20: 0 | D20: 0 | E20: 0
A21: MAY | C21: 0 | D21: 0 | E21: 0 | I21: 66000 | J21: 18500 | K21: 2500
A22: JUN | C22: 0 | D22: 5500 | E22: 500
A23: JUL | C23: 0 | D23: 5500 | E23: 500
A24: AUG | C24: 0 | D24: 0 | E24: 0
A25: SEP | C25: 66000 | D25: 18500 | E25: 2500
A27: Total Amount | C27: =SUM(C13:C25) -> 66000 | D27: =SUM(D13:D25) -> 40000 | E27: =SUM(E13:E25) -> 4000 | J27: 80000
A28: Amount Expected | C28: =11000*(COUNT(C20:C25)) -> 66000 | D28: =5000*(COUNT(D14:D25)-4) -> 40000 | E28: =500*(COUNT(E14:E25)-4) -> 4000
A29: Amount Owed 2020 | C29: =C28-C27 -> 0 | D29: =D28-D27-E13 -> 0 | E29: =E28-E27-F13 -> 0
A30: Total Owed | C30: =C29+D29+E29 -> 0
A32: *The loan should have been paid at KES 66,000 by now with KES 44000 carried to 2021. The loan has been paid at 0. Therefore balance carried forward is still 110,000 | F32: =80000-C29 -> 80000

Sheet Janet Dali Statement
A1: Receipts 2020
A2: Date | B2: Credit | C2: Name
A8: Contributions
A9: Describtion | B9: Loans | C9: Contributions | D9: Welfare
A10: Balance B/F | B10: 0 | C10: 13500 | D10: 0
A11: OCT | B11: 0 | C11: 0 | D11: 0
A12: NOV | B12: 0 | C12: 0 | D12: 0
A13: DEC | B13: 0 | C13: 0 | D13: 0
A14: JAN | B14: 0 | C14: 0 | D14: 0
A15: FEB | B15: 0 | C15: 0 | D15: 0
A16: MAR | B16: 0 | C16: 0 | D16: 0
A17: APR | B17: 0 | C17: 0 | D17: 0
A18: MAY | B18: 0 | C18: 0 | D18: 0
A19: JUN | B19: 0 | C19: 0 | D19: 0
A20: JUL | B20: 0 | C20: 0 | D20: 0
A21: AUG | B21: 0 | C21: 0 | D21: 0
A22: SEP | B22: 0 | C22: 0 | D22: 0
A23: Total | B23: 0 | C23: =SUM(C11:C22) -> 0 | D23: =SUM(D11:D22) -> 0
A24: Expected Amount | B24: 0 | C24: =40000 -> 40000 | D24: =4000 -> 4000
A25: Balance C/F(2020) | B25: 0 | C25: =(C24-C10)-C23 -> 26500 | D25: =(D24-D10)-D23 -> 4000
A26: Total Owed | B26: =B25+C25+D25 -> 30500
A27: Notes:

Sheet KK Statement
A1: Receipts 2020
A2: Date | B2: Credit | C2: Name
B3: 38500
A4: 13112019 | B4: 5000
A5: 9122019 | B5: 11000
A6: 9012020 | B6: 11000
A9: Contributions
A10: Describtion | B10: Loans Issued | C10: Loans | D10: Contributions | E10: Welfare
A11: Balance B/F | C11: 0 | D11: 0 | E11: 0
A12: OCT | C12: 0 | D12: 0 | E12: 0
A13: NOV | B13: 110000 | C13: 0 | D13: 5000 | E13: 0
A14: DEC | C14: 11000 | D14: 0 | E14: 0
A15: JAN | C15: 11000 | D15: 0 | E15: 0
A16: FEB | C16: 0 | D16: 0 | E16: 0 | I16: =133300 -> 133300
A17: MAR | C17: 0 | D17: 0 | E17: 0 | I17: 1000
A18: APR | C18: 0 | D18: 0 | E18: 0 | I18: 3300 | L18: 88000 | M18: 35000 | N18: 4000
A19: MAY | C19: 0 | D19: 0 | E19: 0 | I19: =I16+I17+I18 -> 137600
A20: JUN | C20: 0 | D20: 0 | E20: 0
A21: JUL | C21: 0 | D21: 0 | E21: 0 | I21: =I19-D24+E24 -> 137600
A22: AUG | C22: 0 | D22: 0 | E22: 0
A23: SEP | C23: 0 | D23: 0 | E23: 0 | H23: =B13-(C14+C15) -> 88000 | I23: =C24+D24+E24 -> 0
C24: 0 | D24: 0 | E24: 0 | I24: =I19-I23 -> 137600
A25: Total | C25: =SUM(C12:C24) -> 22000 | D25: =SUM(D12:D24) -> 5000 | E25: =SUM(E12:E24) -> 0
A26: Expected Amount | C26: 110000 | D26: =40000 -> 40000 | E26: =4000 -> 4000
A27: Balance C/F(2020) | C27: =C26-C25 -> 88000 | D27: =(D26-D11)-D25 -> 35000 | E27: =(E26-E11)-E25 -> 4000
A28: Total Owed | C28: =C27+D27+E27 -> 127000 | H28: 133000
H29: 1000
H30: 3300
H31: =H28+H29+H30 -> 137300

Sheet Maimuna Juma Statement
A1: Receipts 2020
A2: Date | B2: Credit | C2: Name
A8: Contributions
A9: Describtion | B9: Loans Issued | C9: Loans | D9: Contributions | E9: Welfare
A10: Balance B/F | C10: 0 | D10: -19500 | E10: -2000
A11: OCT | B11: =150000*1.1 -> 165000 | C11: 0 | D11: 0 | E11: 0
A12: NOV | C12: 0 | D12: 0 | E12: 0
A13: DEC | C13: 0 | D13: 0 | E13: 0
A14: JAN | C14: 0 | D14: 0 | E14: 0
A15: FEB | C15: 0 | D15: 0 | E15: 0
A16: MAR | C16: 0 | D16: 0 | E16: 0
A17: APR | C17: 0 | D17: 0 | E17: 0
A18: MAY | C18: 0 | D18: 0 | E18: 0
A19: JUN | C19: 0 | D19: 0 | E19: 0
A20: JUL | C20: 0 | D20: 0 | E20: 0
A21: AUG | C21: 0 | D21: 0 | E21: 0
A22: SEP | C22: 0 | D22: 0 | E22: 0
A23: Total Amount | C23: 0 | D23: =SUM(D11:D22) -> 0 | E23: =SUM(E11:E22) -> 0
A24: Amount Expected | C24: =16500*((COUNT(C12:C21))) -> 165000 | D24: =5000*(COUNT(D11:D22)-4) -> 40000 | E24: =500*(COUNT(E11:E22)-4) -> 4000 | H24: 44000
A25: Amount Owed 2020 | C25: =C24-C23 -> 165000 | D25: =D24-D23-D10 -> 59500 | E25: =E24-E23-E10 -> 6000 | H25: 23500
A26: Total Owed | C26: =C25+D25+E25 -> 230500

Sheet Nuru K Statement
A1: Receipts 2020
A2: Date | B2: Credit | C2: Name
A3: 21082020 | B3: 25000
A4: 3092020 | B4: 25000
A7: Contributions
A8: Describtion | B8: Loans Issued | C8: Loans | D8: Contributions | E8: Welfare
A9: Balance B/F | C9: 0 | D9: 10100 | E9: 0
A10: OCT | B10: 132000 | C10: 0 | D10: 0 | E10: 0
A11: NOV | C11: 0 | D11: 0 | E11: 0
A12: DEC | C12: 0 | D12: 0 | E12: 0
A13: JAN | C13: 0 | D13: 0 | E13: 0
A14: FEB | C14: 0 | D14: 0 | E14: 0
A15: MAR | C15: 0 | D15: 0 | E15: 0
A16: APR | C16: 0 | D16: 0 | E16: 0
A17: MAY | C17: 0 | D17: 0 | E17: 0
A18: JUN | C18: 0 | D18: 0 | E18: 0
A19: JUL | C19: 0 | D19: 0 | E19: 0
A20: AUG | C20: 0 | D20: 23000 | E20: 2000
A21: SEP | C21: 0 | D21: 23000 | E21: 2000
A22: Total Amount | C22: =SUM(C11:C21) -> 0 | D22: =SUM(D10:D21) -> 46000 | E22: =SUM(E10:E21) -> 4000
A23: Amount Expected | C23: =132000 -> 132000 | D23: =5000*(COUNT(D10:D21)-4) -> 40000 | E23: =500*(COUNT(E10:E21)-4) -> 4000
A24: Amount Owed 2020 | C24: =C23-C22 -> 132000 | D24: =D23-D22-D9 -> -16100 | E24: =E23-E22-E9 -> 0
A25: Total Owed | C25: =C24+D24+E24 -> 115900

Sheet Nuru M Statement
A1: Receipts 2020
A2: Date | B2: Credit | C2: Name
A3: 4112019 | B3: 16460
A4: 13112019 | B4: 16500
A5: 3012020 | B5: 16500
A6: 2032020 | B6: 33000
A8: Contributions
A9: Describtion | B9: Loans Issued | C9: Loans | D9: Contributions | E9: Welfare
A10: Balance B/F | C10: 0 | D10: 0 | E10: 1000
A11: OCT | B11: 165000 | C11: 0 | D11: 0 | E11: 0
A12: NOV | C12: 16500 | D12: 0 | E12: 0
A13: DEC | C13: 16500 | D13: 0 | E13: 0
A14: JAN | C14: 16500 | D14: 0 | E14: 0
A15: FEB | C15: =C14*2 -> 33000 | D15: 0 | E15: 0
A16: MAR | C16: 0 | D16: 0 | E16: 0
A17: APR | C17: 0 | D17: 0 | E17: 0
A18: MAY | C18: 0 | D18: 0 | E18: 0
A19: JUN | C19: 0 | D19: 0 | E19: 0
A20: JUL | C20: 0 | D20: 0 | E20: 0 | H20: =B11-C24 -> 16500
A21: AUG | C21: 0 | D21: 0 | E21: 0 | H21: =C12+C13+C14+C15+C23 -> 148500
A22: SEP | C22: 0 | D22: 0 | E22: 0 | H22: =B11-C24 -> 16500
A23: OCT | C23: 66000 | D23: 40000 | E23: 3000
A24: Total Amount | C24: =SUM(C12:C23) -> 148500 | D24: =SUM(D11:D23) -> 40000 | E24: =SUM(E11:E23) -> 3000
A25: Amount Expected | C25: =16500*((COUNT(C12:C22)-2)) -> 148500 | D25: =5000*(COUNT(D11:D22)-4) -> 40000 | E25: =500*(COUNT(E11:E22)-4) -> 4000
A26: Amount Owed 2020 | C26: =C25-C24 -> 0 | D26: =D25-D24-D10 -> 0 | E26: =E25-E24-E10 -> 0
A27: Total Owed | C27: =C26+D26+E26 -> 0

Sheet Patience Ndonye Statement
A1: Receipts 2020
A2: Date | B2: Credit | C2: Name
A3: 30062020 | B3: 10000
A8: Contributions
A9: Describtion | B9: Loans Issued | C9: Loans | D9: Contributions | E9: Welfare
A10: Balance B/F | C10: 0 | D10: -35000 | E10: -6000
A11: OCT | C11: 0 | D11: 0 | E11: 0
A12: NOV | C12: 0 | D12: 0 | E12: 0
A13: DEC | C13: 0 | D13: 0 | E13: 0
A14: JAN | C14: 0 | D14: 0 | E14: 0
A15: FEB | C15: 0 | D15: 0 | E15: 0
A16: MAR | C16: 0 | D16: 0 | E16: 0
A17: APR | C17: 0 | D17: 0 | E17: 0
A18: MAY | C18: 0 | D18: 0 | E18: 0
A19: JUN | C19: 0 | D19: 10000 | E19: 0
A20: JUL | C20: 0 | D20: 0 | E20: 0
A21: AUG | C21: 0 | D21: 0 | E21: 0
A22: SEP | C22: 0 | D22: 0 | E22: 0
A23: Total Amount | C23: =SUM(C12:C22) -> 0 | D23: =SUM(D11:D22) -> 10000 | E23: =SUM(E11:E22) -> 0
A24: Amount Expected | C24: 0 | D24: =5000*(COUNT(D11:D22)-4) -> 40000 | E24: =500*(COUNT(E11:E22)-4) -> 4000
A25: Amount Owed 2020 | C25: =C24-C23 -> 0 | D25: =D24-D23-D10 -> 65000 | E25: =E24-E23-E10 -> 10000
A26: Total Owed | C26: =C25+D25+E25 -> 75000

Sheet Amina Salim
A1: Date | B1: Describtion | C1: Credit | D1: Debit | E1: Comments
A2: 43375 | B2: Amina Salim | C2: 5500
A3: 43404 | B3: Amina Salim | C3: 5500
A4: 43435 | B4: Amina Salim | C4: 5500
A5: 43467 | B5: Amina Salim | C5: 5500
A6: 43491 | B6: Amina Salim | C6: 5500
A7: 43528 | B7: Amina Salim | C7: 5500
A8: 43554 | B8: Amina Salim | C8: 5500
A9: 43582 | B9: Amina Salim | C9: 5500
A10: 43619 | B10: Amina Salim | C10: 5500
A11: 43649 | B11: Amina Salim | C11: 5500
A14: Total | C14: =SUM(C2:C13) -> 55000 | D14: =SUM(D2:D13) -> 0 | E14: =SUM(E2:E13) -> 0

Sheet Fatma Shaffi
A1: Date | B1: Describtion | C1: Credit | D1: Debit | E1: Fees
A2: 43390 | B2: Loan | D2: 60000 | E2: 6000
A3: 43405 | B3: Fatma Shaffi | C3: 11000
A4: 43469 | B4: Fatma Shaffi | C4: 20000
A5: 43565 | B5: Fatma Shaffi | C5: 20500
A6: 43631 | B6: Fatma Shaffi | C6: 11000
A7: 43645 | B7: Fatma Shaffi | C7: 5500
A9: Total | C9: =SUM(C3:C8) -> 68000 | D9: =SUM(D2:D8) -> 60000 | E9: =SUM(E2:E8) -> 6000
A10: Net Position | C10: =(C9-(D9+E9)) -> 2000 | D10: Applied for Oct 2018
A12: Date | B12: Amount Disbursed | C12: First Repayment | D12: Last Repayment
A13: 43755 | B13: 60000 | C13: 43405 | D13: 43678
A14: Repayment Schedule
A15: Date | B15: Principal | C15: Fee | D15: Total | E15: Paid | F15: Balance
A16: 43770 | B16: 6000 | C16: 600 | D16: =B16+C16 -> 6600 | E16: 11000
A17: 43800 | B17: 6000 | C17: 600 | D17: =B17+C17 -> 6600
A18: 43831 | B18: 6000 | C18: 600 | D18: =B18+C18 -> 6600 | E18: 20000
A19: 43862 | B19: 6000 | C19: 600 | D19: =B19+C19 -> 6600
A20: 43891 | B20: 6000 | C20: 600 | D20: =B20+C20 -> 6600
A21: 43922 | B21: 6000 | C21: 600 | D21: =B21+C21 -> 6600 | E21: 20500
A22: 43952 | B22: 6000 | C22: 600 | D22: =B22+C22 -> 6600
A23: 43983 | B23: 6000 | C23: 600 | D23: =B23+C23 -> 6600 | E23: 15000
A24: 44013 | B24: 6000 | C24: 600 | D24: =B24+C24 -> 6600
A25: 44044 | B25: 6000 | C25: 600 | D25: =B25+C25 -> 6600

Sheet Janet Dali
A1: Date | B1: Describtion | C1: Credit | D1: Debit | E1: Fees | H1: Comments
A2: 43447 | B2: Janet Dali | C2: 11636 | D2: 0 | E2: 0 | H2: Refund for AGM Usage
A3: 43447 | B3: Janet Dali | C3: 15000 | D3: 0 | E3: 0 | F3: =5500*3 -> 16500 | H3: Oct Nov Dec (Less 1500)
A5: Total | C5: =SUM(C3:C4) -> 15000 | D5: =SUM(D2:D3) -> 0 | E5: =SUM(H2:H3) -> 0

Sheet Khadijah Jaber
A1: Date | B1: Describtion | C1: Credit | D1: Debit | E1: Fees
A2: 43350 | B2: Khadija Jaber | C2: 12000
A3: 43389 | B3: Khadija Jaber | C3: 1500
A4: 43413 | B4: Khadija Jaber | C4: 11000
A5: 43437 | B5: Khadija Jaber | C5: 5500
A6: 43505 | B6: Khadija Jaber | C6: 11000
A9: Total | C9: =SUM(C3:C8) -> 29000 | D9: =SUM(D2:D8) -> 0 | E9: =SUM(E2:E8) -> 0
A10: Net Position | C10: =(C9-(D9+E9)) -> 29000

Sheet Rabia Salim Statement
A1: Receipts 2020
A2: Date | B2: Credit | C2: Name
A3: 4112019 | B3: 10960 | C3: 5K amina 5K Rabia
A4: 3122019 | B4: 5500 | C4: Amina Salim for Rabia
A5: 31122019 | B5: 5500 | C5: Rabia Salim
A6: 24022020 | B6: 5500 | C6: Rabia
A7: 19032020 | B7: 5500 | C7: Rabia
A11: Contributions
A12: Describtion | B12: Loans Issued | C12: Loans | D12: Contributions | E12: Welfare | G12: Describtion | H12: Loans Issued | I12: Loans | J12: Contributions | K12: Welfare
A13: Balance B/F | C13: 0 | D13: 0 | E13: 0 | G13: Balance B/F | I13: 0 | J13: 0 | K13: 0 | M13: 185000 | N13: =205000+(5000*5) -> 230000 | Q13: Rabia Salim Exit Statement
A14: OCT | C14: 0 | D14: 0 | E14: 0 | G14: OCT | I14: 0 | J14: 0 | K14: 0 | M14: =N14 -> 11500 | N14: =N13*5% -> 11500 | P14: Contributions | Q14: Total Contributions | R14: 185000
A15: NOV | C15: 0 | D15: 5000 | E15: 500 | G15: NOV | I15: 0 | J15: 0 | K15: 0 | M15: =(K30+E30) -> 4000 | Q15: Expected Contribution By Feb | R15: 230000
A16: DEC | C16: 0 | D16: 5000 | E16: 500 | G16: DEC | I16: 45000 | J16: 0 | K16: 0 | M16: =I30 -> 65000 | Q16: Admin Costs 5% | R16: -11500
A17: JAN | C17: 0 | D17: 5000 | E17: 500 | G17: JAN | I17: 0 | J17: 0 | K17: 0 | M17: =M13-(M14+M15+M16) -> 104500 | P17: Welfare | Q17: Total Contributions | R17: 14000
A18: FEB | C18: 0 | D18: 0 | E18: 0 | G18: FEB | I18: 0 | J18: 0 | K18: 0 | Q18: Expected Contribution By Feb | R18: 18000
A19: MAR | C19: 0 | D19: 0 | E19: 0 | G19: MAR | I19: 0 | J19: 0 | K19: 0 | Q19: Deficit | R19: =R17-R18 -> -4000
A20: APR | C20: 0 | D20: 0 | E20: 0 | G20: APR | I20: 0 | J20: 0 | K20: 0 | P20: Loan | Q20: Loan Issued | R20: 100000
A21: MAY | C21: 0 | D21: 0 | E21: 0 | G21: MAY | I21: 0 | J21: 0 | K21: 0 | Q21: Loan Fee | R21: 10000
A22: JUN | B22: 110000 | C22: 0 | D22: 5000 | E22: 500 | G22: JUN | I22: 0 | J22: 0 | K22: 0 | Q22: Loan Payment | R22: 45000
A23: JUL | C23: 0 | D23: 5000 | E23: 500 | G23: JUL | I23: 0 | J23: 0 | K23: 0 | Q23: Loan Balance | R23: =R22-(R20+R21) -> -65000
A24: AUG | C24: 0 | D24: 0 | E24: 0 | G24: AUG | I24: 0 | J24: 0 | K24: 0
A25: SEP | C25: 0 | D25: 0 | E25: 0 | G25: SEP | I25: 0 | J25: 0 | K25: 0 | Q25: Total Amount Owed to Chama | R25: =R23+R19+R16 -> -80500
Q26: Final Payment | R26: =R14+R25 -> 104500
A28: Total Amount | C28: =SUM(C15:C25) -> 0 | D28: =SUM(D14:D25) -> 25000 | E28: =SUM(E14:E25) -> 2500 | G28: Total Amount | I28: =SUM(I15:I25) -> 45000 | J28: =SUM(J14:J25) -> 0 | K28: 0
A29: Amount Expected | C29: =11000*(COUNT(C23:C25)) -> 33000 | D29: =5000*(COUNT(D14:D25)-4) -> 40000 | E29: =500*(COUNT(E14:E25)-4) -> 4000 | G29: Amount Expected | I29: 110000 | J29: =5000*(COUNT(J14:J25)-4) -> 40000 | K29: =500*5 -> 2500
A30: Amount Owed 2020 | C30: =C29-C28 -> 33000 | D30: =D29-D28-D13 -> 15000 | E30: =E29-E28-E13 -> 1500 | G30: Amount Owed 2020 | I30: =I29-I28 -> 65000 | J30: =J29-J28-J13 -> 40000 | K30: =K29-K28-K13 -> 2500
A31: Total Owed | C31: =C30+D30+E30 -> 49500 | G31: Total Owed | I31: =I30+J30+K30 -> 107500

Sheet Sheila Mwalekwa Statement
A1: Receipts 2020
A2: Date | B2: Credit | C2: Name
A11: Contributions
A12: Describtion | B12: Loans Issued | C12: Loans | D12: Contributions | E12: Welfare
A13: Balance B/F | C13: 0 | D13: -10000 | E13: -6000
A14: OCT | C14: 0 | D14: 0 | E14: 0
A15: NOV | C15: 0 | D15: 0 | E15: 0
A16: DEC | C16: 0 | D16: 0 | E16: 0
A17: JAN | C17: 0 | D17: 0 | E17: 0
A18: FEB | C18: 0 | D18: 0 | E18: 0
A19: MAR | C19: 0 | D19: 0 | E19: 0
A20: APR | C20: 0 | D20: 0 | E20: 0
A21: MAY | C21: 0 | D21: 0 | E21: 0
A22: JUN | C22: 0 | D22: 0 | E22: 0
A23: JUL | C23: 0 | D23: 0 | E23: 0
A24: AUG | C24: 0 | D24: 0 | E24: 0
A25: SEP | C25: 0 | D25: 0 | E25: 0
A26: Total Amount | C26: =SUM(C15:C25) -> 0 | D26: =SUM(D14:D25) -> 0 | E26: =SUM(E14:E25) -> 0
A27: Amount Expected | C27: =0 -> 0 | D27: =5000*(COUNT(D14:D25)-4) -> 40000 | E27: =500*(COUNT(E14:E25)-4) -> 4000
A28: Amount Owed 2020 | C28: =C27-C26 -> 0 | D28: =D27-D26-D13 -> 50000 | E28: =E27-E26-E13 -> 10000
A29: Total Owed | C29: =C28+D28+E28 -> 60000

Sheet Zuhura Sumba Statement
A1: Receipts 2020
A2: Date | B2: Credit | C2: Name
A3: 31032020 | B3: 11000
A4: 9062020 | B4: 11000
A11: Contributions
A12: Describtion | B12: Loans Issued | C12: Loans | D12: Contributions | E12: Welfare
A13: Balance B/F | C13: 0 | D13: 0 | E13: 0
A14: OCT | C14: 0 | D14: 0 | E14: 0
A15: NOV | C15: 0 | D15: 0 | E15: 0
A16: DEC | C16: 0 | D16: 0 | E16: 0
A17: JAN | C17: 0 | D17: 0 | E17: 0
A18: FEB | C18: 0 | D18: 0 | E18: 0
A19: MAR | C19: 0 | D19: 10000 | E19: 1000
A20: APR | C20: 0 | D20: 0 | E20: 0
A21: MAY | C21: 0 | D21: 0 | E21: 0
A22: JUN | C22: 0 | D22: 10000 | E22: 1000
A23: JUL | C23: 0 | D23: 0 | E23: 0
A24: AUG | C24: 0 | D24: 0 | E24: 0
A25: SEP | C25: 0 | D25: 0 | E25: 0
A26: Total Amount | C26: =SUM(C15:C25) -> 0 | D26: =SUM(D14:D25) -> 20000 | E26: =SUM(E14:E25) -> 2000
A27: Amount Expected | C27: =0 -> 0 | D27: =5000*(COUNT(D14:D25)-4) -> 40000 | E27: =500*(COUNT(E14:E25)-4) -> 4000
A28: Amount Owed 2020 | C28: =C27-C26 -> 0 | D28: =D27-D26-D13 -> 20000 | E28: =E27-E26-E13 -> 2000
A29: Total Owed | C29: =C28+D28+E28 -> 22000

Sheet Rehema Ali Statement
A1: Receipts 2020
A2: Date | B2: Credit | C2: Name
A3: 30062020 | B3: 35000
A11: Contributions
A12: Describtion | B12: Loans Issued | C12: Loans | D12: Contributions | E12: Welfare
A13: Balance B/F | C13: 0 | D13: -40000 | E13: -5000
A14: OCT | C14: 0 | D14: 0 | E14: 0
A15: NOV | C15: 0 | D15: 0 | E15: 0
A16: DEC | C16: 0 | D16: 0 | E16: 0
A17: JAN | C17: 0 | D17: 0 | E17: 0
A18: FEB | C18: 0 | D18: 0 | E18: 0
A19: MAR | C19: 0 | D19: 0 | E19: 0
A20: APR | C20: 0 | D20: 0 | E20: 0
A21: MAY | C21: 0 | D21: 0 | E21: 0
A22: JUN | C22: 0 | D22: 30000 | E22: 5000
A23: JUL | C23: 0 | D23: 0 | E23: 0
A24: AUG | C24: 0 | D24: 0 | E24: 0
A25: SEP | C25: 0 | D25: 0 | E25: 0
A26: Total Amount | C26: =SUM(C15:C25) -> 0 | D26: =SUM(D14:D25) -> 30000 | E26: =SUM(E14:E25) -> 5000
A27: Amount Expected | C27: =0 -> 0 | D27: =5000*(COUNT(D14:D25)-4) -> 40000 | E27: =500*(COUNT(E14:E25)-4) -> 4000
A28: Amount Owed 2020 | C28: =C27-C26 -> 0 | D28: =D27-D26-D13 -> 50000 | E28: =E27-E26-E13 -> 4000
A29: Total Owed | C29: =C28+D28+E28 -> 54000

Sheet Nuru K
A1: Date | B1: Describtion | C1: Credit | D1: Debit | E1: Fees
A2: 43379 | B2: Nuru Kibirige | C2: 5500
A3: 43390 | B3: Loan | D3: 60000 | E3: 6000
A4: 43405 | B4: Nuru Kibirige | C4: 5500
A5: 43444 | B5: Nuru Kibirige | C5: 5500
A6: 43507 | B6: Nuru Kibirige | C6: 8000
A7: 43533 | B7: Nuru Kibirige | C7: 5500
A8: 43556 | B8: Nuru Kibirige | C8: 5500
A9: 43587 | B9: Nuru Kibirige | C9: 5500
A10: 43623 | B10: Nuru Kibirige | C10: 25500
A11: 43654 | B11: Nuru Kibirige | C11: 65500
A12: 43711 | B12: Nuru Kibirige | C12: 10100
A14: Total | C14: =SUM(C2:C12) -> 142100 | D14: =SUM(D2:D12) -> 60000 | E14: =SUM(E2:E12) -> 6000
A15: Net Position | C15: =(C14-(D14+E14)) -> 76100
A17: Date | B17: Amount Disbursed | C17: First Repayment | D17: Last Repayment
A18: 43755 | B18: 60000 | C18: 43405 | D18: 43678
A19: Repayment Schedule
A20: Date | B20: Principal | C20: Fee | D20: Total | E20: Paid | F20: Balance
A21: 43770 | B21: 6000 | C21: 600 | D21: =B21+C21 -> 6600 | E21: 0 | F21: =D14+E14 -> 66000
A22: 43800 | B22: 6000 | C22: 600 | D22: =B22+C22 -> 6600 | E22: 0 | F22: =F21-E22 -> 66000
A23: 43831 | B23: 6000 | C23: 600 | D23: =B23+C23 -> 6600 | E23: 0 | F23: =F22-E23 -> 66000
A24: 43862 | B24: 6000 | C24: 600 | D24: =B24+C24 -> 6600 | E24: 0 | F24: =F23-E24 -> 66000
A25: 43891 | B25: 6000 | C25: 600 | D25: =B25+C25 -> 6600 | E25: 0 | F25: =F24-E25 -> 66000
A26: 43922 | B26: 6000 | C26: 600 | D26: =B26+C26 -> 6600 | E26: 0 | F26: =F25-E26 -> 66000
A27: 43952 | B27: 6000 | C27: 600 | D27: =B27+C27 -> 6600 | E27: 0 | F27: =F26-E27 -> 66000
A28: 43983 | B28: 6000 | C28: 600 | D28: =B28+C28 -> 6600 | E28: 0 | F28: =F27-E28 -> 66000
A29: 44013 | B29: 6000 | C29: 600 | D29: =B29+C29 -> 6600 | E29: =65500 -> 65500 | F29: =F28-E29 -> 500
A30: 44044 | B30: 6000 | C30: 600 | D30: =B30+C30 -> 6600 | E30: 10100 | F30: =F29-E30 -> -9600 | G30: Overpayment moved to savings

Sheet Nuru M
A1: Date | B1: Describtion | C1: Credit | D1: Debit | E1: Fees
A2: 43344 | B2: Nuru Mohammed | C2: 16500
A3: 43375 | B3: Nuru Mohammed | C3: 5500
A4: 43419 | B4: Nuru Mohammed | C4: 5000
A5: 43444 | B5: Nuru Mohammed | C5: 5500
A6: 43470 | B6: Nuru Mohammed | C6: 5500
A7: 43507 | B7: Nuru Mohammed | C7: 5500
A8: 43528 | B8: Nuru Mohammed | C8: 5500 | I8: BALANCE BF | J8: Balance BF | K8: OCT | L8: NOV | M8: DEC
A9: 43563 | B9: Nuru Mohammed | C9: 5500 | I9: OCT
A10: 43617 | B10: Nuru Mohammed | C10: 5500 | I10: NOV
A11: 43656 | B11: Nuru Mohammed | C11: 5500 | I11: DEC
I12: JAN
A13: Total | C13: =SUM(C1:C11) -> 65500 | D13: =SUM(D1:D11) -> 0 | E13: =SUM(E1:E11) -> 0 | I13: FEB
A14: Net Position | C14: =(C13-(D13+E13)) -> 65500 | I14: MAR
I15: APR
A16: Date | B16: Amount Disbursed | C16: First Repayment | D16: Last Repayment | I16: MAY
A17: 43755 | B17: 150000 | C17: 43770 | D17: 44075 | F17: =B17*1.1 -> 165000 | I17: JUN
A18: Repayment Schedule | I18: JUL
A19: Date | B19: Principal | C19: Fee | D19: Total | E19: Paid | F19: Balance | I19: AUG
A20: 4112019 | B20: 15000 | C20: 1500 | D20: =B20+C20 -> 16500 | E20: =D20 -> 16500 | F20: =F17-E20 -> 148500 | I20: SEP
A21: 13112019 | B21: 15000 | C21: 1500 | D21: =B21+C21 -> 16500 | E21: =D21 -> 16500 | F21: =F20-E21 -> 132000 | I21: OCT
A22: 3012020 | B22: 15000 | C22: 1500 | D22: =B22+C22 -> 16500 | E22: =D22 -> 16500 | F22: =F21-E22 -> 115500
A23: 2032020 | B23: 15000 | C23: 1500 | D23: =B23+C23 -> 16500 | E23: =D23 -> 16500 | F23: =F22-E23 -> 99000

Sheet Patience Ndonye
A1: Patience Ndonye

Sheet Rabia Salim
A1: Date | B1: Describtion | C1: Credit | D1: Debit | E1: Fees
A2: 43404 | B2: Rabia Salim | C2: 5500
A3: 43438 | B3: Rabia Salim | C3: 5500
A4: 43504 | B4: Rabia Salim | C4: 11000
A5: 43531 | B5: Rabia Salim | C5: 5500
A6: 43556 | B6: Rabia Salim | C6: 5500
A7: 43587 | B7: Rabia Salim | C7: 5500
A8: 43626 | B8: Rabia Salim | C8: 5500
A9: 43701 | B9: Rabia Salim | C9: 11000
A11: Total | C11: =SUM(C2:C9) -> 55000 | D11: =SUM(D2:D9) -> 0 | E11: =SUM(E2:E9) -> 0
A12: Net Position | C12: =(C11-(D11+E11)) -> 55000

Sheet Rehema Ali
A1: Date | B1: Describtion | C1: Credit | D1: Debit | E1: Fees
A2: 43370 | B2: Rehema Ali | C2: 30000
A3: 43420 | B3: Rehema Ali | C3: 23000
A4: 43420 | B4: Rehema Ali | C4: 10000 | H4: 5000
H5: =500*12 -> 6000
A7: Total | C7: =SUM(C2:C4) -> 63000 | D7: =SUM(D2:D4) -> 0 | E7: =SUM(E2:E4) -> 0
A8: Net Position | C8: =(C7-(D7+E7)) -> 63000

Sheet Sheila Mwalekwa
A1: Date | B1: Describtion | C1: Credit | D1: Debit | E1: Fees
A2: 43565 | B2: Sheila Mwalekwa | C2: 50000
A7: Total | C7: =SUM(C2:C4) -> 50000 | D7: =SUM(D2:D4) -> 0 | E7: =SUM(E2:E4) -> 0
A8: Net Position | C8: =(C7-(D7+E7)) -> 50000
